Workbook

Sheet HUONG_DAN
B1: HƯỚNG DẪN SỬ DỤNG – THEO DÕI SẢN LƯỢNG V19
B2: Mỗi sheet dữ liệu là một Excel Table (lọc/sắp xếp ở dòng 4). Cột có tiêu đề VÀNG (dòng 3) là cột nhập tay;
B3: cột có tiêu đề XANH NHẠT là công thức, KHÔNG gõ đè. Thêm dữ liệu: gõ vào dòng ngay dưới bảng, bảng tự nới ra và tự điền công thức.
B4: Dữ liệu bắt đầu từ dòng 5 ở mọi sheet. Dòng 2–3 là tiêu đề Trung/Việt, dòng 4 là số thứ tự cột.
B6: 1. Danh mục (ít khi đổi)
B7: CAU_HINH_CA: mã ca và các đợt làm việc. TỔNG GIỜ tự tính từ giờ bắt đầu/kết thúc.
B8: DANH_SACH_CHUYEN: thứ tự ở đây là thứ tự hiển thị trên TV. Thêm chuyền thì thêm 1 dòng ở cả sheet này và bảng HIEN_THI.
B9: DANH_SACH_SAN_PHAM: mọi mã sản phẩm. Mã được lưu dạng chữ (883 và "883" là một).
B11: 2. Đầu tháng
B12: MUC_TIEU_THANG: mỗi sản phẩm một dòng cho mỗi tháng. Cột THÁNG gõ dạng 10/2026. Các cột lũy kế tự tính.
B14: 3. Hằng ngày – sheet NHAP_LIEU
B15: Mỗi chuyền một dòng mỗi ngày: NGÀY, CHUYỀN, MÃ SẢN PHẨM, MÃ CA, MỤC TIÊU MỖI GIỜ.
... B39: Tiêu đề cột công thức

Sheet CAU_HINH_CA
A1: 工作時間設定 / CẤU HÌNH CA
A2: 班次代碼 | B2: 班次名稱 | C2: 總工時 | D2: 第一時段開始 | E2: 第一時段結束 | F2: 第二時段開始 | G2: 第二時段結束 | H2: 第三時段開始 | I2: 第三時段結束 | J2: 啟用狀態
A3: MÃ CA | B3: TÊN CA | C3: TỔNG GIỜ (tự tính) | D3: ĐỢT 1 BẮT ĐẦU | E3: ĐỢT 1 KẾT THÚC | F3: ĐỢT 2 BẮT ĐẦU | G3: ĐỢT 2 KẾT THÚC | H3: ĐỢT 3 BẮT ĐẦU | I3: ĐỢT 3 KẾT THÚC | J3: TRẠNG THÁI
A4: 1 | B4: 2 | C4: 3 | D4: 4 | E4: 5 | F4: 6 | G4: 7 | H4: 8 | I4: 9 | J4: 10
A5: 8H | B5: 8 giờ | C5: =IF(A5="","",ROUND(((E5-D5)+(G5-F5)+(I5-H5))*24,2)) -> 8 | D5: 0.3125 | E5: 0.47916667 | F5: 0.52083333 | G5: 0.6875 | J5: Đang sử dụng
A6: 9H | B6: 9 giờ | C6: =IF(A6="","",ROUND(((E6-D6)+(G6-F6)+(I6-H6))*24,2)) -> 9 | D6: 0.3125 | E6: 0.47916667 | F6: 0.52083333 | G6: 0.72916667 | J6: Đang sử dụng
A7: 10H | B7: 10 giờ | C7: =IF(A7="","",ROUND(((E7-D7)+(G7-F7)+(I7-H7))*24,2)) -> 10 | D7: 0.3125 | E7: 0.47916667 | F7: 0.52083333 | G7: 0.77083333 | J7: Đang sử dụng
A8: 11H30 | B8: 11 giờ 30 phút | C8: =IF(A8="","",ROUND(((E8-D8)+(G8-F8)+(I8-H8))*24,2)) -> 11.5 | D8: 0.3125 | E8: 0.47916667 | F8: 0.52083333 | G8: 0.6875 | H8: 0.70833333 | I8: 0.85416667 | J8: Đang sử dụng

Sheet DANH_SACH_CHUYEN
A1: 產線清單 / DANH SÁCH CHUYỀN
A2: 產線代碼 | B2: 產線名稱 | C2: 線長姓名 | D2: 啟用狀態
A3: MÃ CHUYỀN | B3: TÊN CHUYỀN | C3: TÊN TRƯỞNG CHUYỀN | D3: TRẠNG THÁI
A4: 1 | B4: 2 | C4: 3 | D4: 4
A5: CH01 | B5: Chuyền 1 | D5: Đang sử dụng
A6: CH02 | B6: Chuyền 2 | D6: Đang sử dụng
A7: CH03 | B7: Chuyền 3 | D7: Đang sử dụng
A8: CH04 | B8: Chuyền 4 | D8: Đang sử dụng
A9: CH05 | B9: Chuyền 5 | D9: Đang sử dụng
A10: CH06 | B10: Chuyền 6 | D10: Đang sử dụng

Sheet DANH_SACH_SAN_PHAM
A1: 產品清單 / DANH SÁCH SẢN PHẨM
A2: 产品代码 | B2: 产品名称 | C2: 備註 | D2: 啟用狀態
A3: MÃ SẢN PHẨM | B3: TÊN SẢN PHẨM | C3: GHI CHÚ | D3: TRẠNG THÁI
A4: 1 | B4: 2 | C4: 3 | D4: 4
A5: ĐAI LƯNG | D5: Đang sử dụng
A6: BAO TAY XANH | D6: Đang sử dụng
A7: 883 | D7: Đang sử dụng
A8: 567 | C8: Test | D8: Đang sử dụng
A9: MÃ 9H | C9: Mã thử từ V17 | D9: Đang sử dụng

Sheet DANH_SACH_LY_DO
A1: 未達原因清單 / DANH SÁCH LÝ DO KHÔNG ĐẠT
A2: 原因 | B2: 備註
A3: LÝ DO KHÔNG ĐẠT | B3: GHI CHÚ
A4: 1 | B4: 2
A5: Thiếu vật tư
A6: Hư máy
A7: Thiếu người
A8: Chờ hàng / chờ khuôn
A9: Sửa hàng lỗi
A10: Khác

Sheet LICH_LAM_VIEC
A1: 工作日曆 / LỊCH LÀM VIỆC (Chủ nhật mặc định nghỉ)
A2: 日期 | B2: 類型 | C2: 星期 | D2: 備註
A3: NGÀY | B3: LOẠI | C3: THỨ | D3: GHI CHÚ
A4: 1 | B4: 2 | C4: 3 | D4: 4
A5: 46388 | B5: Nghỉ | C5: =IF(A5="","",CHOOSE(WEEKDAY(A5),"CN","T2","T3","T4","T5","T6","T7")) -> T6 | D5: Tết Dương lịch (ví dụ)
A6: 46305 | B6: Nghỉ | C6: =IF(A6="","",CHOOSE(WEEKDAY(A6),"CN","T2","T3","T4","T5","T6","T7")) -> T7
A7: 46313 | B7: Làm bù | C7: =IF(A7="","",CHOOSE(WEEKDAY(A7),"CN","T2","T3","T4","T5","T6","T7")) -> CN

Sheet NHAP_LIEU
A1: 生產計劃與每小時產量 / NHẬP LIỆU HẰNG NGÀY (KẾ HOẠCH + SẢN LƯỢNG THEO GIỜ)
A2: 日期 | B2: 產線 | C2: 产品代码 | D2: 工作時間 | E2: 每小时目标产量PCS | F2: 總工時 | G2: 每日目标产量PCS | H2: 第1小時 | I2: 第2小時 | J2: 第3小時 | K2: 第4小時 | L2: 第5小時 | M2: 第6小時 | N2: 第7小時 | O2: 第8小時 | P2: 第9小時 | Q2: 第10小時 | R2: 第11小時 | S2: 第12小時 | T2: 每日实际产量PCS | U2: 当日达成率% | V2: 差異PCS | W2: 剩餘PCS | X2: 已輸入小時數 | Y2: 累計目標PCS | Z2: 進度達成率% | AA2: 前一工作日 | AB2: 前一日欠數PCS | AC2: 狀態 | AD2: 備註 | AE2: 檢查 | AF2: 索引 | AG2: 工人數 | AH2: 不良數PCS | AI2: 未達原因 | AJ2: 停機分鐘 | AK2: 人均每小時產量 | AL2: 不良率%
A3: NGÀY | B3: CHUYỀN | C3: MÃ SẢN PHẨM | D3: MÃ CA | E3: MỤC TIÊU MỖI GIỜ | F3: GIỜ CA | G3: MỤC TIÊU TRONG NGÀY | H3: GIỜ 1 | I3: GIỜ 2 | J3: GIỜ 3 | K3: GIỜ 4 | L3: GIỜ 5 | M3: GIỜ 6 | N3: GIỜ 7 | O3: GIỜ 8 | P3: GIỜ 9 | Q3: GIỜ 10 | R3: GIỜ 11 | S3: GIỜ 12 | T3: THỰC TẾ TRONG NGÀY | U3: TỶ LỆ ĐẠT TRONG NGÀY | V3: CHÊNH LỆCH | W3: CÒN THIẾU | X3: SỐ GIỜ ĐÃ NHẬP | Y3: MỤC TIÊU ĐẾN GIỜ ĐÃ NHẬP | Z3: TIẾN ĐỘ THEO GIỜ | AA3: NGÀY LÀM TRƯỚC | AB3: THIẾU HÔM TRƯỚC | AC3: TRẠNG THÁI | AD3: GHI CHÚ | AE3: KIỂM TRA | AF3: KHÓA (máy dùng) | AG3: SỐ CÔNG NHÂN | AH3: SỐ LỖI | AI3: LÝ DO KHÔNG ĐẠT | AJ3: PHÚT DỪNG MÁY | AK3: SP / NGƯỜI / GIỜ | AL3: TỶ LỆ LỖI
A4: 1 | B4: 2 | C4: 3 | D4: 4 | E4: 5 | F4: 6 | G4: 7 | H4: 8 | I4: 9 | J4: 10 | K4: 11 | L4: 12 | M4: 13 | N4: 14 | O4: 15 | P4: 16 | Q4: 17 | R4: 18 | S4: 19 | T4: 20 | U4: 21 | V4: 22 | W4: 23 | X4: 24 | Y4: 25 | Z4: 26 | AA4: 27 | AB4: 28 | AC4: 29 | AD4: 30 | AE4: 31 | AF4: 32 | AG4: 33 | AH4: 34 | AI4: 35 | AJ4: 36 | AK4: 37 | AL4: 38
A5: 46295 | B5: Chuyền 1 | C5: ĐAI LƯNG | D5: 8H | E5: 100 | F5: =IF(D5="","",IFERROR(INDEX(CAU_HINH_CA!$C$5:$C$50,MATCH(D5,CAU_HINH_CA!$A$5:$A$50,0)),"")) -> 8 | G5: =IF(OR(F5="",E5=""),"",ROUND(F5*E5,0)) -> 800 | H5: 100 | I5: 90 | J5: 110 | T5: =IF(COUNT(H5:S5)=0,"",SUM(H5:S5)) -> 300 | U5: =IF(OR(T5="",N(G5)=0),"",T5/G5) -> 0.375 | V5: =IF(OR(T5="",G5=""),"",T5-G5) -> -500 | W5: =IF(OR(T5="",G5=""),"",MAX(0,G5-T5)) -> 500 | X5: =IF(A5="","",COUNT(H5:S5)) -> 3 | Y5: =IF(OR(X5="",E5="",G5=""),"",MIN(G5,X5*E5)) -> 300 | Z5: =IF(OR(T5="",N(Y5)=0),"",T5/Y5) -> 1 | AA5: =IF(OR(A5="",B5=""),"",IF(SUMPRODUCT(MAX(($B$5:$B$10004=B5)*($A$5:$A$10004<A5)*$A$5:$A$10004))=0,"",SUMPRODUCT(MAX(($B$5:$B$10004=B5)*($A$5:$A$10004<A5)*$A$5:$A$10004)))) -> 46294 | AB5: =IF(N(AA5)=0,"",SUMIFS($W$5:$W$10004,$B$5:$B$10004,B5,$A$5:$A$10004,AA5)) -> 40 | AC5: Đang chạy | AE5: =IF(OR(A5="",B5=""),"",IF(COUNTIFS($A$5:$A$10004,A5,$B$5:$B$10004,B5)>1,"TRÙNG NGÀY + CHUYỀN",IF(G5="","THIẾU MÃ CA / MỤC TIÊU GIỜ",IF(SUMPRODUCT((COLUMN(H5:S5)-COLUMN(H5)+1>ROUNDUP(F5,0))*(H5:S5<>""))>0,"NHẬP QUÁ GIỜ CA",IF(AND(N(X5)>=ROUNDUP(N(F5),0),N(F5)>0,N(T5)<N(G5),AI5=""),"CHƯA GHI LÝ DO KHÔNG ĐẠT",IF(COUNTIFS(MUC_TIEU_THANG!$B$5:$B$2004,C5,MUC_TIEU_THANG!$A$5:$A$2004,">="&DATE(YEAR(A5),MONTH(A5),1),MUC_TIEU_THANG!$A$5:$A$2004,"<"&DATE(YEAR(A5),MONTH(A5)+1,1))=0,"CHƯA CÓ MỤC TIÊU THÁNG","OK")))))) -> OK | AF5: =IF(OR(A5="",B5=""),"",B5&"|"&A5) -> Chuyền 1|46295 | AK5: =IF(OR(T5="",N(AG5)=0,N(X5)=0),"",T5/(AG5*X5)) | AL5: =IF(OR(AH5="",N(T5)=0),"",AH5/T5)
A6: 46295 | B6: Chuyền 2 | C6: BAO TAY XANH | D6: 10H | E6: 100 | F6: =IF(D6="","",IFERROR(INDEX(CAU_HINH_CA!$C$5:$C$50,MATCH(D6,CAU_HINH_CA!$A$5:$A$50,0)),"")) -> 10 | G6: =IF(OR(F6="",E6=""),"",ROUND(F6*E6,0)) -> 1000 | H6: 100 | I6: 100 | T6: =IF(COUNT(H6:S6)=0,"",SUM(H6:S6)) -> 200 | U6: =IF(OR(T6="",N(G6)=0),"",T6/G6) -> 0.2 | V6: =IF(OR(T6="",G6=""),"",T6-G6) -> -800 | W6: =IF(OR(T6="",G6=""),"",MAX(0,G6-T6)) -> 800 | X6: =IF(A6="","",COUNT(H6:S6)) -> 2 | Y6: =IF(OR(X6="",E6="",G6=""),"",MIN(G6,X6*E6)) -> 200 | Z6: =IF(OR(T6="",N(Y6)=0),"",T6/Y6) -> 1 | AA6: =IF(OR(A6="",B6=""),"",IF(SUMPRODUCT(MAX(($B$5:$B$10004=B6)*($A$5:$A$10004<A6)*$A$5:$A$10004))=0,"",SUMPRODUCT(MAX(($B$5:$B$10004=B6)*($A$5:$A$10004<A6)*$A$5:$A$10004)))) -> 46294 | AB6: =IF(N(AA6)=0,"",SUMIFS($W$5:$W$10004,$B$5:$B$10004,B6,$A$5:$A$10004,AA6)) -> 0 | AC6: Đang chạy | AE6: =IF(OR(A6="",B6=""),"",IF(COUNTIFS($A$5:$A$10004,A6,$B$5:$B$10004,B6)>1,"TRÙNG NGÀY + CHUYỀN",IF(G6="","THIẾU MÃ CA / MỤC TIÊU GIỜ",IF(SUMPRODUCT((COLUMN(H6:S6)-COLUMN(H6)+1>ROUNDUP(F6,0))*(H6:S6<>""))>0,"NHẬP QUÁ GIỜ CA",IF(AND(N(X6)>=ROUNDUP(N(F6),0),N(F6)>0,N(T6)<N(G6),AI6=""),"CHƯA GHI LÝ DO KHÔNG ĐẠT",IF(COUNTIFS(MUC_TIEU_THANG!$B$5:$B$2004,C6,MUC_TIEU_THANG!$A$5:$A$2004,">="&DATE(YEAR(A6),MONTH(A6),1),MUC_TIEU_THANG!$A$5:$A$2004,"<"&DATE(YEAR(A6),MONTH(A6)+1,1))=0,"CHƯA CÓ MỤC TIÊU THÁNG","OK")))))) -> OK | AF6: =IF(OR(A6="",B6=""),"",B6&"|"&A6) -> Chuyền 2|46295 | AK6: =IF(OR(T6="",N(AG6)=0,N(X6)=0),"",T6/(AG6*X6)) | AL6: =IF(OR(AH6="",N(T6)=0),"",AH6/T6)
A7: 46295 | B7: Chuyền 3 | C7: 883 | D7: 11H30 | E7: 185 | F7: =IF(D7="","",IFERROR(INDEX(CAU_HINH_CA!$C$5:$C$50,MATCH(D7,CAU_HINH_CA!$A$5:$A$50,0)),"")) -> 11.5 | G7: =IF(OR(F7="",E7=""),"",ROUND(F7*E7,0)) -> 2128 | H7: 180 | I7: 185 | J7: 190 | K7: 170 | T7: =IF(COUNT(H7:S7)=0,"",SUM(H7:S7)) -> 725 | U7: =IF(OR(T7="",N(G7)=0),"",T7/G7) -> 0.34069549 | V7: =IF(OR(T7="",G7=""),"",T7-G7) -> -1403 | W7: =IF(OR(T7="",G7=""),"",MAX(0,G7-T7)) -> 1403 | X7: =IF(A7="","",COUNT(H7:S7)) -> 4 | Y7: =IF(OR(X7="",E7="",G7=""),"",MIN(G7,X7*E7)) -> 740 | Z7: =IF(OR(T7="",N(Y7)=0),"",T7/Y7) -> 0.97972973 | AA7: =IF(OR(A7="",B7=""),"",IF(SUMPRODUCT(MAX(($B$5:$B$10004=B7)*($A$5:$A$10004<A7)*$A$5:$A$10004))=0,"",SUMPRODUCT(MAX(($B$5:$B$10004=B7)*($A$5:$A$10004<A7)*$A$5:$A$10004)))) | AB7: =IF(N(AA7)=0,"",SUMIFS($W$5:$W$10004,$B$5:$B$10004,B7,$A$5:$A$10004,AA7)) | AC7: Đang chạy | AE7: =IF(OR(A7="",B7=""),"",IF(COUNTIFS($A$5:$A$10004,A7,$B$5:$B$10004,B7)>1,"TRÙNG NGÀY + CHUYỀN",IF(G7="","THIẾU MÃ CA / MỤC TIÊU GIỜ",IF(SUMPRODUCT((COLUMN(H7:S7)-COLUMN(H7)+1>ROUNDUP(F7,0))*(H7:S7<>""))>0,"NHẬP QUÁ GIỜ CA",IF(AND(N(X7)>=ROUNDUP(N(F7),0),N(F7)>0,N(T7)<N(G7),AI7=""),"CHƯA GHI LÝ DO KHÔNG ĐẠT",IF(COUNTIFS(MUC_TIEU_THANG!$B$5:$B$2004,C7,MUC_TIEU_THANG!$A$5:$A$2004,">="&DATE(YEAR(A7),MONTH(A7),1),MUC_TIEU_THANG!$A$5:$A$2004,"<"&DATE(YEAR(A7),MONTH(A7)+1,1))=0,"CHƯA CÓ MỤC TIÊU THÁNG","OK")))))) -> OK | AF7: =IF(OR(A7="",B7=""),"",B7&"|"&A7) -> Chuyền 3|46295 | AK7: =IF(OR(T7="",N(AG7)=0,N(X7)=0),"",T7/(AG7*X7)) | AL7: =IF(OR(AH7="",N(T7)=0),"",AH7/T7)
A8: 46295 | B8: Chuyền 4 | C8: MÃ 9H | D8: 9H | E8: 100 | F8: =IF(D8="","",IFERROR(INDEX(CAU_HINH_CA!$C$5:$C$50,MATCH(D8,CAU_HINH_CA!$A$5:$A$50,0)),"")) -> 9 | G8: =IF(OR(F8="",E8=""),"",ROUND(F8*E8,0)) -> 900 | T8: =IF(COUNT(H8:S8)=0,"",SUM(H8:S8)) | U8: =IF(OR(T8="",N(G8)=0),"",T8/G8) | V8: =IF(OR(T8="",G8=""),"",T8-G8) | W8: =IF(OR(T8="",G8=""),"",MAX(0,G8-T8)) | X8: =IF(A8="","",COUNT(H8:S8)) -> 0 | Y8: =IF(OR(X8="",E8="",G8=""),"",MIN(G8,X8*E8)) -> 0 | Z8: =IF(OR(T8="",N(Y8)=0),"",T8/Y8) | AA8: =IF(OR(A8="",B8=""),"",IF(SUMPRODUCT(MAX(($B$5:$B$10004=B8)*($A$5:$A$10004<A8)*$A$5:$A$10004))=0,"",SUMPRODUCT(MAX(($B$5:$B$10004=B8)*($A$5:$A$10004<A8)*$A$5:$A$10004)))) | AB8: =IF(N(AA8)=0,"",SUMIFS($W$5:$W$10004,$B$5:$B$10004,B8,$A$5:$A$10004,AA8)) | AC8: Đang chạy | AE8: =IF(OR(A8="",B8=""),"",IF(COUNTIFS($A$5:$A$10004,A8,$B$5:$B$10004,B8)>1,"TRÙNG NGÀY + CHUYỀN",IF(G8="","THIẾU MÃ CA / MỤC TIÊU GIỜ",IF(SUMPRODUCT((COLUMN(H8:S8)-COLUMN(H8)+1>ROUNDUP(F8,0))*(H8:S8<>""))>0,"NHẬP QUÁ GIỜ CA",IF(AND(N(X8)>=ROUNDUP(N(F8),0),N(F8)>0,N(T8)<N(G8),AI8=""),"CHƯA GHI LÝ DO KHÔNG ĐẠT",IF(COUNTIFS(MUC_TIEU_THANG!$B$5:$B$2004,C8,MUC_TIEU_THANG!$A$5:$A$2004,">="&DATE(YEAR(A8),MONTH(A8),1),MUC_TIEU_THANG!$A$5:$A$2004,"<"&DATE(YEAR(A8),MONTH(A8)+1,1))=0,"CHƯA CÓ MỤC TIÊU THÁNG","OK")))))) -> CHƯA CÓ MỤC TIÊU THÁNG | AF8: =IF(OR(A8="",B8=""),"",B8&"|"&A8) -> Chuyền 4|46295 | AK8: =IF(OR(T8="",N(AG8)=0,N(X8)=0),"",T8/(AG8*X8)) | AL8: =IF(OR(AH8="",N(T8)=0),"",AH8/T8)
A9: 46295 | B9: Chuyền 6 | C9: 567 | D9: 10H | E9: 40 | F9: =IF(D9="","",IFERROR(INDEX(CAU_HINH_CA!$C$5:$C$50,MATCH(D9,CAU_HINH_CA!$A$5:$A$50,0)),"")) -> 10 | G9: =IF(OR(F9="",E9=""),"",ROUND(F9*E9,0)) -> 400 | H9: 40 | I9: 40 | J9: 40 | K9: 40 | L9: 40 | T9: =IF(COUNT(H9:S9)=0,"",SUM(H9:S9)) -> 200 | U9: =IF(OR(T9="",N(G9)=0),"",T9/G9) -> 0.5 | V9: =IF(OR(T9="",G9=""),"",T9-G9) -> -200 | W9: =IF(OR(T9="",G9=""),"",MAX(0,G9-T9)) -> 200 | X9: =IF(A9="","",COUNT(H9:S9)) -> 5 | Y9: =IF(OR(X9="",E9="",G9=""),"",MIN(G9,X9*E9)) -> 200 | Z9: =IF(OR(T9="",N(Y9)=0),"",T9/Y9) -> 1 | AA9: =IF(OR(A9="",B9=""),"",IF(SUMPRODUCT(MAX(($B$5:$B$10004=B9)*($A$5:$A$10004<A9)*$A$5:$A$10004))=0,"",SUMPRODUCT(MAX(($B$5:$B$10004=B9)*($A$5:$A$10004<A9)*$A$5:$A$10004)))) | AB9: =IF(N(AA9)=0,"",SUMIFS($W$5:$W$10004,$B$5:$B$10004,B9,$A$5:$A$10004,AA9)) | AC9: Đang chạy | AE9: =IF(OR(A9="",B9=""),"",IF(COUNTIFS($A$5:$A$10004,A9,$B$5:$B$10004,B9)>1,"TRÙNG NGÀY + CHUYỀN",IF(G9="","THIẾU MÃ CA / MỤC TIÊU GIỜ",IF(SUMPRODUCT((COLUMN(H9:S9)-COLUMN(H9)+1>ROUNDUP(F9,0))*(H9:S9<>""))>0,"NHẬP QUÁ GIỜ CA",IF(AND(N(X9)>=ROUNDUP(N(F9),0),N(F9)>0,N(T9)<N(G9),AI9=""),"CHƯA GHI LÝ DO KHÔNG ĐẠT",IF(COUNTIFS(MUC_TIEU_THANG!$B$5:$B$2004,C9,MUC_TIEU_THANG!$A$5:$A$2004,">="&DATE(YEAR(A9),MONTH(A9),1),MUC_TIEU_THANG!$A$5:$A$2004,"<"&DATE(YEAR(A9),MONTH(A9)+1,1))=0,"CHƯA CÓ MỤC TIÊU THÁNG","OK")))))) -> OK | AF9: =IF(OR(A9="",B9=""),"",B9&"|"&A9) -> Chuyền 6|46295 | AK9: =IF(OR(T9="",N(AG9)=0,N(X9)=0),"",T9/(AG9*X9)) | AL9: =IF(OR(AH9="",N(T9)=0),"",AH9/T9)
A10: 46294 | B10: Chuyền 1 | C10: ĐAI LƯNG | D10: 8H | E10: 100 | F10: =IF(D10="","",IFERROR(INDEX(CAU_HINH_CA!$C$5:$C$50,MATCH(D10,CAU_HINH_CA!$A$5:$A$50,0)),"")) -> 8 | G10: =IF(OR(F10="",E10=""),"",ROUND(F10*E10,0)) -> 800 | H10: 95 | I10: 95 | J10: 95 | K10: 95 | L10: 95 | M10: 95 | N10: 95 | O10: 95 | T10: =IF(COUNT(H10:S10)=0,"",SUM(H10:S10)) -> 760 | U10: =IF(OR(T10="",N(G10)=0),"",T10/G10) -> 0.95 | V10: =IF(OR(T10="",G10=""),"",T10-G10) -> -40 | W10: =IF(OR(T10="",G10=""),"",MAX(0,G10-T10)) -> 40 | X10: =IF(A10="","",COUNT(H10:S10)) -> 8 | Y10: =IF(OR(X10="",E10="",G10=""),"",MIN(G10,X10*E10)) -> 800 | Z10: =IF(OR(T10="",N(Y10)=0),"",T10/Y10) -> 0.95 | AA10: =IF(OR(A10="",B10=""),"",IF(SUMPRODUCT(MAX(($B$5:$B$10004=B10)*($A$5:$A$10004<A10)*$A$5:$A$10004))=0,"",SUMPRODUCT(MAX(($B$5:$B$10004=B10)*($A$5:$A$10004<A10)*$A$5:$A$10004)))) | AB10: =IF(N(AA10)=0,"",SUMIFS($W$5:$W$10004,$B$5:$B$10004,B10,$A$5:$A$10004,AA10)) | AE10: =IF(OR(A10="",B10=""),"",IF(COUNTIFS($A$5:$A$10004,A10,$B$5:$B$10004,B10)>1,"TRÙNG NGÀY + CHUYỀN",IF(G10="","THIẾU MÃ CA / MỤC TIÊU GIỜ",IF(SUMPRODUCT((COLUMN(H10:S10)-COLUMN(H10)+1>ROUNDUP(F10,0))*(H10:S10<>""))>0,"NHẬP QUÁ GIỜ CA",IF(AND(N(X10)>=ROUNDUP(N(F10),0),N(F10)>0,N(T10)<N(G10),AI10=""),"CHƯA GHI LÝ DO KHÔNG ĐẠT",IF(COUNTIFS(MUC_TIEU_THANG!$B$5:$B$2004,C10,MUC_TIEU_THANG!$A$5:$A$2004,">="&DATE(YEAR(A10),MONTH(A10),1),MUC_TIEU_THANG!$A$5:$A$2004,"<"&DATE(YEAR(A10),MONTH(A10)+1,1))=0,"CHƯA CÓ MỤC TIÊU THÁNG","OK")))))) -> OK | AF10: =IF(OR(A10="",B10=""),"",B10&"|"&A10) -> Chuyền 1|46294 | AG10: 20 | AH10: 5 | AI10: Thiếu vật tư | AJ10: 30 | AK10: =IF(OR(T10="",N(AG10)=0,N(X10)=0),"",T10/(AG10*X10)) -> 4.75 | AL10: =IF(OR(AH10="",N(T10)=0),"",AH10/T10) -> 0.0065789474
A11: 46294 | B11: Chuyền 2 | C11: BAO TAY XANH | D11: 10H | E11: 100 | F11: =IF(D11="","",IFERROR(INDEX(CAU_HINH_CA!$C$5:$C$50,MATCH(D11,CAU_HINH_CA!$A$5:$A$50,0)),"")) -> 10 | G11: =IF(OR(F11="",E11=""),"",ROUND(F11*E11,0)) -> 1000 | H11: 100 | I11: 100 | J11: 100 | K11: 100 | L11: 100 | M11: 100 | N11: 100 | O11: 100 | P11: 100 | Q11: 100 | T11: =IF(COUNT(H11:S11)=0,"",SUM(H11:S11)) -> 1000 | U11: =IF(OR(T11="",N(G11)=0),"",T11/G11) -> 1 | V11: =IF(OR(T11="",G11=""),"",T11-G11) -> 0 | W11: =IF(OR(T11="",G11=""),"",MAX(0,G11-T11)) -> 0 | X11: =IF(A11="","",COUNT(H11:S11)) -> 10 | Y11: =IF(OR(X11="",E11="",G11=""),"",MIN(G11,X11*E11)) -> 1000 | Z11: =IF(OR(T11="",N(Y11)=0),"",T11/Y11) -> 1 | AA11: =IF(OR(A11="",B11=""),"",IF(SUMPRODUCT(MAX(($B$5:$B$10004=B11)*($A$5:$A$10004<A11)*$A$5:$A$10004))=0,"",SUMPRODUCT(MAX(($B$5:$B$10004=B11)*($A$5:$A$10004<A11)*$A$5:$A$10004)))) | AB11: =IF(N(AA11)=0,"",SUMIFS($W$5:$W$10004,$B$5:$B$10004,B11,$A$5:$A$10004,AA11)) | AE11: =IF(OR(A11="",B11=""),"",IF(COUNTIFS($A$5:$A$10004,A11,$B$5:$B$10004,B11)>1,"TRÙNG NGÀY + CHUYỀN",IF(G11="","THIẾU MÃ CA / MỤC TIÊU GIỜ",IF(SUMPRODUCT((COLUMN(H11:S11)-COLUMN(H11)+1>ROUNDUP(F11,0))*(H11:S11<>""))>0,"NHẬP QUÁ GIỜ CA",IF(AND(N(X11)>=ROUNDUP(N(F11),0),N(F11)>0,N(T11)<N(G11),AI11=""),"CHƯA GHI LÝ DO KHÔNG ĐẠT",IF(COUNTIFS(MUC_TIEU_THANG!$B$5:$B$2004,C11,MUC_TIEU_THANG!$A$5:$A$2004,">="&DATE(YEAR(A11),MONTH(A11),1),MUC_TIEU_THANG!$A$5:$A$2004,"<"&DATE(YEAR(A11),MONTH(A11)+1,1))=0,"CHƯA CÓ MỤC TIÊU THÁNG","OK")))))) -> OK | AF11: =IF(OR(A11="",B11=""),"",B11&"|"&A11) -> Chuyền 2|46294 | AG11: 25 | AH11: 3 | AK11: =IF(OR(T11="",N(AG11)=0,N(X11)=0),"",T11/(AG11*X11)) -> 4 | AL11: =IF(OR(AH11="",N(T11)=0),"",AH11/T11) -> 0.003
A12: 46296 | B12: Chuyền 1 | C12: ĐAI LƯNG | D12: 8H | E12: 100 | F12: =IF(D12="","",IFERROR(INDEX(CAU_HINH_CA!$C$5:$C$50,MATCH(D12,CAU_HINH_CA!$A$5:$A$50,0)),"")) -> 8 | G12: =IF(OR(F12="",E12=""),"",ROUND(F12*E12,0)) -> 800 | H12: 100 | I12: 100 | J12: 100 | K12: 100 | L12: 100 | M12: 100 | N12: 100 | O12: 100 | T12: =IF(COUNT(H12:S12)=0,"",SUM(H12:S12)) -> 800 | U12: =IF(OR(T12="",N(G12)=0),"",T12/G12) -> 1 | V12: =IF(OR(T12="",G12=""),"",T12-G12) -> 0 | W12: =IF(OR(T12="",G12=""),"",MAX(0,G12-T12)) -> 0 | X12: =IF(A12="","",COUNT(H12:S12)) -> 8 | Y12: =IF(OR(X12="",E12="",G12=""),"",MIN(G12,X12*E12)) -> 800 | Z12: =IF(OR(T12="",N(Y12)=0),"",T12/Y12) -> 1 | AA12: =IF(OR(A12="",B12=""),"",IF(SUMPRODUCT(MAX(($B$5:$B$10004=B12)*($A$5:$A$10004<A12)*$A$5:$A$10004))=0,"",SUMPRODUCT(MAX(($B$5:$B$10004=B12)*($A$5:$A$10004<A12)*$A$5:$A$10004)))) -> 46295 | AB12: =IF(N(AA12)=0,"",SUMIFS($W$5:$W$10004,$B$5:$B$10004,B12,$A$5:$A$10004,AA12)) -> 500 | AE12: =IF(OR(A12="",B12=""),"",IF(COUNTIFS($A$5:$A$10004,A12,$B$5:$B$10004,B12)>1,"TRÙNG NGÀY + CHUYỀN",IF(G12="","THIẾU MÃ CA / MỤC TIÊU GIỜ",IF(SUMPRODUCT((COLUMN(H12:S12)-COLUMN(H12)+1>ROUNDUP(F12,0))*(H12:S12<>""))>0,"NHẬP QUÁ GIỜ CA",IF(AND(N(X12)>=ROUNDUP(N(F12),0),N(F12)>0,N(T12)<N(G12),AI12=""),"CHƯA GHI LÝ DO KHÔNG ĐẠT",IF(COUNTIFS(MUC_TIEU_THANG!$B$5:$B$2004,C12,MUC_TIEU_THANG!$A$5:$A$2004,">="&DATE(YEAR(A12),MONTH(A12),1),MUC_TIEU_THANG!$A$5:$A$2004,"<"&DATE(YEAR(A12),MONTH(A12)+1,1))=0,"CHƯA CÓ MỤC TIÊU THÁNG","OK")))))) -> OK | AF12: =IF(OR(A12="",B12=""),"",B12&"|"&A12) -> Chuyền 1|46296 | AG12: 20 | AH12: 4 | AK12: =IF(OR(T12="",N(AG12)=0,N(X12)=0),"",T12/(AG12*X12)) -> 5 | AL12: =IF(OR(AH12="",N(T12)=0),"",AH12/T12) -> 0.005
A13: 46296 | B13: Chuyền 2 | C13: BAO TAY XANH | D13: 10H | E13: 100 | F13: =IF(D13="","",IFERROR(INDEX(CAU_HINH_CA!$C$5:$C$50,MATCH(D13,CAU_HINH_CA!$A$5:$A$50,0)),"")) -> 10 | G13: =IF(OR(F13="",E13=""),"",ROUND(F13*E13,0)) -> 1000 | H13: 90 | I13: 90 | J13: 90 | K13: 90 | L13: 90 | M13: 90 | N13: 90 | O13: 90 | P13: 90 | Q13: 90 | T13: =IF(COUNT(H13:S13)=0,"",SUM(H13:S13)) -> 900 | U13: =IF(OR(T13="",N(G13)=0),"",T13/G13) -> 0.9 | V13: =IF(OR(T13="",G13=""),"",T13-G13) -> -100 | W13: =IF(OR(T13="",G13=""),"",MAX(0,G13-T13)) -> 100 | X13: =IF(A13="","",COUNT(H13:S13)) -> 10 | Y13: =IF(OR(X13="",E13="",G13=""),"",MIN(G13,X13*E13)) -> 1000 | Z13: =IF(OR(T13="",N(Y13)=0),"",T13/Y13) -> 0.9 | AA13: =IF(OR(A13="",B13=""),"",IF(SUMPRODUCT(MAX(($B$5:$B$10004=B13)*($A$5:$A$10004<A13)*$A$5:$A$10004))=0,"",SUMPRODUCT(MAX(($B$5:$B$10004=B13)*($A$5:$A$10004<A13)*$A$5:$A$10004)))) -> 46295 | AB13: =IF(N(AA13)=0,"",SUMIFS($W$5:$W$10004,$B$5:$B$10004,B13,$A$5:$A$10004,AA13)) -> 800 | AE13: =IF(OR(A13="",B13=""),"",IF(COUNTIFS($A$5:$A$10004,A13,$B$5:$B$10004,B13)>1,"TRÙNG NGÀY + CHUYỀN",IF(G13="","THIẾU MÃ CA / MỤC TIÊU GIỜ",IF(SUMPRODUCT((COLUMN(H13:S13)-COLUMN(H13)+1>ROUNDUP(F13,0))*(H13:S13<>""))>0,"NHẬP QUÁ GIỜ CA",IF(AND(N(X13)>=ROUNDUP(N(F13),0),N(F13)>0,N(T13)<N(G13),AI13=""),"CHƯA GHI LÝ DO KHÔNG ĐẠT",IF(COUNTIFS(MUC_TIEU_THANG!$B$5:$B$2004,C13,MUC_TIEU_THANG!$A$5:$A$2004,">="&DATE(YEAR(A13),MONTH(A13),1),MUC_TIEU_THANG!$A$5:$A$2004,"<"&DATE(YEAR(A13),MONTH(A13)+1,1))=0,"CHƯA CÓ MỤC TIÊU THÁNG","OK")))))) -> OK | AF13: =IF(OR(A13="",B13=""),"",B13&"|"&A13) -> Chuyền 2|46296 | AG13: 25 | AH13: 10 | AI13: Hư máy | AJ13: 45 | AK13: =IF(OR(T13="",N(AG13)=0,N(X13)=0),"",T13/(AG13*X13)) -> 3.6 | AL13: =IF(OR(AH13="",N(T13)=0),"",AH13/T13) -> 0.011111111
A14: 46296 | B14: Chuyền 3 | C14: 883 | D14: 11H30 | E14: 185 | F14: =IF(D14="","",IFERROR(INDEX(CAU_HINH_CA!$C$5:$C$50,MATCH(D14,CAU_HINH_CA!$A$5:$A$50,0)),"")) -> 11.5 | G14: =IF(OR(F14="",E14=""),"",ROUND(F14*E14,0)) -> 2128 | H14: 185 | I14: 185 | J14: 185 | K14: 185 | L14: 185 | M14: 185 | N14: 185 | O14: 185 | P14: 185 | Q14: 185 | R14: 185 | T14: =IF(COUNT(H14:S14)=0,"",SUM(H14:S14)) -> 2035 | U14: =IF(OR(T14="",N(G14)=0),"",T14/G14) -> 0.95629699 | V14: =IF(OR(T14="",G14=""),"",T14-G14) -> -93 | W14: =IF(OR(T14="",G14=""),"",MAX(0,G14-T14)) -> 93 | X14: =IF(A14="","",COUNT(H14:S14)) -> 11 | Y14: =IF(OR(X14="",E14="",G14=""),"",MIN(G14,X14*E14)) -> 2035 | Z14: =IF(OR(T14="",N(Y14)=0),"",T14/Y14) -> 1 | AA14: =IF(OR(A14="",B14=""),"",IF(SUMPRODUCT(MAX(($B$5:$B$10004=B14)*($A$5:$A$10004<A14)*$A$5:$A$10004))=0,"",SUMPRODUCT(MAX(($B$5:$B$10004=B14)*($A$5:$A$10004<A14)*$A$5:$A$10004)))) -> 46295 | AB14: =IF(N(AA14)=0,"",SUMIFS($W$5:$W$10004,$B$5:$B$10004,B14,$A$5:$A$10004,AA14)) -> 1403 | AE14: =IF(OR(A14="",B14=""),"",IF(COUNTIFS($A$5:$A$10004,A14,$B$5:$B$10004,B14)>1,"TRÙNG NGÀY + CHUYỀN",IF(G14="","THIẾU MÃ CA / MỤC TIÊU GIỜ",IF(SUMPRODUCT((COLUMN(H14:S14)-COLUMN(H14)+1>ROUNDUP(F14,0))*(H14:S14<>""))>0,"NHẬP QUÁ GIỜ CA",IF(AND(N(X14)>=ROUNDUP(N(F14),0),N(F14)>0,N(T14)<N(G14),AI14=""),"CHƯA GHI LÝ DO KHÔNG ĐẠT",IF(COUNTIFS(MUC_TIEU_THANG!$B$5:$B$2004,C14,MUC_TIEU_THANG!$A$5:$A$2004,">="&DATE(YEAR(A14),MONTH(A14),1),MUC_TIEU_THANG!$A$5:$A$2004,"<"&DATE(YEAR(A14),MONTH(A14)+1,1))=0,"CHƯA CÓ MỤC TIÊU THÁNG","OK")))))) -> OK | AF14: =IF(OR(A14="",B14=""),"",B14&"|"&A14) -> Chuyền 3|46296 | AG14: 30 | AH14: 2 | AK14: =IF(OR(T14="",N(AG14)=0,N(X14)=0),"",T14/(AG14*X14)) -> 6.1666667 | AL14: =IF(OR(AH14="",N(T14)=0),"",AH14/T14) -> 0.00098280098
A15: 46297 | B15: Chuyền 1 | C15: ĐAI LƯNG | D15: 8H | E15: 100 | F15: =IF(D15="","",IFERROR(INDEX(CAU_HINH_CA!$C$5:$C$50,MATCH(D15,CAU_HINH_CA!$A$5:$A$50,0)),"")) -> 8 | G15: =IF(OR(F15="",E15=""),"",ROUND(F15*E15,0)) -> 800 | H15: 100 | I15: 100 | T15: =IF(COUNT(H15:S15)=0,"",SUM(H15:S15)) -> 200 | U15: =IF(OR(T15="",N(G15)=0),"",T15/G15) -> 0.25 | V15: =IF(OR(T15="",G15=""),"",T15-G15) -> -600 | W15: =IF(OR(T15="",G15=""),"",MAX(0,G15-T15)) -> 600 | X15: =IF(A15="","",COUNT(H15:S15)) -> 2 | Y15: =IF(OR(X15="",E15="",G15=""),"",MIN(G15,X15*E15)) -> 200 | Z15: =IF(OR(T15="",N(Y15)=0),"",T15/Y15) -> 1 | AA15: =IF(OR(A15="",B15=""),"",IF(SUMPRODUCT(MAX(($B$5:$B$10004=B15)*($A$5:$A$10004<A15)*$A$5:$A$10004))=0,"",SUMPRODUCT(MAX(($B$5:$B$10004=B15)*($A$5:$A$10004<A15)*$A$5:$A$10004)))) -> 46296 | AB15: =IF(N(AA15)=0,"",SUMIFS($W$5:$W$10004,$B$5:$B$10004,B15,$A$5:$A$10004,AA15)) -> 0 | AE15: =IF(OR(A15="",B15=""),"",IF(COUNTIFS($A$5:$A$10004,A15,$B$5:$B$10004,B15)>1,"TRÙNG NGÀY + CHUYỀN",IF(G15="","THIẾU MÃ CA / MỤC TIÊU GIỜ",IF(SUMPRODUCT((COLUMN(H15:S15)-COLUMN(H15)+1>ROUNDUP(F15,0))*(H15:S15<>""))>0,"NHẬP QUÁ GIỜ CA",IF(AND(N(X15)>=ROUNDUP(N(F15),0),N(F15)>0,N(T15)<N(G15),AI15=""),"CHƯA GHI LÝ DO KHÔNG ĐẠT",IF(COUNTIFS(MUC_TIEU_THANG!$B$5:$B$2004,C15,MUC_TIEU_THANG!$A$5:$A$2004,">="&DATE(YEAR(A15),MONTH(A15),1),MUC_TIEU_THANG!$A$5:$A$2004,"<"&DATE(YEAR(A15),MONTH(A15)+1,1))=0,"CHƯA CÓ MỤC TIÊU THÁNG","OK")))))) -> OK | AF15: =IF(OR(A15="",B15=""),"",B15&"|"&A15) -> Chuyền 1|46297 | AG15: 20 | AK15: =IF(OR(T15="",N(AG15)=0,N(X15)=0),"",T15/(AG15*X15)) -> 5 | AL15: =IF(OR(AH15="",N(T15)=0),"",AH15/T15)
A16: 46297 | B16: Chuyền 2 | C16: BAO TAY XANH | D16: 10H | E16: 100 | F16: =IF(D16="","",IFERROR(INDEX(CAU_HINH_CA!$C$5:$C$50,MATCH(D16,CAU_HINH_CA!$A$5:$A$50,0)),"")) -> 10 | G16: =IF(OR(F16="",E16=""),"",ROUND(F16*E16,0)) -> 1000 | H16: 80 | I16: 80 | J16: 80 | T16: =IF(COUNT(H16:S16)=0,"",SUM(H16:S16)) -> 240 | U16: =IF(OR(T16="",N(G16)=0),"",T16/G16) -> 0.24 | V16: =IF(OR(T16="",G16=""),"",T16-G16) -> -760 | W16: =IF(OR(T16="",G16=""),"",MAX(0,G16-T16)) -> 760 | X16: =IF(A16="","",COUNT(H16:S16)) -> 3 | Y16: =IF(OR(X16="",E16="",G16=""),"",MIN(G16,X16*E16)) -> 300 | Z16: =IF(OR(T16="",N(Y16)=0),"",T16/Y16) -> 0.8 | AA16: =IF(OR(A16="",B16=""),"",IF(SUMPRODUCT(MAX(($B$5:$B$10004=B16)*($A$5:$A$10004<A16)*$A$5:$A$10004))=0,"",SUMPRODUCT(MAX(($B$5:$B$10004=B16)*($A$5:$A$10004<A16)*$A$5:$A$10004)))) -> 46296 | AB16: =IF(N(AA16)=0,"",SUMIFS($W$5:$W$10004,$B$5:$B$10004,B16,$A$5:$A$10004,AA16)) -> 100 | AE16: =IF(OR(A16="",B16=""),"",IF(COUNTIFS($A$5:$A$10004,A16,$B$5:$B$10004,B16)>1,"TRÙNG NGÀY + CHUYỀN",IF(G16="","THIẾU MÃ CA / MỤC TIÊU GIỜ",IF(SUMPRODUCT((COLUMN(H16:S16)-COLUMN(H16)+1>ROUNDUP(F16,0))*(H16:S16<>""))>0,"NHẬP QUÁ GIỜ CA",IF(AND(N(X16)>=ROUNDUP(N(F16),0),N(F16)>0,N(T16)<N(G16),AI16=""),"CHƯA GHI LÝ DO KHÔNG ĐẠT",IF(COUNTIFS(MUC_TIEU_THANG!$B$5:$B$2004,C16,MUC_TIEU_THANG!$A$5:$A$2004,">="&DATE(YEAR(A16),MONTH(A16),1),MUC_TIEU_THANG!$A$5:$A$2004,"<"&DATE(YEAR(A16),MONTH(A16)+1,1))=0,"CHƯA CÓ MỤC TIÊU THÁNG","OK")))))) -> OK | AF16: =IF(OR(A16="",B16=""),"",B16&"|"&A16) -> Chuyền 2|46297 | AG16: 25 | AH16: 1 | AK16: =IF(OR(T16="",N(AG16)=0,N(X16)=0),"",T16/(AG16*X16)) -> 3.2 | AL16: =IF(OR(AH16="",N(T16)=0),"",AH16/T16) -> 0.0041666667
A17: 46296 | B17: Chuyền 6 | C17: 567 | D17: 10H | E17: 40 | F17: =IF(D17="","",IFERROR(INDEX(CAU_HINH_CA!$C$5:$C$50,MATCH(D17,CAU_HINH_CA!$A$5:$A$50,0)),"")) -> 10 | G17: =IF(OR(F17="",E17=""),"",ROUND(F17*E17,0)) -> 400 | H17: 30 | I17: 30 | J17: 30 | K17: 30 | L17: 30 | M17: 30 | N17: 30 | O17: 30 | P17: 30 | Q17: 30 | T17: =IF(COUNT(H17:S17)=0,"",SUM(H17:S17)) -> 300 | U17: =IF(OR(T17="",N(G17)=0),"",T17/G17) -> 0.75 | V17: =IF(OR(T17="",G17=""),"",T17-G17) -> -100 | W17: =IF(OR(T17="",G17=""),"",MAX(0,G17-T17)) -> 100 | X17: =IF(A17="","",COUNT(H17:S17)) -> 10 | Y17: =IF(OR(X17="",E17="",G17=""),"",MIN(G17,X17*E17)) -> 400 | Z17: =IF(OR(T17="",N(Y17)=0),"",T17/Y17) -> 0.75 | AA17: =IF(OR(A17="",B17=""),"",IF(SUMPRODUCT(MAX(($B$5:$B$10004=B17)*($A$5:$A$10004<A17)*$A$5:$A$10004))=0,"",SUMPRODUCT(MAX(($B$5:$B$10004=B17)*($A$5:$A$10004<A17)*$A$5:$A$10004)))) -> 46295 | AB17: =IF(N(AA17)=0,"",SUMIFS($W$5:$W$10004,$B$5:$B$10004,B17,$A$5:$A$10004,AA17)) -> 200 | AE17: =IF(OR(A17="",B17=""),"",IF(COUNTIFS($A$5:$A$10004,A17,$B$5:$B$10004,B17)>1,"TRÙNG NGÀY + CHUYỀN",IF(G17="","THIẾU MÃ CA / MỤC TIÊU GIỜ",IF(SUMPRODUCT((COLUMN(H17:S17)-COLUMN(H17)+1>ROUNDUP(F17,0))*(H17:S17<>""))>0,"NHẬP QUÁ GIỜ CA",IF(AND(N(X17)>=ROUNDUP(N(F17),0),N(F17)>0,N(T17)<N(G17),AI17=""),"CHƯA GHI LÝ DO KHÔNG ĐẠT",IF(COUNTIFS(MUC_TIEU_THANG!$B$5:$B$2004,C17,MUC_TIEU_THANG!$A$5:$A$2004,">="&DATE(YEAR(A17),MONTH(A17),1),MUC_TIEU_THANG!$A$5:$A$2004,"<"&DATE(YEAR(A17),MONTH(A17)+1,1))=0,"CHƯA CÓ MỤC TIÊU THÁNG","OK")))))) -> CHƯA GHI LÝ DO KHÔNG ĐẠT | AF17: =IF(OR(A17="",B17=""),"",B17&"|"&A17) -> Chuyền 6|46296 | AG17: 8 | AK17: =IF(OR(T17="",N(AG17)=0,N(X17)=0),"",T17/(AG17*X17)) -> 3.75 | AL17: =IF(OR(AH17="",N(T17)=0),"",AH17/T17)

Sheet MUC_TIEU_THANG
A1: 當月目標與累計 / MỤC TIÊU & LŨY KẾ THÁNG
A2: 月份 | B2: 产品代码 | C2: 当月总目标产量PCS | D2: 備註 | E2: 当月累计产能PCS | F2: 当月累计差异PCS | G2: 当月总达成率 | H2: 剩餘PCS | I2: 累計每日目標PCS | J2: 與每日目標差異PCS | K2: 上月欠數PCS | L2: 當月工作天數 | M2: 平均每日需產量PCS
A3: THÁNG | B3: MÃ SẢN PHẨM | C3: TỔNG SẢN LƯỢNG MỤC TIÊU TRONG THÁNG | D3: GHI CHÚ | E3: LŨY KẾ SẢN LƯỢNG TRONG THÁNG | F3: LŨY KẾ CHÊNH LỆCH TRONG THÁNG | G3: TỔNG ĐẠT % TRONG THÁNG | H3: CÒN THIẾU TRONG THÁNG | I3: LŨY KẾ MỤC TIÊU NGÀY (các ngày đã nhập) | J3: CHÊNH LỆCH SO VỚI MỤC TIÊU NGÀY | K3: THIẾU THÁNG TRƯỚC | L3: SỐ NGÀY LÀM VIỆC TRONG THÁNG | M3: BÌNH QUÂN CẦN / NGÀY
A4: 1 | B4: 2 | C4: 3 | D4: 4 | E4: 5 | F4: 6 | G4: 7 | H4: 8 | I4: 9 | J4: 10 | K4: 11 | L4: 12 | M4: 13
A5: 46266 | B5: ĐAI LƯNG | C5: 40000 | E5: =IF(OR(A5="",B5=""),"",SUMPRODUCT((NHAP_LIEU!$C$5:$C$10004=B5)*(NHAP_LIEU!$A$5:$A$10004>=DATE(YEAR(A5),MONTH(A5),1))*(NHAP_LIEU!$A$5:$A$10004<DATE(YEAR(A5),MONTH(A5)+1,1))*NHAP_LIEU!$H$5:$S$10004)) -> 1060 | F5: =IF(OR(E5="",C5=""),"",E5-C5) -> -38940 | G5: =IF(OR(E5="",N(C5)=0),"",E5/C5) -> 0.0265 | H5: =IF(OR(E5="",C5=""),"",MAX(0,C5-E5)) -> 38940 | I5: =IF(OR(A5="",B5=""),"",SUMPRODUCT((NHAP_LIEU!$C$5:$C$10004=B5)*(NHAP_LIEU!$A$5:$A$10004>=DATE(YEAR(A5),MONTH(A5),1))*(NHAP_LIEU!$A$5:$A$10004<DATE(YEAR(A5),MONTH(A5)+1,1))*(((NHAP_LIEU!$H$5:$H$10004<>"")+(NHAP_LIEU!$I$5:$I$10004<>"")+(NHAP_LIEU!$J$5:$J$10004<>"")+(NHAP_LIEU!$K$5:$K$10004<>"")+(NHAP_LIEU!$L$5:$L$10004<>"")+(NHAP_LIEU!$M$5:$M$10004<>"")+(NHAP_LIEU!$N$5:$N$10004<>"")+(NHAP_LIEU!$O$5:$O$10004<>"")+(NHAP_LIEU!$P$5:$P$10004<>"")+(NHAP_LIEU!$Q$5:$Q$10004<>"")+(NHAP_LIEU!$R$5:$R$10004<>"")+(NHAP_LIEU!$S$5:$S$10004<>""))>0)*ROUND(SUMIF(CAU_HINH_CA!$A$5:$A$50,NHAP_LIEU!$D$5:$D$10004,CAU_HINH_CA!$C$5:$C$50)*NHAP_LIEU!$E$5:$E$10004,0))) -> 1600 | J5: =IF(I5="","",E5-I5) -> -540 | K5: =IF(OR(A5="",B5=""),"",SUMIFS($H$5:$H$2004,$B$5:$B$2004,B5,$A$5:$A$2004,">="&DATE(YEAR(A5),MONTH(A5)-1,1),$A$5:$A$2004,"<"&DATE(YEAR(A5),MONTH(A5),1))) -> 0 | L5: =IF(A5="","",MAX(0,NETWORKDAYS.INTL(DATE(YEAR(A5),MONTH(A5),1),EOMONTH(A5,0),11)-SUMPRODUCT((LICH_LAM_VIEC!$A$5:$A$1000>=DATE(YEAR(A5),MONTH(A5),1))*(LICH_LAM_VIEC!$A$5:$A$1000<=EOMONTH(A5,0))*(LICH_LAM_VIEC!$B$5:$B$1000="Nghỉ")*(WEEKDAY(LICH_LAM_VIEC!$A$5:$A$1000)<>1))+SUMPRODUCT((LICH_LAM_VIEC!$A$5:$A$1000>=DATE(YEAR(A5),MONTH(A5),1))*(LICH_LAM_VIEC!$A$5:$A$1000<=EOMONTH(A5,0))*(LICH_LAM_VIEC!$B$5:$B$1000="Làm bù")*(WEEKDAY(LICH_LAM_VIEC!$A$5:$A$1000)=1)))) -> 26 | M5: =IF(OR(N(L5)=0,C5=""),"",ROUNDUP(C5/L5,0)) -> 1539
A6: 46266 | B6: BAO TAY XANH | C6: 40000 | E6: =IF(OR(A6="",B6=""),"",SUMPRODUCT((NHAP_LIEU!$C$5:$C$10004=B6)*(NHAP_LIEU!$A$5:$A$10004>=DATE(YEAR(A6),MONTH(A6),1))*(NHAP_LIEU!$A$5:$A$10004<DATE(YEAR(A6),MONTH(A6)+1,1))*NHAP_LIEU!$H$5:$S$10004)) -> 1200 | F6: =IF(OR(E6="",C6=""),"",E6-C6) -> -38800 | G6: =IF(OR(E6="",N(C6)=0),"",E6/C6) -> 0.03 | H6: =IF(OR(E6="",C6=""),"",MAX(0,C6-E6)) -> 38800 | I6: =IF(OR(A6="",B6=""),"",SUMPRODUCT((NHAP_LIEU!$C$5:$C$10004=B6)*(NHAP_LIEU!$A$5:$A$10004>=DATE(YEAR(A6),MONTH(A6),1))*(NHAP_LIEU!$A$5:$A$10004<DATE(YEAR(A6),MONTH(A6)+1,1))*(((NHAP_LIEU!$H$5:$H$10004<>"")+(NHAP_LIEU!$I$5:$I$10004<>"")+(NHAP_LIEU!$J$5:$J$10004<>"")+(NHAP_LIEU!$K$5:$K$10004<>"")+(NHAP_LIEU!$L$5:$L$10004<>"")+(NHAP_LIEU!$M$5:$M$10004<>"")+(NHAP_LIEU!$N$5:$N$10004<>"")+(NHAP_LIEU!$O$5:$O$10004<>"")+(NHAP_LIEU!$P$5:$P$10004<>"")+(NHAP_LIEU!$Q$5:$Q$10004<>"")+(NHAP_LIEU!$R$5:$R$10004<>"")+(NHAP_LIEU!$S$5:$S$10004<>""))>0)*ROUND(SUMIF(CAU_HINH_CA!$A$5:$A$50,NHAP_LIEU!$D$5:$D$10004,CAU_HINH_CA!$C$5:$C$50)*NHAP_LIEU!$E$5:$E$10004,0))) -> 2000 | J6: =IF(I6="","",E6-I6) -> -800 | K6: =IF(OR(A6="",B6=""),"",SUMIFS($H$5:$H$2004,$B$5:$B$2004,B6,$A$5:$A$2004,">="&DATE(YEAR(A6),MONTH(A6)-1,1),$A$5:$A$2004,"<"&DATE(YEAR(A6),MONTH(A6),1))) -> 0 | L6: =IF(A6="","",MAX(0,NETWORKDAYS.INTL(DATE(YEAR(A6),MONTH(A6),1),EOMONTH(A6,0),11)-SUMPRODUCT((LICH_LAM_VIEC!$A$5:$A$1000>=DATE(YEAR(A6),MONTH(A6),1))*(LICH_LAM_VIEC!$A$5:$A$1000<=EOMONTH(A6,0))*(LICH_LAM_VIEC!$B$5:$B$1000="Nghỉ")*(WEEKDAY(LICH_LAM_VIEC!$A$5:$A$1000)<>1))+SUMPRODUCT((LICH_LAM_VIEC!$A$5:$A$1000>=DATE(YEAR(A6),MONTH(A6),1))*(LICH_LAM_VIEC!$A$5:$A$1000<=EOMONTH(A6,0))*(LICH_LAM_VIEC!$B$5:$B$1000="Làm bù")*(WEEKDAY(LICH_LAM_VIEC!$A$5:$A$1000)=1)))) -> 26 | M6: =IF(OR(N(L6)=0,C6=""),"",ROUNDUP(C6/L6,0)) -> 1539
A7: 46266 | B7: 883 | C7: 50000 | E7: =IF(OR(A7="",B7=""),"",SUMPRODUCT((NHAP_LIEU!$C$5:$C$10004=B7)*(NHAP_LIEU!$A$5:$A$10004>=DATE(YEAR(A7),MONTH(A7),1))*(NHAP_LIEU!$A$5:$A$10004<DATE(YEAR(A7),MONTH(A7)+1,1))*NHAP_LIEU!$H$5:$S$10004)) -> 725 | F7: =IF(OR(E7="",C7=""),"",E7-C7) -> -49275 | G7: =IF(OR(E7="",N(C7)=0),"",E7/C7) -> 0.0145 | H7: =IF(OR(E7="",C7=""),"",MAX(0,C7-E7)) -> 49275 | I7: =IF(OR(A7="",B7=""),"",SUMPRODUCT((NHAP_LIEU!$C$5:$C$10004=B7)*(NHAP_LIEU!$A$5:$A$10004>=DATE(YEAR(A7),MONTH(A7),1))*(NHAP_LIEU!$A$5:$A$10004<DATE(YEAR(A7),MONTH(A7)+1,1))*(((NHAP_LIEU!$H$5:$H$10004<>"")+(NHAP_LIEU!$I$5:$I$10004<>"")+(NHAP_LIEU!$J$5:$J$10004<>"")+(NHAP_LIEU!$K$5:$K$10004<>"")+(NHAP_LIEU!$L$5:$L$10004<>"")+(NHAP_LIEU!$M$5:$M$10004<>"")+(NHAP_LIEU!$N$5:$N$10004<>"")+(NHAP_LIEU!$O$5:$O$10004<>"")+(NHAP_LIEU!$P$5:$P$10004<>"")+(NHAP_LIEU!$Q$5:$Q$10004<>"")+(NHAP_LIEU!$R$5:$R$10004<>"")+(NHAP_LIEU!$S$5:$S$10004<>""))>0)*ROUND(SUMIF(CAU_HINH_CA!$A$5:$A$50,NHAP_LIEU!$D$5:$D$10004,CAU_HINH_CA!$C$5:$C$50)*NHAP_LIEU!$E$5:$E$10004,0))) -> 2128 | J7: =IF(I7="","",E7-I7) -> -1403 | K7: =IF(OR(A7="",B7=""),"",SUMIFS($H$5:$H$2004,$B$5:$B$2004,B7,$A$5:$A$2004,">="&DATE(YEAR(A7),MONTH(A7)-1,1),$A$5:$A$2004,"<"&DATE(YEAR(A7),MONTH(A7),1))) -> 0 | L7: =IF(A7="","",MAX(0,NETWORKDAYS.INTL(DATE(YEAR(A7),MONTH(A7),1),EOMONTH(A7,0),11)-SUMPRODUCT((LICH_LAM_VIEC!$A$5:$A$1000>=DATE(YEAR(A7),MONTH(A7),1))*(LICH_LAM_VIEC!$A$5:$A$1000<=EOMONTH(A7,0))*(LICH_LAM_VIEC!$B$5:$B$1000="Nghỉ")*(WEEKDAY(LICH_LAM_VIEC!$A$5:$A$1000)<>1))+SUMPRODUCT((LICH_LAM_VIEC!$A$5:$A$1000>=DATE(YEAR(A7),MONTH(A7),1))*(LICH_LAM_VIEC!$A$5:$A$1000<=EOMONTH(A7,0))*(LICH_LAM_VIEC!$B$5:$B$1000="Làm bù")*(WEEKDAY(LICH_LAM_VIEC!$A$5:$A$1000)=1)))) -> 26 | M7: =IF(OR(N(L7)=0,C7=""),"",ROUNDUP(C7/L7,0)) -> 1924
A8: 46266 | B8: 567 | C8: 100000 | D8: Test | E8: =IF(OR(A8="",B8=""),"",SUMPRODUCT((NHAP_LIEU!$C$5:$C$10004=B8)*(NHAP_LIEU!$A$5:$A$10004>=DATE(YEAR(A8),MONTH(A8),1))*(NHAP_LIEU!$A$5:$A$10004<DATE(YEAR(A8),MONTH(A8)+1,1))*NHAP_LIEU!$H$5:$S$10004)) -> 200 | F8: =IF(OR(E8="",C8=""),"",E8-C8) -> -99800 | G8: =IF(OR(E8="",N(C8)=0),"",E8/C8) -> 0.002 | H8: =IF(OR(E8="",C8=""),"",MAX(0,C8-E8)) -> 99800 | I8: =IF(OR(A8="",B8=""),"",SUMPRODUCT((NHAP_LIEU!$C$5:$C$10004=B8)*(NHAP_LIEU!$A$5:$A$10004>=DATE(YEAR(A8),MONTH(A8),1))*(NHAP_LIEU!$A$5:$A$10004<DATE(YEAR(A8),MONTH(A8)+1,1))*(((NHAP_LIEU!$H$5:$H$10004<>"")+(NHAP_LIEU!$I$5:$I$10004<>"")+(NHAP_LIEU!$J$5:$J$10004<>"")+(NHAP_LIEU!$K$5:$K$10004<>"")+(NHAP_LIEU!$L$5:$L$10004<>"")+(NHAP_LIEU!$M$5:$M$10004<>"")+(NHAP_LIEU!$N$5:$N$10004<>"")+(NHAP_LIEU!$O$5:$O$10004<>"")+(NHAP_LIEU!$P$5:$P$10004<>"")+(NHAP_LIEU!$Q$5:$Q$10004<>"")+(NHAP_LIEU!$R$5:$R$10004<>"")+(NHAP_LIEU!$S$5:$S$10004<>""))>0)*ROUND(SUMIF(CAU_HINH_CA!$A$5:$A$50,NHAP_LIEU!$D$5:$D$10004,CAU_HINH_CA!$C$5:$C$50)*NHAP_LIEU!$E$5:$E$10004,0))) -> 400 | J8: =IF(I8="","",E8-I8) -> -200 | K8: =IF(OR(A8="",B8=""),"",SUMIFS($H$5:$H$2004,$B$5:$B$2004,B8,$A$5:$A$2004,">="&DATE(YEAR(A8),MONTH(A8)-1,1),$A$5:$A$2004,"<"&DATE(YEAR(A8),MONTH(A8),1))) -> 0 | L8: =IF(A8="","",MAX(0,NETWORKDAYS.INTL(DATE(YEAR(A8),MONTH(A8),1),EOMONTH(A8,0),11)-SUMPRODUCT((LICH_LAM_VIEC!$A$5:$A$1000>=DATE(YEAR(A8),MONTH(A8),1))*(LICH_LAM_VIEC!$A$5:$A$1000<=EOMONTH(A8,0))*(LICH_LAM_VIEC!$B$5:$B$1000="Nghỉ")*(WEEKDAY(LICH_LAM_VIEC!$A$5:$A$1000)<>1))+SUMPRODUCT((LICH_LAM_VIEC!$A$5:$A$1000>=DATE(YEAR(A8),MONTH(A8),1))*(LICH_LAM_VIEC!$A$5:$A$1000<=EOMONTH(A8,0))*(LICH_LAM_VIEC!$B$5:$B$1000="Làm bù")*(WEEKDAY(LICH_LAM_VIEC!$A$5:$A$1000)=1)))) -> 26 | M8: =IF(OR(N(L8)=0,C8=""),"",ROUNDUP(C8/L8,0)) -> 3847
A9: 46296 | B9: ĐAI LƯNG | C9: 42000 | E9: =IF(OR(A9="",B9=""),"",SUMPRODUCT((NHAP_LIEU!$C$5:$C$10004=B9)*(NHAP_LIEU!$A$5:$A$10004>=DATE(YEAR(A9),MONTH(A9),1))*(NHAP_LIEU!$A$5:$A$10004<DATE(YEAR(A9),MONTH(A9)+1,1))*NHAP_LIEU!$H$5:$S$10004)) -> 1000 | F9: =IF(OR(E9="",C9=""),"",E9-C9) -> -41000 | G9: =IF(OR(E9="",N(C9)=0),"",E9/C9) -> 0.023809524 | H9: =IF(OR(E9="",C9=""),"",MAX(0,C9-E9)) -> 41000 | I9: =IF(OR(A9="",B9=""),"",SUMPRODUCT((NHAP_LIEU!$C$5:$C$10004=B9)*(NHAP_LIEU!$A$5:$A$10004>=DATE(YEAR(A9),MONTH(A9),1))*(NHAP_LIEU!$A$5:$A$10004<DATE(YEAR(A9),MONTH(A9)+1,1))*(((NHAP_LIEU!$H$5:$H$10004<>"")+(NHAP_LIEU!$I$5:$I$10004<>"")+(NHAP_LIEU!$J$5:$J$10004<>"")+(NHAP_LIEU!$K$5:$K$10004<>"")+(NHAP_LIEU!$L$5:$L$10004<>"")+(NHAP_LIEU!$M$5:$M$10004<>"")+(NHAP_LIEU!$N$5:$N$10004<>"")+(NHAP_LIEU!$O$5:$O$10004<>"")+(NHAP_LIEU!$P$5:$P$10004<>"")+(NHAP_LIEU!$Q$5:$Q$10004<>"")+(NHAP_LIEU!$R$5:$R$10004<>"")+(NHAP_LIEU!$S$5:$S$10004<>""))>0)*ROUND(SUMIF(CAU_HINH_CA!$A$5:$A$50,NHAP_LIEU!$D$5:$D$10004,CAU_HINH_CA!$C$5:$C$50)*NHAP_LIEU!$E$5:$E$10004,0))) -> 1600 | J9: =IF(I9="","",E9-I9) -> -600 | K9: =IF(OR(A9="",B9=""),"",SUMIFS($H$5:$H$2004,$B$5:$B$2004,B9,$A$5:$A$2004,">="&DATE(YEAR(A9),MONTH(A9)-1,1),$A$5:$A$2004,"<"&DATE(YEAR(A9),MONTH(A9),1))) -> 38940 | L9: =IF(A9="","",MAX(0,NETWORKDAYS.INTL(DATE(YEAR(A9),MONTH(A9),1),EOMONTH(A9,0),11)-SUMPRODUCT((LICH_LAM_VIEC!$A$5:$A$1000>=DATE(YEAR(A9),MONTH(A9),1))*(LICH_LAM_VIEC!$A$5:$A$1000<=EOMONTH(A9,0))*(LICH_LAM_VIEC!$B$5:$B$1000="Nghỉ")*(WEEKDAY(LICH_LAM_VIEC!$A$5:$A$1000)<>1))+SUMPRODUCT((LICH_LAM_VIEC!$A$5:$A$1000>=DATE(YEAR(A9),MONTH(A9),1))*(LICH_LAM_VIEC!$A$5:$A$1000<=EOMONTH(A9,0))*(LICH_LAM_VIEC!$B$5:$B$1000="Làm bù")*(WEEKDAY(LICH_LAM_VIEC!$A$5:$A$1000)=1)))) -> 27 | M9: =IF(OR(N(L9)=0,C9=""),"",ROUNDUP(C9/L9,0)) -> 1556
A10: 46296 | B10: BAO TAY XANH | C10: 40000 | E10: =IF(OR(A10="",B10=""),"",SUMPRODUCT((NHAP_LIEU!$C$5:$C$10004=B10)*(NHAP_LIEU!$A$5:$A$10004>=DATE(YEAR(A10),MONTH(A10),1))*(NHAP_LIEU!$A$5:$A$10004<DATE(YEAR(A10),MONTH(A10)+1,1))*NHAP_LIEU!$H$5:$S$10004)) -> 1140 | F10: =IF(OR(E10="",C10=""),"",E10-C10) -> -38860 | G10: =IF(OR(E10="",N(C10)=0),"",E10/C10) -> 0.0285 | H10: =IF(OR(E10="",C10=""),"",MAX(0,C10-E10)) -> 38860 | I10: =IF(OR(A10="",B10=""),"",SUMPRODUCT((NHAP_LIEU!$C$5:$C$10004=B10)*(NHAP_LIEU!$A$5:$A$10004>=DATE(YEAR(A10),MONTH(A10),1))*(NHAP_LIEU!$A$5:$A$10004<DATE(YEAR(A10),MONTH(A10)+1,1))*(((NHAP_LIEU!$H$5:$H$10004<>"")+(NHAP_LIEU!$I$5:$I$10004<>"")+(NHAP_LIEU!$J$5:$J$10004<>"")+(NHAP_LIEU!$K$5:$K$10004<>"")+(NHAP_LIEU!$L$5:$L$10004<>"")+(NHAP_LIEU!$M$5:$M$10004<>"")+(NHAP_LIEU!$N$5:$N$10004<>"")+(NHAP_LIEU!$O$5:$O$10004<>"")+(NHAP_LIEU!$P$5:$P$10004<>"")+(NHAP_LIEU!$Q$5:$Q$10004<>"")+(NHAP_LIEU!$R$5:$R$10004<>"")+(NHAP_LIEU!$S$5:$S$10004<>""))>0)*ROUND(SUMIF(CAU_HINH_CA!$A$5:$A$50,NHAP_LIEU!$D$5:$D$10004,CAU_HINH_CA!$C$5:$C$50)*NHAP_LIEU!$E$5:$E$10004,0))) -> 2000 | J10: =IF(I10="","",E10-I10) -> -860 | K10: =IF(OR(A10="",B10=""),"",SUMIFS($H$5:$H$2004,$B$5:$B$2004,B10,$A$5:$A$2004,">="&DATE(YEAR(A10),MONTH(A10)-1,1),$A$5:$A$2004,"<"&DATE(YEAR(A10),MONTH(A10),1))) -> 38800 | L10: =IF(A10="","",MAX(0,NETWORKDAYS.INTL(DATE(YEAR(A10),MONTH(A10),1),EOMONTH(A10,0),11)-SUMPRODUCT((LICH_LAM_VIEC!$A$5:$A$1000>=DATE(YEAR(A10),MONTH(A10),1))*(LICH_LAM_VIEC!$A$5:$A$1000<=EOMONTH(A10,0))*(LICH_LAM_VIEC!$B$5:$B$1000="Nghỉ")*(WEEKDAY(LICH_LAM_VIEC!$A$5:$A$1000)<>1))+SUMPRODUCT((LICH_LAM_VIEC!$A$5:$A$1000>=DATE(YEAR(A10),MONTH(A10),1))*(LICH_LAM_VIEC!$A$5:$A$1000<=EOMONTH(A10,0))*(LICH_LAM_VIEC!$B$5:$B$1000="Làm bù")*(WEEKDAY(LICH_LAM_VIEC!$A$5:$A$1000)=1)))) -> 27 | M10: =IF(OR(N(L10)=0,C10=""),"",ROUNDUP(C10/L10,0)) -> 1482
A11: 46296 | B11: 883 | C11: 50000 | E11: =IF(OR(A11="",B11=""),"",SUMPRODUCT((NHAP_LIEU!$C$5:$C$10004=B11)*(NHAP_LIEU!$A$5:$A$10004>=DATE(YEAR(A11),MONTH(A11),1))*(NHAP_LIEU!$A$5:$A$10004<DATE(YEAR(A11),MONTH(A11)+1,1))*NHAP_LIEU!$H$5:$S$10004)) -> 2035 | F11: =IF(OR(E11="",C11=""),"",E11-C11) -> -47965 | G11: =IF(OR(E11="",N(C11)=0),"",E11/C11) -> 0.0407 | H11: =IF(OR(E11="",C11=""),"",MAX(0,C11-E11)) -> 47965 | I11: =IF(OR(A11="",B11=""),"",SUMPRODUCT((NHAP_LIEU!$C$5:$C$10004=B11)*(NHAP_LIEU!$A$5:$A$10004>=DATE(YEAR(A11),MONTH(A11),1))*(NHAP_LIEU!$A$5:$A$10004<DATE(YEAR(A11),MONTH(A11)+1,1))*(((NHAP_LIEU!$H$5:$H$10004<>"")+(NHAP_LIEU!$I$5:$I$10004<>"")+(NHAP_LIEU!$J$5:$J$10004<>"")+(NHAP_LIEU!$K$5:$K$10004<>"")+(NHAP_LIEU!$L$5:$L$10004<>"")+(NHAP_LIEU!$M$5:$M$10004<>"")+(NHAP_LIEU!$N$5:$N$10004<>"")+(NHAP_LIEU!$O$5:$O$10004<>"")+(NHAP_LIEU!$P$5:$P$10004<>"")+(NHAP_LIEU!$Q$5:$Q$10004<>"")+(NHAP_LIEU!$R$5:$R$10004<>"")+(NHAP_LIEU!$S$5:$S$10004<>""))>0)*ROUND(SUMIF(CAU_HINH_CA!$A$5:$A$50,NHAP_LIEU!$D$5:$D$10004,CAU_HINH_CA!$C$5:$C$50)*NHAP_LIEU!$E$5:$E$10004,0))) -> 2128 | J11: =IF(I11="","",E11-I11) -> -93 | K11: =IF(OR(A11="",B11=""),"",SUMIFS($H$5:$H$2004,$B$5:$B$2004,B11,$A$5:$A$2004,">="&DATE(YEAR(A11),MONTH(A11)-1,1),$A$5:$A$2004,"<"&DATE(YEAR(A11),MONTH(A11),1))) -> 49275 | L11: =IF(A11="","",MAX(0,NETWORKDAYS.INTL(DATE(YEAR(A11),MONTH(A11),1),EOMONTH(A11,0),11)-SUMPRODUCT((LICH_LAM_VIEC!$A$5:$A$1000>=DATE(YEAR(A11),MONTH(A11),1))*(LICH_LAM_VIEC!$A$5:$A$1000<=EOMONTH(A11,0))*(LICH_LAM_VIEC!$B$5:$B$1000="Nghỉ")*(WEEKDAY(LICH_LAM_VIEC!$A$5:$A$1000)<>1))+SUMPRODUCT((LICH_LAM_VIEC!$A$5:$A$1000>=DATE(YEAR(A11),MONTH(A11),1))*(LICH_LAM_VIEC!$A$5:$A$1000<=EOMONTH(A11,0))*(LICH_LAM_VIEC!$B$5:$B$1000="Làm bù")*(WEEKDAY(LICH_LAM_VIEC!$A$5:$A$1000)=1)))) -> 27 | M11: =IF(OR(N(L11)=0,C11=""),"",ROUNDUP(C11/L11,0)) -> 1852

Sheet HIEN_THI
A1: 電視顯示 / BẢNG HIỂN THỊ TV | G1: CHỌN NGÀY (để trống = ngày mới nhất): | K1: ĐANG HIỂN THỊ: | M1: =IF(J1<>"",J1,MAX(NHAP_LIEU!$A$5:$A$10004)) -> 46297
A2: 日期 | B2: 產線 | C2: 产品代码 | D2: 工作時間 | E2: 總工時 | F2: 每小时目标产量PCS | G2: 每日目标产量PCS | H2: 每日实际产量PCS | I2: 当日达成率% | J2: 差異PCS | K2: 剩餘PCS | L2: 已輸入小時數 | M2: 累計目標PCS | N2: 進度達成率% | O2: 前一工作日 | P2: 前一日欠數PCS | Q2: 当月总目标产量PCS | R2: 当月累计产能PCS | S2: 当月总达成率 | T2: 剩餘PCS | U2: 本線當月累計PCS | V2: 第1小時 | W2: 第2小時 | X2: 第3小時 | Y2: 第4小時 | Z2: 第5小時 | AA2: 第6小時 | AB2: 第7小時 | AC2: 第8小時 | AD2: 第9小時 | AE2: 第10小時 | AF2: 第11小時 | AG2: 第12小時 | AH2: 狀態 | AI2: 備註 | AJ2: 索引 | AK2: 前一日索引 | AL2: 上月欠數PCS | AM2: 剩餘工作天數 | AN2: 每日需產量PCS | AO2: 工人數 | AP2: 人均每小時產量 | AQ2: 不良數PCS | AR2: 不良率% | AS2: 未達原因 | AT2: 停機分鐘
A3: NGÀY | B3: CHUYỀN | C3: MÃ SẢN PHẨM | D3: MÃ CA | E3: GIỜ CA | F3: MỤC TIÊU MỖI GIỜ | G3: MỤC TIÊU TRONG NGÀY | H3: THỰC TẾ TRONG NGÀY | I3: TỶ LỆ ĐẠT TRONG NGÀY | J3: CHÊNH LỆCH | K3: CÒN THIẾU | L3: SỐ GIỜ ĐÃ NHẬP | M3: MỤC TIÊU ĐẾN GIỜ ĐÃ NHẬP | N3: TIẾN ĐỘ THEO GIỜ | O3: NGÀY LÀM TRƯỚC | P3: THIẾU HÔM TRƯỚC | Q3: MỤC TIÊU THÁNG (SẢN PHẨM) | R3: LŨY KẾ THÁNG (SẢN PHẨM, đến ngày này) | S3: TỶ LỆ ĐẠT THÁNG | T3: CÒN THIẾU THÁNG | U3: LŨY KẾ THÁNG CỦA CHUYỀN | V3: GIỜ 1 | W3: GIỜ 2 | X3: GIỜ 3 | Y3: GIỜ 4 | Z3: GIỜ 5 | AA3: GIỜ 6 | AB3: GIỜ 7 | AC3: GIỜ 8 | AD3: GIỜ 9 | AE3: GIỜ 10 | AF3: GIỜ 11 | AG3: GIỜ 12 | AH3: TRẠNG THÁI | AI3: GHI CHÚ | AJ3: DÒNG NHẬP LIỆU (máy dùng) | AK3: DÒNG NGÀY TRƯỚC (máy dùng) | AL3: THIẾU THÁNG TRƯỚC (SẢN PHẨM) | AM3: NGÀY LÀM VIỆC CÒN LẠI (tính cả ngày này) | AN3: CẦN LÀM MỖI NGÀY ĐỂ KỊP THÁNG (SẢN PHẨM) | AO3: SỐ CÔNG NHÂN | AP3: SP / NGƯỜI / GIỜ | AQ3: SỐ LỖI | AR3: TỶ LỆ LỖI | AS3: LÝ DO KHÔNG ĐẠT | AT3: PHÚT DỪNG MÁY
A4: 1 | B4: 2 | C4: 3 | D4: 4 | E4: 5 | F4: 6 | G4: 7 | H4: 8 | I4: 9 | J4: 10 | K4: 11 | L4: 12 | M4: 13 | N4: 14 | O4: 15 | P4: 16 | Q4: 17 | R4: 18 | S4: 19 | T4: 20 | U4: 21 | V4: 22 | W4: 23 | X4: 24 | Y4: 25 | Z4: 26 | AA4: 27 | AB4: 28 | AC4: 29 | AD4: 30 | AE4: 31 | AF4: 32 | AG4: 33 | AH4: 34 | AI4: 35 | AJ4: 36 | AK4: 37 | AL4: 38 | AM4: 39 | AN4: 40 | AO4: 41 | AP4: 42 | AQ4: 43 | AR4: 44 | AS4: 45 | AT4: 46
A5: =IF(B5="","",$M$1) -> 46297 | B5: =IF(DANH_SACH_CHUYEN!B5="","",DANH_SACH_CHUYEN!B5) -> Chuyền 1 | C5: =IF($AJ5="","",IF(INDEX(NHAP_LIEU!$C$5:$C$10004,$AJ5)="","",INDEX(NHAP_LIEU!$C$5:$C$10004,$AJ5))) -> ĐAI LƯNG | D5: =IF($AJ5="","",IF(INDEX(NHAP_LIEU!$D$5:$D$10004,$AJ5)="","",INDEX(NHAP_LIEU!$D$5:$D$10004,$AJ5))) -> 8H | E5: =IF(D5="","",IFERROR(INDEX(CAU_HINH_CA!$C$5:$C$50,MATCH(D5,CAU_HINH_CA!$A$5:$A$50,0)),"")) -> 8 | F5: =IF($AJ5="","",IF(INDEX(NHAP_LIEU!$E$5:$E$10004,$AJ5)="","",INDEX(NHAP_LIEU!$E$5:$E$10004,$AJ5))) -> 100 | G5: =IF(OR(E5="",F5=""),"",ROUND(E5*F5,0)) -> 800 | H5: =IF(COUNT(V5:AG5)=0,"",SUM(V5:AG5)) -> 200 | I5: =IF(OR(H5="",N(G5)=0),"",H5/G5) -> 0.25 | J5: =IF(OR(H5="",G5=""),"",H5-G5) -> -600 | K5: =IF(OR(H5="",G5=""),"",MAX(0,G5-H5)) -> 600 | L5: =IF(AJ5="","",COUNT(V5:AG5)) -> 2 | M5: =IF(OR(L5="",F5="",G5=""),"",MIN(G5,L5*F5)) -> 200 | N5: =IF(OR(H5="",N(M5)=0),"",H5/M5) -> 1 | O5: =IF(OR(B5="",A5=""),"",IF(SUMPRODUCT(MAX((NHAP_LIEU!$B$5:$B$10004=B5)*(NHAP_LIEU!$A$5:$A$10004<A5)*NHAP_LIEU!$A$5:$A$10004))=0,"",SUMPRODUCT(MAX((NHAP_LIEU!$B$5:$B$10004=B5)*(NHAP_LIEU!$A$5:$A$10004<A5)*NHAP_LIEU!$A$5:$A$10004)))) -> 46296 | P5: =IF(AK5="","",IF(COUNT(INDEX(NHAP_LIEU!$H$5:$S$10004,AK5,0))=0,0,MAX(0,IFERROR(ROUND(INDEX(CAU_HINH_CA!$C$5:$C$50,MATCH(INDEX(NHAP_LIEU!$D$5:$D$10004,AK5),CAU_HINH_CA!$A$5:$A$50,0))*INDEX(NHAP_LIEU!$E$5:$E$10004,AK5),0),0)-SUM(INDEX(NHAP_LIEU!$H$5:$S$10004,AK5,0))))) -> 0 | Q5: =IF(C5="","",SUMIFS(MUC_TIEU_THANG!$C$5:$C$2004,MUC_TIEU_THANG!$B$5:$B$2004,C5,MUC_TIEU_THANG!$A$5:$A$2004,">="&DATE(YEAR(A5),MONTH(A5),1),MUC_TIEU_THANG!$A$5:$A$2004,"<"&DATE(YEAR(A5),MONTH(A5)+1,1))) -> 42000 | R5: =IF(C5="","",SUMPRODUCT((NHAP_LIEU!$C$5:$C$10004=C5)*(NHAP_LIEU!$A$5:$A$10004>=DATE(YEAR(A5),MONTH(A5),1))*(NHAP_LIEU!$A$5:$A$10004<=A5)*NHAP_LIEU!$H$5:$S$10004)) -> 1000 | S5: =IF(OR(R5="",N(Q5)=0),"",R5/Q5) -> 0.023809524 | T5: =IF(OR(R5="",N(Q5)=0),"",MAX(0,Q5-R5)) -> 41000 | U5: =IF(B5="","",SUMPRODUCT((NHAP_LIEU!$B$5:$B$10004=B5)*(NHAP_LIEU!$A$5:$A$10004>=DATE(YEAR(A5),MONTH(A5),1))*(NHAP_LIEU!$A$5:$A$10004<=A5)*NHAP_LIEU!$H$5:$S$10004)) -> 1000 | V5: =IF($AJ5="","",IF(INDEX(NHAP_LIEU!$H$5:$H$10004,$AJ5)="","",INDEX(NHAP_LIEU!$H$5:$H$10004,$AJ5))) -> 100 | W5: =IF($AJ5="","",IF(INDEX(NHAP_LIEU!$I$5:$I$10004,$AJ5)="","",INDEX(NHAP_LIEU!$I$5:$I$10004,$AJ5))) -> 100 | X5: =IF($AJ5="","",IF(INDEX(NHAP_LIEU!$J$5:$J$10004,$AJ5)="","",INDEX(NHAP_LIEU!$J$5:$J$10004,$AJ5))) | Y5: =IF($AJ5="","",IF(INDEX(NHAP_LIEU!$K$5:$K$10004,$AJ5)="","",INDEX(NHAP_LIEU!$K$5:$K$10004,$AJ5))) | Z5: =IF($AJ5="","",IF(INDEX(NHAP_LIEU!$L$5:$L$10004,$AJ5)="","",INDEX(NHAP_LIEU!$L$5:$L$10004,$AJ5))) | AA5: =IF($AJ5="","",IF(INDEX(NHAP_LIEU!$M$5:$M$10004,$AJ5)="","",INDEX(NHAP_LIEU!$M$5:$M$10004,$AJ5))) | AB5: =IF($AJ5="","",IF(INDEX(NHAP_LIEU!$N$5:$N$10004,$AJ5)="","",INDEX(NHAP_LIEU!$N$5:$N$10004,$AJ5))) | AC5: =IF($AJ5="","",IF(INDEX(NHAP_LIEU!$O$5:$O$10004,$AJ5)="","",INDEX(NHAP_LIEU!$O$5:$O$10004,$AJ5))) | AD5: =IF($AJ5="","",IF(INDEX(NHAP_LIEU!$P$5:$P$10004,$AJ5)="","",INDEX(NHAP_LIEU!$P$5:$P$10004,$AJ5))) | AE5: =IF($AJ5="","",IF(INDEX(NHAP_LIEU!$Q$5:$Q$10004,$AJ5)="","",INDEX(NHAP_LIEU!$Q$5:$Q$10004,$AJ5))) | AF5: =IF($AJ5="","",IF(INDEX(NHAP_LIEU!$R$5:$R$10004,$AJ5)="","",INDEX(NHAP_LIEU!$R$5:$R$10004,$AJ5))) | AG5: =IF($AJ5="","",IF(INDEX(NHAP_LIEU!$S$5:$S$10004,$AJ5)="","",INDEX(NHAP_LIEU!$S$5:$S$10004,$AJ5))) | AH5: =IF($AJ5="","",IF(INDEX(NHAP_LIEU!$AC$5:$AC$10004,$AJ5)="","",INDEX(NHAP_LIEU!$AC$5:$AC$10004,$AJ5))) | AI5: =IF($AJ5="","",IF(INDEX(NHAP_LIEU!$AD$5:$AD$10004,$AJ5)="","",INDEX(NHAP_LIEU!$AD$5:$AD$10004,$AJ5))) | AJ5: =IF(OR(B5="",A5=""),"",IFERROR(MATCH(1,INDEX((NHAP_LIEU!$A$5:$A$10004=A5)*(NHAP_LIEU!$B$5:$B$10004=B5),0),0),"")) -> 11 | AK5: =IF(O5="","",IFERROR(MATCH(1,INDEX((NHAP_LIEU!$A$5:$A$10004=O5)*(NHAP_LIEU!$B$5:$B$10004=B5),0),0),"")) -> 8 | AL5: =IF(C5="","",SUMIFS(MUC_TIEU_THANG!$K$5:$K$2004,MUC_TIEU_THANG!$B$5:$B$2004,C5,MUC_TIEU_THANG!$A$5:$A$2004,">="&DATE(YEAR(A5),MONTH(A5),1),MUC_TIEU_THANG!$A$5:$A$2004,"<"&DATE(YEAR(A5),MONTH(A5)+1,1))) -> 38940 | AM5: =IF(A5="","",MAX(0,NETWORKDAYS.INTL(A5,EOMONTH(A5,0),11)-SUMPRODUCT((LICH_LAM_VIEC!$A$5:$A$1000>=A5)*(LICH_LAM_VIEC!$A$5:$A$1000<=EOMONTH(A5,0))*(LICH_LAM_VIEC!$B$5:$B$1000="Nghỉ")*(WEEKDAY(LICH_LAM_VIEC!$A$5:$A$1000)<>1))+SUMPRODUCT((LICH_LAM_VIEC!$A$5:$A$1000>=A5)*(LICH_LAM_VIEC!$A$5:$A$1000<=EOMONTH(A5,0))*(LICH_LAM_VIEC!$B$5:$B$1000="Làm bù")*(WEEKDAY(LICH_LAM_VIEC!$A$5:$A$1000)=1)))) -> 26 | AN5: =IF(OR(C5="",N(Q5)=0,N(AM5)=0),"",ROUNDUP(MAX(0,Q5-SUMPRODUCT((NHAP_LIEU!$C$5:$C$10004=C5)*(NHAP_LIEU!$A$5:$A$10004>=DATE(YEAR(A5),MONTH(A5),1))*(NHAP_LIEU!$A$5:$A$10004<A5)*NHAP_LIEU!$H$5:$S$10004))/AM5,0)) -> 1585 | AO5: =IF($AJ5="","",IF(INDEX(NHAP_LIEU!$AG$5:$AG$10004,$AJ5)="","",INDEX(NHAP_LIEU!$AG$5:$AG$10004,$AJ5))) -> 20 | AP5: =IF(OR(H5="",N(AO5)=0,N(L5)=0),"",H5/(AO5*L5)) -> 5 | AQ5: =IF($AJ5="","",IF(INDEX(NHAP_LIEU!$AH$5:$AH$10004,$AJ5)="","",INDEX(NHAP_LIEU!$AH$5:$AH$10004,$AJ5))) | AR5: =IF(OR(AQ5="",N(H5)=0),"",AQ5/H5) | AS5: =IF($AJ5="","",IF(INDEX(NHAP_LIEU!$AI$5:$AI$10004,$AJ5)="","",INDEX(NHAP_LIEU!$AI$5:$AI$10004,$AJ5))) | AT5: =IF($AJ5="","",IF(INDEX(NHAP_LIEU!$AJ$5:$AJ$10004,$AJ5)="","",INDEX(NHAP_LIEU!$AJ$5:$AJ$10004,$AJ5)))
A6: =IF(B6="","",$M$1) -> 46297 | B6: =IF(DANH_SACH_CHUYEN!B6="","",DANH_SACH_CHUYEN!B6) -> Chuyền 2 | C6: =IF($AJ6="","",IF(INDEX(NHAP_LIEU!$C$5:$C$10004,$AJ6)="","",INDEX(NHAP_LIEU!$C$5:$C$10004,$AJ6))) -> BAO TAY XANH | D6: =IF($AJ6="","",IF(INDEX(NHAP_LIEU!$D$5:$D$10004,$AJ6)="","",INDEX(NHAP_LIEU!$D$5:$D$10004,$AJ6))) -> 10H | E6: =IF(D6="","",IFERROR(INDEX(CAU_HINH_CA!$C$5:$C$50,MATCH(D6,CAU_HINH_CA!$A$5:$A$50,0)),"")) -> 10 | F6: =IF($AJ6="","",IF(INDEX(NHAP_LIEU!$E$5:$E$10004,$AJ6)="","",INDEX(NHAP_LIEU!$E$5:$E$10004,$AJ6))) -> 100 | G6: =IF(OR(E6="",F6=""),"",ROUND(E6*F6,0)) -> 1000 | H6: =IF(COUNT(V6:AG6)=0,"",SUM(V6:AG6)) -> 240 | I6: =IF(OR(H6="",N(G6)=0),"",H6/G6) -> 0.24 | J6: =IF(OR(H6="",G6=""),"",H6-G6) -> -760 | K6: =IF(OR(H6="",G6=""),"",MAX(0,G6-H6)) -> 760 | L6: =IF(AJ6="","",COUNT(V6:AG6)) -> 3 | M6: =IF(OR(L6="",F6="",G6=""),"",MIN(G6,L6*F6)) -> 300 | N6: =IF(OR(H6="",N(M6)=0),"",H6/M6) -> 0.8 | O6: =IF(OR(B6="",A6=""),"",IF(SUMPRODUCT(MAX((NHAP_LIEU!$B$5:$B$10004=B6)*(NHAP_LIEU!$A$5:$A$10004<A6)*NHAP_LIEU!$A$5:$A$10004))=0,"",SUMPRODUCT(MAX((NHAP_LIEU!$B$5:$B$10004=B6)*(NHAP_LIEU!$A$5:$A$10004<A6)*NHAP_LIEU!$A$5:$A$10004)))) -> 46296 | P6: =IF(AK6="","",IF(COUNT(INDEX(NHAP_LIEU!$H$5:$S$10004,AK6,0))=0,0,MAX(0,IFERROR(ROUND(INDEX(CAU_HINH_CA!$C$5:$C$50,MATCH(INDEX(NHAP_LIEU!$D$5:$D$10004,AK6),CAU_HINH_CA!$A$5:$A$50,0))*INDEX(NHAP_LIEU!$E$5:$E$10004,AK6),0),0)-SUM(INDEX(NHAP_LIEU!$H$5:$S$10004,AK6,0))))) -> 100 | Q6: =IF(C6="","",SUMIFS(MUC_TIEU_THANG!$C$5:$C$2004,MUC_TIEU_THANG!$B$5:$B$2004,C6,MUC_TIEU_THANG!$A$5:$A$2004,">="&DATE(YEAR(A6),MONTH(A6),1),MUC_TIEU_THANG!$A$5:$A$2004,"<"&DATE(YEAR(A6),MONTH(A6)+1,1))) -> 40000 | R6: =IF(C6="","",SUMPRODUCT((NHAP_LIEU!$C$5:$C$10004=C6)*(NHAP_LIEU!$A$5:$A$10004>=DATE(YEAR(A6),MONTH(A6),1))*(NHAP_LIEU!$A$5:$A$10004<=A6)*NHAP_LIEU!$H$5:$S$10004)) -> 1140 | S6: =IF(OR(R6="",N(Q6)=0),"",R6/Q6) -> 0.0285 | T6: =IF(OR(R6="",N(Q6)=0),"",MAX(0,Q6-R6)) -> 38860 | U6: =IF(B6="","",SUMPRODUCT((NHAP_LIEU!$B$5:$B$10004=B6)*(NHAP_LIEU!$A$5:$A$10004>=DATE(YEAR(A6),MONTH(A6),1))*(NHAP_LIEU!$A$5:$A$10004<=A6)*NHAP_LIEU!$H$5:$S$10004)) -> 1140 | V6: =IF($AJ6="","",IF(INDEX(NHAP_LIEU!$H$5:$H$10004,$AJ6)="","",INDEX(NHAP_LIEU!$H$5:$H$10004,$AJ6))) -> 80 | W6: =IF($AJ6="","",IF(INDEX(NHAP_LIEU!$I$5:$I$10004,$AJ6)="","",INDEX(NHAP_LIEU!$I$5:$I$10004,$AJ6))) -> 80 | X6: =IF($AJ6="","",IF(INDEX(NHAP_LIEU!$J$5:$J$10004,$AJ6)="","",INDEX(NHAP_LIEU!$J$5:$J$10004,$AJ6))) -> 80 | Y6: =IF($AJ6="","",IF(INDEX(NHAP_LIEU!$K$5:$K$10004,$AJ6)="","",INDEX(NHAP_LIEU!$K$5:$K$10004,$AJ6))) | Z6: =IF($AJ6="","",IF(INDEX(NHAP_LIEU!$L$5:$L$10004,$AJ6)="","",INDEX(NHAP_LIEU!$L$5:$L$10004,$AJ6))) | AA6: =IF($AJ6="","",IF(INDEX(NHAP_LIEU!$M$5:$M$10004,$AJ6)="","",INDEX(NHAP_LIEU!$M$5:$M$10004,$AJ6))) | AB6: =IF($AJ6="","",IF(INDEX(NHAP_LIEU!$N$5:$N$10004,$AJ6)="","",INDEX(NHAP_LIEU!$N$5:$N$10004,$AJ6))) | AC6: =IF($AJ6="","",IF(INDEX(NHAP_LIEU!$O$5:$O$10004,$AJ6)="","",INDEX(NHAP_LIEU!$O$5:$O$10004,$AJ6))) | AD6: =IF($AJ6="","",IF(INDEX(NHAP_LIEU!$P$5:$P$10004,$AJ6)="","",INDEX(NHAP_LIEU!$P$5:$P$10004,$AJ6))) | AE6: =IF($AJ6="","",IF(INDEX(NHAP_LIEU!$Q$5:$Q$10004,$AJ6)="","",INDEX(NHAP_LIEU!$Q$5:$Q$10004,$AJ6))) | AF6: =IF($AJ6="","",IF(INDEX(NHAP_LIEU!$R$5:$R$10004,$AJ6)="","",INDEX(NHAP_LIEU!$R$5:$R$10004,$AJ6))) | AG6: =IF($AJ6="","",IF(INDEX(NHAP_LIEU!$S$5:$S$10004,$AJ6)="","",INDEX(NHAP_LIEU!$S$5:$S$10004,$AJ6))) | AH6: =IF($AJ6="","",IF(INDEX(NHAP_LIEU!$AC$5:$AC$10004,$AJ6)="","",INDEX(NHAP_LIEU!$AC$5:$AC$10004,$AJ6))) | AI6: =IF($AJ6="","",IF(INDEX(NHAP_LIEU!$AD$5:$AD$10004,$AJ6)="","",INDEX(NHAP_LIEU!$AD$5:$AD$10004,$AJ6))) | AJ6: =IF(OR(B6="",A6=""),"",IFERROR(MATCH(1,INDEX((NHAP_LIEU!$A$5:$A$10004=A6)*(NHAP_LIEU!$B$5:$B$10004=B6),0),0),"")) -> 12 | AK6: =IF(O6="","",IFERROR(MATCH(1,INDEX((NHAP_LIEU!$A$5:$A$10004=O6)*(NHAP_LIEU!$B$5:$B$10004=B6),0),0),"")) -> 9 | AL6: =IF(C6="","",SUMIFS(MUC_TIEU_THANG!$K$5:$K$2004,MUC_TIEU_THANG!$B$5:$B$2004,C6,MUC_TIEU_THANG!$A$5:$A$2004,">="&DATE(YEAR(A6),MONTH(A6),1),MUC_TIEU_THANG!$A$5:$A$2004,"<"&DATE(YEAR(A6),MONTH(A6)+1,1))) -> 38800 | AM6: =IF(A6="","",MAX(0,NETWORKDAYS.INTL(A6,EOMONTH(A6,0),11)-SUMPRODUCT((LICH_LAM_VIEC!$A$5:$A$1000>=A6)*(LICH_LAM_VIEC!$A$5:$A$1000<=EOMONTH(A6,0))*(LICH_LAM_VIEC!$B$5:$B$1000="Nghỉ")*(WEEKDAY(LICH_LAM_VIEC!$A$5:$A$1000)<>1))+SUMPRODUCT((LICH_LAM_VIEC!$A$5:$A$1000>=A6)*(LICH_LAM_VIEC!$A$5:$A$1000<=EOMONTH(A6,0))*(LICH_LAM_VIEC!$B$5:$B$1000="Làm bù")*(WEEKDAY(LICH_LAM_VIEC!$A$5:$A$1000)=1)))) -> 26 | AN6: =IF(OR(C6="",N(Q6)=0,N(AM6)=0),"",ROUNDUP(MAX(0,Q6-SUMPRODUCT((NHAP_LIEU!$C$5:$C$10004=C6)*(NHAP_LIEU!$A$5:$A$10004>=DATE(YEAR(A6),MONTH(A6),1))*(NHAP_LIEU!$A$5:$A$10004<A6)*NHAP_LIEU!$H$5:$S$10004))/AM6,0)) -> 1504 | AO6: =IF($AJ6="","",IF(INDEX(NHAP_LIEU!$AG$5:$AG$10004,$AJ6)="","",INDEX(NHAP_LIEU!$AG$5:$AG$10004,$AJ6))) -> 25 | AP6: =IF(OR(H6="",N(AO6)=0,N(L6)=0),"",H6/(AO6*L6)) -> 3.2 | AQ6: =IF($AJ6="","",IF(INDEX(NHAP_LIEU!$AH$5:$AH$10004,$AJ6)="","",INDEX(NHAP_LIEU!$AH$5:$AH$10004,$AJ6))) -> 1 | AR6: =IF(OR(AQ6="",N(H6)=0),"",AQ6/H6) -> 0.0041666667 | AS6: =IF($AJ6="","",IF(INDEX(NHAP_LIEU!$AI$5:$AI$10004,$AJ6)="","",INDEX(NHAP_LIEU!$AI$5:$AI$10004,$AJ6))) | AT6: =IF($AJ6="","",IF(INDEX(NHAP_LIEU!$AJ$5:$AJ$10004,$AJ6)="","",INDEX(NHAP_LIEU!$AJ$5:$AJ$10004,$AJ6)))
A7: =IF(B7="","",$M$1) -> 46297 | B7: =IF(DANH_SACH_CHUYEN!B7="","",DANH_SACH_CHUYEN!B7) -> Chuyền 3 | C7: =IF($AJ7="","",IF(INDEX(NHAP_LIEU!$C$5:$C$10004,$AJ7)="","",INDEX(NHAP_LIEU!$C$5:$C$10004,$AJ7))) | D7: =IF($AJ7="","",IF(INDEX(NHAP_LIEU!$D$5:$D$10004,$AJ7)="","",INDEX(NHAP_LIEU!$D$5:$D$10004,$AJ7))) | E7: =IF(D7="","",IFERROR(INDEX(CAU_HINH_CA!$C$5:$C$50,MATCH(D7,CAU_HINH_CA!$A$5:$A$50,0)),"")) | F7: =IF($AJ7="","",IF(INDEX(NHAP_LIEU!$E$5:$E$10004,$AJ7)="","",INDEX(NHAP_LIEU!$E$5:$E$10004,$AJ7))) | G7: =IF(OR(E7="",F7=""),"",ROUND(E7*F7,0)) | H7: =IF(COUNT(V7:AG7)=0,"",SUM(V7:AG7)) | I7: =IF(OR(H7="",N(G7)=0),"",H7/G7) | J7: =IF(OR(H7="",G7=""),"",H7-G7) | K7: =IF(OR(H7="",G7=""),"",MAX(0,G7-H7)) | L7: =IF(AJ7="","",COUNT(V7:AG7)) | M7: =IF(OR(L7="",F7="",G7=""),"",MIN(G7,L7*F7)) | N7: =IF(OR(H7="",N(M7)=0),"",H7/M7) | O7: =IF(OR(B7="",A7=""),"",IF(SUMPRODUCT(MAX((NHAP_LIEU!$B$5:$B$10004=B7)*(NHAP_LIEU!$A$5:$A$10004<A7)*NHAP_LIEU!$A$5:$A$10004))=0,"",SUMPRODUCT(MAX((NHAP_LIEU!$B$5:$B$10004=B7)*(NHAP_LIEU!$A$5:$A$10004<A7)*NHAP_LIEU!$A$5:$A$10004)))) -> 46296 | P7: =IF(AK7="","",IF(COUNT(INDEX(NHAP_LIEU!$H$5:$S$10004,AK7,0))=0,0,MAX(0,IFERROR(ROUND(INDEX(CAU_HINH_CA!$C$5:$C$50,MATCH(INDEX(NHAP_LIEU!$D$5:$D$10004,AK7),CAU_HINH_CA!$A$5:$A$50,0))*INDEX(NHAP_LIEU!$E$5:$E$10004,AK7),0),0)-SUM(INDEX(NHAP_LIEU!$H$5:$S$10004,AK7,0))))) -> 93 | Q7: =IF(C7="","",SUMIFS(MUC_TIEU_THANG!$C$5:$C$2004,MUC_TIEU_THANG!$B$5:$B$2004,C7,MUC_TIEU_THANG!$A$5:$A$2004,">="&DATE(YEAR(A7),MONTH(A7),1),MUC_TIEU_THANG!$A$5:$A$2004,"<"&DATE(YEAR(A7),MONTH(A7)+1,1))) | R7: =IF(C7="","",SUMPRODUCT((NHAP_LIEU!$C$5:$C$10004=C7)*(NHAP_LIEU!$A$5:$A$10004>=DATE(YEAR(A7),MONTH(A7),1))*(NHAP_LIEU!$A$5:$A$10004<=A7)*NHAP_LIEU!$H$5:$S$10004)) | S7: =IF(OR(R7="",N(Q7)=0),"",R7/Q7) | T7: =IF(OR(R7="",N(Q7)=0),"",MAX(0,Q7-R7)) | U7: =IF(B7="","",SUMPRODUCT((NHAP_LIEU!$B$5:$B$10004=B7)*(NHAP_LIEU!$A$5:$A$10004>=DATE(YEAR(A7),MONTH(A7),1))*(NHAP_LIEU!$A$5:$A$10004<=A7)*NHAP_LIEU!$H$5:$S$10004)) -> 2035 | V7: =IF($AJ7="","",IF(INDEX(NHAP_LIEU!$H$5:$H$10004,$AJ7)="","",INDEX(NHAP_LIEU!$H$5:$H$10004,$AJ7))) | W7: =IF($AJ7="","",IF(INDEX(NHAP_LIEU!$I$5:$I$10004,$AJ7)="","",INDEX(NHAP_LIEU!$I$5:$I$10004,$AJ7))) | X7: =IF($AJ7="","",IF(INDEX(NHAP_LIEU!$J$5:$J$10004,$AJ7)="","",INDEX(NHAP_LIEU!$J$5:$J$10004,$AJ7))) | Y7: =IF($AJ7="","",IF(INDEX(NHAP_LIEU!$K$5:$K$10004,$AJ7)="","",INDEX(NHAP_LIEU!$K$5:$K$10004,$AJ7))) | Z7: =IF($AJ7="","",IF(INDEX(NHAP_LIEU!$L$5:$L$10004,$AJ7)="","",INDEX(NHAP_LIEU!$L$5:$L$10004,$AJ7))) | AA7: =IF($AJ7="","",IF(INDEX(NHAP_LIEU!$M$5:$M$10004,$AJ7)="","",INDEX(NHAP_LIEU!$M$5:$M$10004,$AJ7))) | AB7: =IF($AJ7="","",IF(INDEX(NHAP_LIEU!$N$5:$N$10004,$AJ7)="","",INDEX(NHAP_LIEU!$N$5:$N$10004,$AJ7))) | AC7: =IF($AJ7="","",IF(INDEX(NHAP_LIEU!$O$5:$O$10004,$AJ7)="","",INDEX(NHAP_LIEU!$O$5:$O$10004,$AJ7))) | AD7: =IF($AJ7="","",IF(INDEX(NHAP_LIEU!$P$5:$P$10004,$AJ7)="","",INDEX(NHAP_LIEU!$P$5:$P$10004,$AJ7))) | AE7: =IF($AJ7="","",IF(INDEX(NHAP_LIEU!$Q$5:$Q$10004,$AJ7)="","",INDEX(NHAP_LIEU!$Q$5:$Q$10004,$AJ7))) | AF7: =IF($AJ7="","",IF(INDEX(NHAP_LIEU!$R$5:$R$10004,$AJ7)="","",INDEX(NHAP_LIEU!$R$5:$R$10004,$AJ7))) | AG7: =IF($AJ7="","",IF(INDEX(NHAP_LIEU!$S$5:$S$10004,$AJ7)="","",INDEX(NHAP_LIEU!$S$5:$S$10004,$AJ7))) | AH7: =IF($AJ7="","",IF(INDEX(NHAP_LIEU!$AC$5:$AC$10004,$AJ7)="","",INDEX(NHAP_LIEU!$AC$5:$AC$10004,$AJ7))) | AI7: =IF($AJ7="","",IF(INDEX(NHAP_LIEU!$AD$5:$AD$10004,$AJ7)="","",INDEX(NHAP_LIEU!$AD$5:$AD$10004,$AJ7))) | AJ7: =IF(OR(B7="",A7=""),"",IFERROR(MATCH(1,INDEX((NHAP_LIEU!$A$5:$A$10004=A7)*(NHAP_LIEU!$B$5:$B$10004=B7),0),0),"")) | AK7: =IF(O7="","",IFERROR(MATCH(1,INDEX((NHAP_LIEU!$A$5:$A$10004=O7)*(NHAP_LIEU!$B$5:$B$10004=B7),0),0),"")) -> 10 | AL7: =IF(C7="","",SUMIFS(MUC_TIEU_THANG!$K$5:$K$2004,MUC_TIEU_THANG!$B$5:$B$2004,C7,MUC_TIEU_THANG!$A$5:$A$2004,">="&DATE(YEAR(A7),MONTH(A7),1),MUC_TIEU_THANG!$A$5:$A$2004,"<"&DATE(YEAR(A7),MONTH(A7)+1,1))) | AM7: =IF(A7="","",MAX(0,NETWORKDAYS.INTL(A7,EOMONTH(A7,0),11)-SUMPRODUCT((LICH_LAM_VIEC!$A$5:$A$1000>=A7)*(LICH_LAM_VIEC!$A$5:$A$1000<=EOMONTH(A7,0))*(LICH_LAM_VIEC!$B$5:$B$1000="Nghỉ")*(WEEKDAY(LICH_LAM_VIEC!$A$5:$A$1000)<>1))+SUMPRODUCT((LICH_LAM_VIEC!$A$5:$A$1000>=A7)*(LICH_LAM_VIEC!$A$5:$A$1000<=EOMONTH(A7,0))*(LICH_LAM_VIEC!$B$5:$B$1000="Làm bù")*(WEEKDAY(LICH_LAM_VIEC!$A$5:$A$1000)=1)))) -> 26 | AN7: =IF(OR(C7="",N(Q7)=0,N(AM7)=0),"",ROUNDUP(MAX(0,Q7-SUMPRODUCT((NHAP_LIEU!$C$5:$C$10004=C7)*(NHAP_LIEU!$A$5:$A$10004>=DATE(YEAR(A7),MONTH(A7),1))*(NHAP_LIEU!$A$5:$A$10004<A7)*NHAP_LIEU!$H$5:$S$10004))/AM7,0)) | AO7: =IF($AJ7="","",IF(INDEX(NHAP_LIEU!$AG$5:$AG$10004,$AJ7)="","",INDEX(NHAP_LIEU!$AG$5:$AG$10004,$AJ7))) | AP7: =IF(OR(H7="",N(AO7)=0,N(L7)=0),"",H7/(AO7*L7)) | AQ7: =IF($AJ7="","",IF(INDEX(NHAP_LIEU!$AH$5:$AH$10004,$AJ7)="","",INDEX(NHAP_LIEU!$AH$5:$AH$10004,$AJ7))) | AR7: =IF(OR(AQ7="",N(H7)=0),"",AQ7/H7) | AS7: =IF($AJ7="","",IF(INDEX(NHAP_LIEU!$AI$5:$AI$10004,$AJ7)="","",INDEX(NHAP_LIEU!$AI$5:$AI$10004,$AJ7))) | AT7: =IF($AJ7="","",IF(INDEX(NHAP_LIEU!$AJ$5:$AJ$10004,$AJ7)="","",INDEX(NHAP_LIEU!$AJ$5:$AJ$10004,$AJ7)))
