Workbook
Name DS_MA_CA: OFFSET(CAU_HINH_CA!$A$5,0,0,MAX(1,COUNTA(CAU_HINH_CA!$A$5:$A$50)),1)
Name DS_CHUYEN: OFFSET(DANH_SACH_CHUYEN!$B$5,0,0,MAX(1,COUNTA(DANH_SACH_CHUYEN!$B$5:$B$1000)),1)
Name DS_MA_SAN_PHAM: OFFSET(DANH_SACH_SAN_PHAM!$A$5,0,0,MAX(1,COUNTA(DANH_SACH_SAN_PHAM!$A$5:$A$1000)),1)
Name DS_LY_DO: OFFSET(DANH_SACH_LY_DO!$A$5,0,0,MAX(1,COUNTA(DANH_SACH_LY_DO!$A$5:$A$1000)),1)
Name DS_LOAI_LOI: OFFSET(DANH_SACH_LOAI_LOI!$A$5,0,0,MAX(1,COUNTA(DANH_SACH_LOAI_LOI!$A$5:$A$1000)),1)

Sheet HUONG_DAN
B1: HƯỚNG DẪN SỬ DỤNG – THEO DÕI SẢN LƯỢNG V20
B2: Mỗi sheet dữ liệu là một Excel Table (lọc/sắp xếp ở dòng 4). Cột có tiêu đề VÀNG (dòng 3) là cột nhập tay;
B3: cột có tiêu đề XANH NHẠT là công thức, KHÔNG gõ đè. Thêm dữ liệu: gõ vào dòng ngay dưới bảng, bảng tự nới ra và tự điền công thức.
B4: Dữ liệu bắt đầu từ dòng 5 ở mọi sheet. Dòng 2–3 là tiêu đề Trung/Việt, dòng 4 là số thứ tự cột.
B6: 1. Danh mục (ít khi đổi)
B7: CAU_HINH_CA: mã ca và các đợt làm việc. TỔNG GIỜ tự tính từ giờ bắt đầu/kết thúc.
B8: DANH_SACH_CHUYEN: thứ tự ở đây là thứ tự hiển thị trên TV. Thêm chuyền thì thêm 1 dòng ở cả sheet này và bảng HIEN_THI.
B9: DANH_SACH_SAN_PHAM: mọi mã sản phẩm. Mã được lưu dạng chữ (883 và "883" là một).
B11: 2. Đầu tháng
B12: MUC_TIEU_THANG: mỗi sản phẩm một dòng cho mỗi tháng. Cột THÁNG gõ dạng 10/2026. Các cột lũy kế tự tính.
B14: 3. Hằng ngày – sheet NHAP_LIEU
B15: Mỗi chuyền một dòng mỗi ngày: NGÀY, CHUYỀN, MÃ SẢN PHẨM, MÃ CA, MỤC TIÊU MỖI GIỜ.
... B45: Tiêu đề cột công thức

Sheet CAU_HINH_CA
A1: 工作時間設定 / CẤU HÌNH CA
A2: 班次代碼 | B2: 班次名稱 | C2: 總工時 | D2: 第一時段開始 | E2: 第一時段結束 | F2: 第二時段開始 | G2: 第二時段結束 | H2: 第三時段開始 | I2: 第三時段結束 | J2: 啟用狀態
A3: MÃ CA | B3: TÊN CA | C3: TỔNG GIỜ (tự tính) | D3: ĐỢT 1 BẮT ĐẦU | E3: ĐỢT 1 KẾT THÚC | F3: ĐỢT 2 BẮT ĐẦU | G3: ĐỢT 2 KẾT THÚC | H3: ĐỢT 3 BẮT ĐẦU | I3: ĐỢT 3 KẾT THÚC | J3: TRẠNG THÁI
A4: 1 | B4: 2 | C4: 3 | D4: 4 | E4: 5 | F4: 6 | G4: 7 | H4: 8 | I4: 9 | J4: 10
A5: 8H | B5: 8 giờ | C5: =IF(A5="","",ROUND(((E5-D5)+(G5-F5)+(I5-H5))*24,2)) | D5: 0.3125 | E5: 0.47916667 | F5: 0.52083333 | G5: 0.6875 | J5: Đang sử dụng
A6: 9H | B6: 9 giờ | C6: =IF(A6="","",ROUND(((E6-D6)+(G6-F6)+(I6-H6))*24,2)) | D6: 0.3125 | E6: 0.47916667 | F6: 0.52083333 | G6: 0.72916667 | J6: Đang sử dụng
A7: 10H | B7: 10 giờ | C7: =IF(A7="","",ROUND(((E7-D7)+(G7-F7)+(I7-H7))*24,2)) | D7: 0.3125 | E7: 0.47916667 | F7: 0.52083333 | G7: 0.77083333 | J7: Đang sử dụng
A8: 11H30 | B8: 11 giờ 30 phút | C8: =IF(A8="","",ROUND(((E8-D8)+(G8-F8)+(I8-H8))*24,2)) | D8: 0.3125 | E8: 0.47916667 | F8: 0.52083333 | G8: 0.6875 | H8: 0.70833333 | I8: 0.85416667 | J8: Đang sử dụng

Sheet DANH_SACH_CHUYEN
A1: 產線清單 / DANH SÁCH CHUYỀN
A2: 產線代碼 | B2: 產線名稱 | C2: 線長姓名 | D2: 啟用狀態
A3: MÃ CHUYỀN | B3: TÊN CHUYỀN | C3: TÊN TRƯỞNG CHUYỀN | D3: TRẠNG THÁI
A4: 1 | B4: 2 | C4: 3 | D4: 4
A5: CH01 | B5: Chuyền 1 | D5: Đang sử dụng
A6: CH02 | B6: Chuyền 2 | D6: Đang sử dụng
A7: CH03 | B7: Chuyền 3 | D7: Đang sử dụng
A8: CH04 | B8: Chuyền 4 | D8: Đang sử dụng
A9: CH05 | B9: Chuyền 5 | D9: Đang sử dụng
A10: CH06 | B10: Chuyền 6 | D10: Đang sử dụng

Sheet DANH_SACH_SAN_PHAM
A1: 產品清單 / DANH SÁCH SẢN PHẨM
A2: 产品代码 | B2: 产品名称 | C2: 備註 | D2: 啟用狀態
A3: MÃ SẢN PHẨM | B3: TÊN SẢN PHẨM | C3: GHI CHÚ | D3: TRẠNG THÁI
A4: 1 | B4: 2 | C4: 3 | D4: 4
A5: ĐAI LƯNG | D5: Đang sử dụng
A6: BAO TAY XANH | D6: Đang sử dụng
A7: 883 | D7: Đang sử dụng
A8: 567 | C8: Test | D8: Đang sử dụng
A9: MÃ 9H | C9: Mã thử từ V17 | D9: Đang sử dụng

Sheet DANH_SACH_LY_DO
A1: 未達原因清單 / DANH SÁCH LÝ DO KHÔNG ĐẠT
A2: 原因 | B2: 備註
A3: LÝ DO KHÔNG ĐẠT | B3: GHI CHÚ
A4: 1 | B4: 2
A5: Thiếu vật tư
A6: Hư máy
A7: Thiếu người
A8: Chờ hàng / chờ khuôn
A9: Sửa hàng lỗi
A10: Khác

Sheet DANH_SACH_LOAI_LOI
A1: 不良類型清單 / DANH SÁCH LOẠI LỖI
A2: 不良類型 | B2: 備註
A3: LOẠI LỖI | B3: GHI CHÚ
A4: 1 | B4: 2
A5: Rách đường may
A6: Bung chỉ
A7: Lem màu
A8: Sai kích thước
A9: Khóa / phụ kiện lệch
A10: Khác

Sheet LICH_LAM_VIEC
A1: 工作日曆 / LỊCH LÀM VIỆC (Chủ nhật mặc định nghỉ)
A2: 日期 | B2: 類型 | C2: 星期 | D2: 備註
A3: NGÀY | B3: LOẠI | C3: THỨ | D3: GHI CHÚ
A4: 1 | B4: 2 | C4: 3 | D4: 4
A5: 46388 | B5: Nghỉ | C5: =IF(A5="","",CHOOSE(WEEKDAY(A5),"CN","T2","T3","T4","T5","T6","T7")) | D5: Tết Dương lịch (ví dụ)

Sheet NHAP_LIEU
A1: 生產計劃與每小時產量 / NHẬP LIỆU HẰNG NGÀY (KẾ HOẠCH + SẢN LƯỢNG THEO GIỜ)
A2: 日期 | B2: 產線 | C2: 产品代码 | D2: 工作時間 | E2: 每小时目标产量PCS | F2: 總工時 | G2: 每日目标产量PCS | H2: 第1小時 | I2: 第2小時 | J2: 第3小時 | K2: 第4小時 | L2: 第5小時 | M2: 第6小時 | N2: 第7小時 | O2: 第8小時 | P2: 第9小時 | Q2: 第10小時 | R2: 第11小時 | S2: 第12小時 | T2: 每日实际产量PCS | U2: 当日达成率% | V2: 差異PCS | W2: 剩餘PCS | X2: 已輸入小時數 | Y2: 累計目標PCS | Z2: 進度達成率% | AA2: 前一工作日 | AB2: 前一日欠數PCS | AC2: 狀態 | AD2: 備註 | AE2: 檢查 | AF2: 索引 | AG2: 工人數 | AH2: 不良數PCS | AI2: 未達原因 | AJ2: 停機分鐘 | AK2: 人均每小時產量 | AL2: 不良率%
A3: NGÀY | B3: CHUYỀN | C3: MÃ SẢN PHẨM | D3: MÃ CA | E3: MỤC TIÊU MỖI GIỜ | F3: GIỜ CA | G3: MỤC TIÊU TRONG NGÀY | H3: GIỜ 1 | I3: GIỜ 2 | J3: GIỜ 3 | K3: GIỜ 4 | L3: GIỜ 5 | M3: GIỜ 6 | N3: GIỜ 7 | O3: GIỜ 8 | P3: GIỜ 9 | Q3: GIỜ 10 | R3: GIỜ 11 | S3: GIỜ 12 | T3: THỰC TẾ TRONG NGÀY | U3: TỶ LỆ ĐẠT TRONG NGÀY | V3: CHÊNH LỆCH | W3: CÒN THIẾU | X3: SỐ GIỜ ĐÃ NHẬP | Y3: MỤC TIÊU ĐẾN GIỜ ĐÃ NHẬP | Z3: TIẾN ĐỘ THEO GIỜ | AA3: NGÀY LÀM TRƯỚC | AB3: THIẾU HÔM TRƯỚC | AC3: TRẠNG THÁI | AD3: GHI CHÚ | AE3: KIỂM TRA | AF3: KHÓA (máy dùng) | AG3: SỐ CÔNG NHÂN | AH3: SỐ LỖI (tự cộng từ HANG_LOI) | AI3: LÝ DO KHÔNG ĐẠT | AJ3: PHÚT DỪNG MÁY | AK3: SP / NGƯỜI / GIỜ | AL3: TỶ LỆ LỖI
A4: 1 | B4: 2 | C4: 3 | D4: 4 | E4: 5 | F4: 6 | G4: 7 | H4: 8 | I4: 9 | J4: 10 | K4: 11 | L4: 12 | M4: 13 | N4: 14 | O4: 15 | P4: 16 | Q4: 17 | R4: 18 | S4: 19 | T4: 20 | U4: 21 | V4: 22 | W4: 23 | X4: 24 | Y4: 25 | Z4: 26 | AA4: 27 | AB4: 28 | AC4: 29 | AD4: 30 | AE4: 31 | AF4: 32 | AG4: 33 | AH4: 34 | AI4: 35 | AJ4: 36 | AK4: 37 | AL4: 38
A5: 46295 | B5: Chuyền 1 | C5: ĐAI LƯNG | D5: 8H | E5: 100 | F5: =IF(D5="","",IFERROR(INDEX(CAU_HINH_CA!$C$5:$C$50,MATCH(D5,CAU_HINH_CA!$A$5:$A$50,0)),"")) | G5: =IF(OR(F5="",E5=""),"",ROUND(F5*E5,0)) | T5: =IF(COUNT(H5:S5)=0,"",SUM(H5:S5)) | U5: =IF(OR(T5="",N(G5)=0),"",T5/G5) | V5: =IF(OR(T5="",G5=""),"",T5-G5) | W5: =IF(OR(T5="",G5=""),"",MAX(0,G5-T5)) | X5: =IF(A5="","",COUNT(H5:S5)) | Y5: =IF(OR(X5="",E5="",G5=""),"",MIN(G5,X5*E5)) | Z5: =IF(OR(T5="",N(Y5)=0),"",T5/Y5) | AA5: =IF(OR(A5="",B5=""),"",IF(SUMPRODUCT(MAX(($B$5:$B$10004=B5)*($A$5:$A$10004<A5)*$A$5:$A$10004))=0,"",SUMPRODUCT(MAX(($B$5:$B$10004=B5)*($A$5:$A$10004<A5)*$A$5:$A$10004)))) | AB5: =IF(N(AA5)=0,"",SUMIFS($W$5:$W$10004,$B$5:$B$10004,B5,$A$5:$A$10004,AA5)) | AC5: Đang chạy | AE5: =IF(OR(A5="",B5=""),"",IF(COUNTIFS($A$5:$A$10004,A5,$B$5:$B$10004,B5)>1,"TRÙNG NGÀY + CHUYỀN",IF(G5="","THIẾU MÃ CA / MỤC TIÊU GIỜ",IF(SUMPRODUCT((COLUMN(H5:S5)-COLUMN(H5)+1>ROUNDUP(F5,0))*(H5:S5<>""))>0,"NHẬP QUÁ GIỜ CA",IF(AND(N(X5)>=ROUNDUP(N(F5),0),N(F5)>0,N(T5)<N(G5),AI5=""),"CHƯA GHI LÝ DO KHÔNG ĐẠT",IF(COUNTIFS(MUC_TIEU_THANG!$B$5:$B$2004,C5,MUC_TIEU_THANG!$A$5:$A$2004,">="&DATE(YEAR(A5),MONTH(A5),1),MUC_TIEU_THANG!$A$5:$A$2004,"<"&DATE(YEAR(A5),MONTH(A5)+1,1))=0,"CHƯA CÓ MỤC TIÊU THÁNG","OK")))))) | AF5: =IF(OR(A5="",B5=""),"",B5&"|"&A5) | AH5: =IF(OR(A5="",B5="",COUNTIFS(HANG_LOI!$A$5:$A$10004,A5,HANG_LOI!$C$5:$C$10004,B5)=0),"",SUMIFS(HANG_LOI!$F$5:$F$10004,HANG_LOI!$A$5:$A$10004,A5,HANG_LOI!$C$5:$C$10004,B5)) | AK5: =IF(OR(T5="",N(AG5)=0,N(X5)=0),"",T5/(AG5*X5)) | AL5: =IF(OR(AH5="",N(T5)=0),"",AH5/T5)
A6: 46295 | B6: Chuyền 2 | C6: BAO TAY XANH | D6: 10H | E6: 100 | F6: =IF(D6="","",IFERROR(INDEX(CAU_HINH_CA!$C$5:$C$50,MATCH(D6,CAU_HINH_CA!$A$5:$A$50,0)),"")) | G6: =IF(OR(F6="",E6=""),"",ROUND(F6*E6,0)) | T6: =IF(COUNT(H6:S6)=0,"",SUM(H6:S6)) | U6: =IF(OR(T6="",N(G6)=0),"",T6/G6) | V6: =IF(OR(T6="",G6=""),"",T6-G6) | W6: =IF(OR(T6="",G6=""),"",MAX(0,G6-T6)) | X6: =IF(A6="","",COUNT(H6:S6)) | Y6: =IF(OR(X6="",E6="",G6=""),"",MIN(G6,X6*E6)) | Z6: =IF(OR(T6="",N(Y6)=0),"",T6/Y6) | AA6: =IF(OR(A6="",B6=""),"",IF(SUMPRODUCT(MAX(($B$5:$B$10004=B6)*($A$5:$A$10004<A6)*$A$5:$A$10004))=0,"",SUMPRODUCT(MAX(($B$5:$B$10004=B6)*($A$5:$A$10004<A6)*$A$5:$A$10004)))) | AB6: =IF(N(AA6)=0,"",SUMIFS($W$5:$W$10004,$B$5:$B$10004,B6,$A$5:$A$10004,AA6)) | AC6: Đang chạy | AE6: =IF(OR(A6="",B6=""),"",IF(COUNTIFS($A$5:$A$10004,A6,$B$5:$B$10004,B6)>1,"TRÙNG NGÀY + CHUYỀN",IF(G6="","THIẾU MÃ CA / MỤC TIÊU GIỜ",IF(SUMPRODUCT((COLUMN(H6:S6)-COLUMN(H6)+1>ROUNDUP(F6,0))*(H6:S6<>""))>0,"NHẬP QUÁ GIỜ CA",IF(AND(N(X6)>=ROUNDUP(N(F6),0),N(F6)>0,N(T6)<N(G6),AI6=""),"CHƯA GHI LÝ DO KHÔNG ĐẠT",IF(COUNTIFS(MUC_TIEU_THANG!$B$5:$B$2004,C6,MUC_TIEU_THANG!$A$5:$A$2004,">="&DATE(YEAR(A6),MONTH(A6),1),MUC_TIEU_THANG!$A$5:$A$2004,"<"&DATE(YEAR(A6),MONTH(A6)+1,1))=0,"CHƯA CÓ MỤC TIÊU THÁNG","OK")))))) | AF6: =IF(OR(A6="",B6=""),"",B6&"|"&A6) | AH6: =IF(OR(A6="",B6="",COUNTIFS(HANG_LOI!$A$5:$A$10004,A6,HANG_LOI!$C$5:$C$10004,B6)=0),"",SUMIFS(HANG_LOI!$F$5:$F$10004,HANG_LOI!$A$5:$A$10004,A6,HANG_LOI!$C$5:$C$10004,B6)) | AK6: =IF(OR(T6="",N(AG6)=0,N(X6)=0),"",T6/(AG6*X6)) | AL6: =IF(OR(AH6="",N(T6)=0),"",AH6/T6)
A7: 46295 | B7: Chuyền 3 | C7: 883 | D7: 11H30 | E7: 185 | F7: =IF(D7="","",IFERROR(INDEX(CAU_HINH_CA!$C$5:$C$50,MATCH(D7,CAU_HINH_CA!$A$5:$A$50,0)),"")) | G7: =IF(OR(F7="",E7=""),"",ROUND(F7*E7,0)) | T7: =IF(COUNT(H7:S7)=0,"",SUM(H7:S7)) | U7: =IF(OR(T7="",N(G7)=0),"",T7/G7) | V7: =IF(OR(T7="",G7=""),"",T7-G7) | W7: =IF(OR(T7="",G7=""),"",MAX(0,G7-T7)) | X7: =IF(A7="","",COUNT(H7:S7)) | Y7: =IF(OR(X7="",E7="",G7=""),"",MIN(G7,X7*E7)) | Z7: =IF(OR(T7="",N(Y7)=0),"",T7/Y7) | AA7: =IF(OR(A7="",B7=""),"",IF(SUMPRODUCT(MAX(($B$5:$B$10004=B7)*($A$5:$A$10004<A7)*$A$5:$A$10004))=0,"",SUMPRODUCT(MAX(($B$5:$B$10004=B7)*($A$5:$A$10004<A7)*$A$5:$A$10004)))) | AB7: =IF(N(AA7)=0,"",SUMIFS($W$5:$W$10004,$B$5:$B$10004,B7,$A$5:$A$10004,AA7)) | AC7: Đang chạy | AE7: =IF(OR(A7="",B7=""),"",IF(COUNTIFS($A$5:$A$10004,A7,$B$5:$B$10004,B7)>1,"TRÙNG NGÀY + CHUYỀN",IF(G7="","THIẾU MÃ CA / MỤC TIÊU GIỜ",IF(SUMPRODUCT((COLUMN(H7:S7)-COLUMN(H7)+1>ROUNDUP(F7,0))*(H7:S7<>""))>0,"NHẬP QUÁ GIỜ CA",IF(AND(N(X7)>=ROUNDUP(N(F7),0),N(F7)>0,N(T7)<N(G7),AI7=""),"CHƯA GHI LÝ DO KHÔNG ĐẠT",IF(COUNTIFS(MUC_TIEU_THANG!$B$5:$B$2004,C7,MUC_TIEU_THANG!$A$5:$A$2004,">="&DATE(YEAR(A7),MONTH(A7),1),MUC_TIEU_THANG!$A$5:$A$2004,"<"&DATE(YEAR(A7),MONTH(A7)+1,1))=0,"CHƯA CÓ MỤC TIÊU THÁNG","OK")))))) | AF7: =IF(OR(A7="",B7=""),"",B7&"|"&A7) | AH7: =IF(OR(A7="",B7="",COUNTIFS(HANG_LOI!$A$5:$A$10004,A7,HANG_LOI!$C$5:$C$10004,B7)=0),"",SUMIFS(HANG_LOI!$F$5:$F$10004,HANG_LOI!$A$5:$A$10004,A7,HANG_LOI!$C$5:$C$10004,B7)) | AK7: =IF(OR(T7="",N(AG7)=0,N(X7)=0),"",T7/(AG7*X7)) | AL7: =IF(OR(AH7="",N(T7)=0),"",AH7/T7)
A8: 46295 | B8: Chuyền 4 | C8: MÃ 9H | D8: 9H | E8: 100 | F8: =IF(D8="","",IFERROR(INDEX(CAU_HINH_CA!$C$5:$C$50,MATCH(D8,CAU_HINH_CA!$A$5:$A$50,0)),"")) | G8: =IF(OR(F8="",E8=""),"",ROUND(F8*E8,0)) | T8: =IF(COUNT(H8:S8)=0,"",SUM(H8:S8)) | U8: =IF(OR(T8="",N(G8)=0),"",T8/G8) | V8: =IF(OR(T8="",G8=""),"",T8-G8) | W8: =IF(OR(T8="",G8=""),"",MAX(0,G8-T8)) | X8: =IF(A8="","",COUNT(H8:S8)) | Y8: =IF(OR(X8="",E8="",G8=""),"",MIN(G8,X8*E8)) | Z8: =IF(OR(T8="",N(Y8)=0),"",T8/Y8) | AA8: =IF(OR(A8="",B8=""),"",IF(SUMPRODUCT(MAX(($B$5:$B$10004=B8)*($A$5:$A$10004<A8)*$A$5:$A$10004))=0,"",SUMPRODUCT(MAX(($B$5:$B$10004=B8)*($A$5:$A$10004<A8)*$A$5:$A$10004)))) | AB8: =IF(N(AA8)=0,"",SUMIFS($W$5:$W$10004,$B$5:$B$10004,B8,$A$5:$A$10004,AA8)) | AC8: Đang chạy | AE8: =IF(OR(A8="",B8=""),"",IF(COUNTIFS($A$5:$A$10004,A8,$B$5:$B$10004,B8)>1,"TRÙNG NGÀY + CHUYỀN",IF(G8="","THIẾU MÃ CA / MỤC TIÊU GIỜ",IF(SUMPRODUCT((COLUMN(H8:S8)-COLUMN(H8)+1>ROUNDUP(F8,0))*(H8:S8<>""))>0,"NHẬP QUÁ GIỜ CA",IF(AND(N(X8)>=ROUNDUP(N(F8),0),N(F8)>0,N(T8)<N(G8),AI8=""),"CHƯA GHI LÝ DO KHÔNG ĐẠT",IF(COUNTIFS(MUC_TIEU_THANG!$B$5:$B$2004,C8,MUC_TIEU_THANG!$A$5:$A$2004,">="&DATE(YEAR(A8),MONTH(A8),1),MUC_TIEU_THANG!$A$5:$A$2004,"<"&DATE(YEAR(A8),MONTH(A8)+1,1))=0,"CHƯA CÓ MỤC TIÊU THÁNG","OK")))))) | AF8: =IF(OR(A8="",B8=""),"",B8&"|"&A8) | AH8: =IF(OR(A8="",B8="",COUNTIFS(HANG_LOI!$A$5:$A$10004,A8,HANG_LOI!$C$5:$C$10004,B8)=0),"",SUMIFS(HANG_LOI!$F$5:$F$10004,HANG_LOI!$A$5:$A$10004,A8,HANG_LOI!$C$5:$C$10004,B8)) | AK8: =IF(OR(T8="",N(AG8)=0,N(X8)=0),"",T8/(AG8*X8)) | AL8: =IF(OR(AH8="",N(T8)=0),"",AH8/T8)
A9: 46295 | B9: Chuyền 6 | C9: 567 | D9: 10H | E9: 40 | F9: =IF(D9="","",IFERROR(INDEX(CAU_HINH_CA!$C$5:$C$50,MATCH(D9,CAU_HINH_CA!$A$5:$A$50,0)),"")) | G9: =IF(OR(F9="",E9=""),"",ROUND(F9*E9,0)) | T9: =IF(COUNT(H9:S9)=0,"",SUM(H9:S9)) | U9: =IF(OR(T9="",N(G9)=0),"",T9/G9) | V9: =IF(OR(T9="",G9=""),"",T9-G9) | W9: =IF(OR(T9="",G9=""),"",MAX(0,G9-T9)) | X9: =IF(A9="","",COUNT(H9:S9)) | Y9: =IF(OR(X9="",E9="",G9=""),"",MIN(G9,X9*E9)) | Z9: =IF(OR(T9="",N(Y9)=0),"",T9/Y9) | AA9: =IF(OR(A9="",B9=""),"",IF(SUMPRODUCT(MAX(($B$5:$B$10004=B9)*($A$5:$A$10004<A9)*$A$5:$A$10004))=0,"",SUMPRODUCT(MAX(($B$5:$B$10004=B9)*($A$5:$A$10004<A9)*$A$5:$A$10004)))) | AB9: =IF(N(AA9)=0,"",SUMIFS($W$5:$W$10004,$B$5:$B$10004,B9,$A$5:$A$10004,AA9)) | AC9: Đang chạy | AE9: =IF(OR(A9="",B9=""),"",IF(COUNTIFS($A$5:$A$10004,A9,$B$5:$B$10004,B9)>1,"TRÙNG NGÀY + CHUYỀN",IF(G9="","THIẾU MÃ CA / MỤC TIÊU GIỜ",IF(SUMPRODUCT((COLUMN(H9:S9)-COLUMN(H9)+1>ROUNDUP(F9,0))*(H9:S9<>""))>0,"NHẬP QUÁ GIỜ CA",IF(AND(N(X9)>=ROUNDUP(N(F9),0),N(F9)>0,N(T9)<N(G9),AI9=""),"CHƯA GHI LÝ DO KHÔNG ĐẠT",IF(COUNTIFS(MUC_TIEU_THANG!$B$5:$B$2004,C9,MUC_TIEU_THANG!$A$5:$A$2004,">="&DATE(YEAR(A9),MONTH(A9),1),MUC_TIEU_THANG!$A$5:$A$2004,"<"&DATE(YEAR(A9),MONTH(A9)+1,1))=0,"CHƯA CÓ MỤC TIÊU THÁNG","OK")))))) | AF9: =IF(OR(A9="",B9=""),"",B9&"|"&A9) | AH9: =IF(OR(A9="",B9="",COUNTIFS(HANG_LOI!$A$5:$A$10004,A9,HANG_LOI!$C$5:$C$10004,B9)=0),"",SUMIFS(HANG_LOI!$F$5:$F$10004,HANG_LOI!$A$5:$A$10004,A9,HANG_LOI!$C$5:$C$10004,B9)) | AK9: =IF(OR(T9="",N(AG9)=0,N(X9)=0),"",T9/(AG9*X9)) | AL9: =IF(OR(AH9="",N(T9)=0),"",AH9/T9)

Sheet HANG_LOI
A1: 不良品記錄 / HÀNG LỖI (kèm ảnh, hiện trên TV)
A2: 日期 | B2: 時間 | C2: 產線 | D2: 产品代码 | E2: 不良類型 | F2: 數量PCS | G2: 照片檔名 | H2: 備註 | I2: 電視顯示 | J2: 檢查
A3: NGÀY | B3: GIỜ | C3: CHUYỀN | D3: MÃ SẢN PHẨM (tự lấy) | E3: LOẠI LỖI | F3: SỐ LƯỢNG | G3: TÊN FILE ẢNH | H3: GHI CHÚ | I3: HIỆN TRÊN TV | J3: KIỂM TRA
A4: 1 | B4: 2 | C4: 3 | D4: 4 | E4: 5 | F4: 6 | G4: 7 | H4: 8 | I4: 9 | J4: 10
A5: 46295 | B5: 0.42708333 | C5: Chuyền 2 | D5: =IF(OR(A5="",C5=""),"",IFERROR(INDEX(NHAP_LIEU!$C$5:$C$10004,MATCH(1,INDEX((NHAP_LIEU!$A$5:$A$10004=A5)*(NHAP_LIEU!$B$5:$B$10004=C5),0),0))&"","")) | E5: Rách đường may | F5: 1 | G5: vi_du_rach.jpg | I5: =IF(OR(A5="",C5=""),"",IF(A5=HIEN_THI!$M$1,"CÓ","")) | J5: =IF(AND(A5="",C5=""),"",IF(OR(A5="",C5=""),"THIẾU NGÀY / CHUYỀN",IF(D5="","CHƯA CÓ DÒNG NHẬP LIỆU NGÀY NÀY",IF(N(F5)<=0,"THIẾU SỐ LƯỢNG",IF(E5="","CHƯA CHỌN LOẠI LỖI",IF(G5="","OK (chưa có ảnh)","OK"))))))
A6: 46295 | B6: 0.39583333 | C6: Chuyền 1 | D6: =IF(OR(A6="",C6=""),"",IFERROR(INDEX(NHAP_LIEU!$C$5:$C$10004,MATCH(1,INDEX((NHAP_LIEU!$A$5:$A$10004=A6)*(NHAP_LIEU!$B$5:$B$10004=C6),0),0))&"","")) | E6: Khóa / phụ kiện lệch | F6: 2 | I6: =IF(OR(A6="",C6=""),"",IF(A6=HIEN_THI!$M$1,"CÓ","")) | J6: =IF(AND(A6="",C6=""),"",IF(OR(A6="",C6=""),"THIẾU NGÀY / CHUYỀN",IF(D6="","CHƯA CÓ DÒNG NHẬP LIỆU NGÀY NÀY",IF(N(F6)<=0,"THIẾU SỐ LƯỢNG",IF(E6="","CHƯA CHỌN LOẠI LỖI",IF(G6="","OK (chưa có ảnh)","OK"))))))

Sheet MUC_TIEU_THANG
A1: 當月目標與累計 / MỤC TIÊU & LŨY KẾ THÁNG
A2: 月份 | B2: 产品代码 | C2: 当月总目标产量PCS | D2: 備註 | E2: 当月累计产能PCS | F2: 当月累计差异PCS | G2: 当月总达成率 | H2: 剩餘PCS | I2: 累計每日目標PCS | J2: 與每日目標差異PCS | K2: 上月欠數PCS | L2: 當月工作天數 | M2: 平均每日需產量PCS
A3: THÁNG | B3: MÃ SẢN PHẨM | C3: TỔNG SẢN LƯỢNG MỤC TIÊU TRONG THÁNG | D3: GHI CHÚ | E3: LŨY KẾ SẢN LƯỢNG TRONG THÁNG | F3: LŨY KẾ CHÊNH LỆCH TRONG THÁNG | G3: TỔNG ĐẠT % TRONG THÁNG | H3: CÒN THIẾU TRONG THÁNG | I3: LŨY KẾ MỤC TIÊU NGÀY (các ngày đã nhập) | J3: CHÊNH LỆCH SO VỚI MỤC TIÊU NGÀY | K3: THIẾU THÁNG TRƯỚC | L3: SỐ NGÀY LÀM VIỆC TRONG THÁNG | M3: BÌNH QUÂN CẦN / NGÀY
A4: 1 | B4: 2 | C4: 3 | D4: 4 | E4: 5 | F4: 6 | G4: 7 | H4: 8 | I4: 9 | J4: 10 | K4: 11 | L4: 12 | M4: 13
A5: 46266 | B5: ĐAI LƯNG | C5: 40000 | E5: =IF(OR(A5="",B5=""),"",SUMPRODUCT((NHAP_LIEU!$C$5:$C$10004=B5)*(NHAP_LIEU!$A$5:$A$10004>=DATE(YEAR(A5),MONTH(A5),1))*(NHAP_LIEU!$A$5:$A$10004<DATE(YEAR(A5),MONTH(A5)+1,1))*NHAP_LIEU!$H$5:$S$10004)) | F5: =IF(OR(E5="",C5=""),"",E5-C5) | G5: =IF(OR(E5="",N(C5)=0),"",E5/C5) | H5: =IF(OR(E5="",C5=""),"",MAX(0,C5-E5)) | I5: =IF(OR(A5="",B5=""),"",SUMPRODUCT((NHAP_LIEU!$C$5:$C$10004=B5)*(NHAP_LIEU!$A$5:$A$10004>=DATE(YEAR(A5),MONTH(A5),1))*(NHAP_LIEU!$A$5:$A$10004<DATE(YEAR(A5),MONTH(A5)+1,1))*(((NHAP_LIEU!$H$5:$H$10004<>"")+(NHAP_LIEU!$I$5:$I$10004<>"")+(NHAP_LIEU!$J$5:$J$10004<>"")+(NHAP_LIEU!$K$5:$K$10004<>"")+(NHAP_LIEU!$L$5:$L$10004<>"")+(NHAP_LIEU!$M$5:$M$10004<>"")+(NHAP_LIEU!$N$5:$N$10004<>"")+(NHAP_LIEU!$O$5:$O$10004<>"")+(NHAP_LIEU!$P$5:$P$10004<>"")+(NHAP_LIEU!$Q$5:$Q$10004<>"")+(NHAP_LIEU!$R$5:$R$10004<>"")+(NHAP_LIEU!$S$5:$S$10004<>""))>0)*ROUND(SUMIF(CAU_HINH_CA!$A$5:$A$50,NHAP_LIEU!$D$5:$D$10004,CAU_HINH_CA!$C$5:$C$50)*NHAP_LIEU!$E$5:$E$10004,0))) | J5: =IF(I5="","",E5-I5) | K5: =IF(OR(A5="",B5=""),"",SUMIFS($H$5:$H$2004,$B$5:$B$2004,B5,$A$5:$A$2004,">="&DATE(YEAR(A5),MONTH(A5)-1,1),$A$5:$A$2004,"<"&DATE(YEAR(A5),MONTH(A5),1))) | L5: =IF(A5="","",MAX(0,NETWORKDAYS.INTL(DATE(YEAR(A5),MONTH(A5),1),EOMONTH(A5,0),11)-SUMPRODUCT((LICH_LAM_VIEC!$A$5:$A$1000>=DATE(YEAR(A5),MONTH(A5),1))*(LICH_LAM_VIEC!$A$5:$A$1000<=EOMONTH(A5,0))*(LICH_LAM_VIEC!$B$5:$B$1000="Nghỉ")*(WEEKDAY(LICH_LAM_VIEC!$A$5:$A$1000)<>1))+SUMPRODUCT((LICH_LAM_VIEC!$A$5:$A$1000>=DATE(YEAR(A5),MONTH(A5),1))*(LICH_LAM_VIEC!$A$5:$A$1000<=EOMONTH(A5,0))*(LICH_LAM_VIEC!$B$5:$B$1000="Làm bù")*(WEEKDAY(LICH_LAM_VIEC!$A$5:$A$1000)=1)))) | M5: =IF(OR(N(L5)=0,C5=""),"",ROUNDUP(C5/L5,0))
A6: 46266 | B6: BAO TAY XANH | C6: 40000 | E6: =IF(OR(A6="",B6=""),"",SUMPRODUCT((NHAP_LIEU!$C$5:$C$10004=B6)*(NHAP_LIEU!$A$5:$A$10004>=DATE(YEAR(A6),MONTH(A6),1))*(NHAP_LIEU!$A$5:$A$10004<DATE(YEAR(A6),MONTH(A6)+1,1))*NHAP_LIEU!$H$5:$S$10004)) | F6: =IF(OR(E6="",C6=""),"",E6-C6) | G6: =IF(OR(E6="",N(C6)=0),"",E6/C6) | H6: =IF(OR(E6="",C6=""),"",MAX(0,C6-E6)) | I6: =IF(OR(A6="",B6=""),"",SUMPRODUCT((NHAP_LIEU!$C$5:$C$10004=B6)*(NHAP_LIEU!$A$5:$A$10004>=DATE(YEAR(A6),MONTH(A6),1))*(NHAP_LIEU!$A$5:$A$10004<DATE(YEAR(A6),MONTH(A6)+1,1))*(((NHAP_LIEU!$H$5:$H$10004<>"")+(NHAP_LIEU!$I$5:$I$10004<>"")+(NHAP_LIEU!$J$5:$J$10004<>"")+(NHAP_LIEU!$K$5:$K$10004<>"")+(NHAP_LIEU!$L$5:$L$10004<>"")+(NHAP_LIEU!$M$5:$M$10004<>"")+(NHAP_LIEU!$N$5:$N$10004<>"")+(NHAP_LIEU!$O$5:$O$10004<>"")+(NHAP_LIEU!$P$5:$P$10004<>"")+(NHAP_LIEU!$Q$5:$Q$10004<>"")+(NHAP_LIEU!$R$5:$R$10004<>"")+(NHAP_LIEU!$S$5:$S$10004<>""))>0)*ROUND(SUMIF(CAU_HINH_CA!$A$5:$A$50,NHAP_LIEU!$D$5:$D$10004,CAU_HINH_CA!$C$5:$C$50)*NHAP_LIEU!$E$5:$E$10004,0))) | J6: =IF(I6="","",E6-I6) | K6: =IF(OR(A6="",B6=""),"",SUMIFS($H$5:$H$2004,$B$5:$B$2004,B6,$A$5:$A$2004,">="&DATE(YEAR(A6),MONTH(A6)-1,1),$A$5:$A$2004,"<"&DATE(YEAR(A6),MONTH(A6),1))) | L6: =IF(A6="","",MAX(0,NETWORKDAYS.INTL(DATE(YEAR(A6),MONTH(A6),1),EOMONTH(A6,0),11)-SUMPRODUCT((LICH_LAM_VIEC!$A$5:$A$1000>=DATE(YEAR(A6),MONTH(A6),1))*(LICH_LAM_VIEC!$A$5:$A$1000<=EOMONTH(A6,0))*(LICH_LAM_VIEC!$B$5:$B$1000="Nghỉ")*(WEEKDAY(LICH_LAM_VIEC!$A$5:$A$1000)<>1))+SUMPRODUCT((LICH_LAM_VIEC!$A$5:$A$1000>=DATE(YEAR(A6),MONTH(A6),1))*(LICH_LAM_VIEC!$A$5:$A$1000<=EOMONTH(A6,0))*(LICH_LAM_VIEC!$B$5:$B$1000="Làm bù")*(WEEKDAY(LICH_LAM_VIEC!$A$5:$A$1000)=1)))) | M6: =IF(OR(N(L6)=0,C6=""),"",ROUNDUP(C6/L6,0))
A7: 46266 | B7: 883 | C7: 50000 | E7: =IF(OR(A7="",B7=""),"",SUMPRODUCT((NHAP_LIEU!$C$5:$C$10004=B7)*(NHAP_LIEU!$A$5:$A$10004>=DATE(YEAR(A7),MONTH(A7),1))*(NHAP_LIEU!$A$5:$A$10004<DATE(YEAR(A7),MONTH(A7)+1,1))*NHAP_LIEU!$H$5:$S$10004)) | F7: =IF(OR(E7="",C7=""),"",E7-C7) | G7: =IF(OR(E7="",N(C7)=0),"",E7/C7) | H7: =IF(OR(E7="",C7=""),"",MAX(0,C7-E7)) | I7: =IF(OR(A7="",B7=""),"",SUMPRODUCT((NHAP_LIEU!$C$5:$C$10004=B7)*(NHAP_LIEU!$A$5:$A$10004>=DATE(YEAR(A7),MONTH(A7),1))*(NHAP_LIEU!$A$5:$A$10004<DATE(YEAR(A7),MONTH(A7)+1,1))*(((NHAP_LIEU!$H$5:$H$10004<>"")+(NHAP_LIEU!$I$5:$I$10004<>"")+(NHAP_LIEU!$J$5:$J$10004<>"")+(NHAP_LIEU!$K$5:$K$10004<>"")+(NHAP_LIEU!$L$5:$L$10004<>"")+(NHAP_LIEU!$M$5:$M$10004<>"")+(NHAP_LIEU!$N$5:$N$10004<>"")+(NHAP_LIEU!$O$5:$O$10004<>"")+(NHAP_LIEU!$P$5:$P$10004<>"")+(NHAP_LIEU!$Q$5:$Q$10004<>"")+(NHAP_LIEU!$R$5:$R$10004<>"")+(NHAP_LIEU!$S$5:$S$10004<>""))>0)*ROUND(SUMIF(CAU_HINH_CA!$A$5:$A$50,NHAP_LIEU!$D$5:$D$10004,CAU_HINH_CA!$C$5:$C$50)*NHAP_LIEU!$E$5:$E$10004,0))) | J7: =IF(I7="","",E7-I7) | K7: =IF(OR(A7="",B7=""),"",SUMIFS($H$5:$H$2004,$B$5:$B$2004,B7,$A$5:$A$2004,">="&DATE(YEAR(A7),MONTH(A7)-1,1),$A$5:$A$2004,"<"&DATE(YEAR(A7),MONTH(A7),1))) | L7: =IF(A7="","",MAX(0,NETWORKDAYS.INTL(DATE(YEAR(A7),MONTH(A7),1),EOMONTH(A7,0),11)-SUMPRODUCT((LICH_LAM_VIEC!$A$5:$A$1000>=DATE(YEAR(A7),MONTH(A7),1))*(LICH_LAM_VIEC!$A$5:$A$1000<=EOMONTH(A7,0))*(LICH_LAM_VIEC!$B$5:$B$1000="Nghỉ")*(WEEKDAY(LICH_LAM_VIEC!$A$5:$A$1000)<>1))+SUMPRODUCT((LICH_LAM_VIEC!$A$5:$A$1000>=DATE(YEAR(A7),MONTH(A7),1))*(LICH_LAM_VIEC!$A$5:$A$1000<=EOMONTH(A7,0))*(LICH_LAM_VIEC!$B$5:$B$1000="Làm bù")*(WEEKDAY(LICH_LAM_VIEC!$A$5:$A$1000)=1)))) | M7: =IF(OR(N(L7)=0,C7=""),"",ROUNDUP(C7/L7,0))
A8: 46266 | B8: 567 | C8: 100000 | D8: Test | E8: =IF(OR(A8="",B8=""),"",SUMPRODUCT((NHAP_LIEU!$C$5:$C$10004=B8)*(NHAP_LIEU!$A$5:$A$10004>=DATE(YEAR(A8),MONTH(A8),1))*(NHAP_LIEU!$A$5:$A$10004<DATE(YEAR(A8),MONTH(A8)+1,1))*NHAP_LIEU!$H$5:$S$10004)) | F8: =IF(OR(E8="",C8=""),"",E8-C8) | G8: =IF(OR(E8="",N(C8)=0),"",E8/C8) | H8: =IF(OR(E8="",C8=""),"",MAX(0,C8-E8)) | I8: =IF(OR(A8="",B8=""),"",SUMPRODUCT((NHAP_LIEU!$C$5:$C$10004=B8)*(NHAP_LIEU!$A$5:$A$10004>=DATE(YEAR(A8),MONTH(A8),1))*(NHAP_LIEU!$A$5:$A$10004<DATE(YEAR(A8),MONTH(A8)+1,1))*(((NHAP_LIEU!$H$5:$H$10004<>"")+(NHAP_LIEU!$I$5:$I$10004<>"")+(NHAP_LIEU!$J$5:$J$10004<>"")+(NHAP_LIEU!$K$5:$K$10004<>"")+(NHAP_LIEU!$L$5:$L$10004<>"")+(NHAP_LIEU!$M$5:$M$10004<>"")+(NHAP_LIEU!$N$5:$N$10004<>"")+(NHAP_LIEU!$O$5:$O$10004<>"")+(NHAP_LIEU!$P$5:$P$10004<>"")+(NHAP_LIEU!$Q$5:$Q$10004<>"")+(NHAP_LIEU!$R$5:$R$10004<>"")+(NHAP_LIEU!$S$5:$S$10004<>""))>0)*ROUND(SUMIF(CAU_HINH_CA!$A$5:$A$50,NHAP_LIEU!$D$5:$D$10004,CAU_HINH_CA!$C$5:$C$50)*NHAP_LIEU!$E$5:$E$10004,0))) | J8: =IF(I8="","",E8-I8) | K8: =IF(OR(A8="",B8=""),"",SUMIFS($H$5:$H$2004,$B$5:$B$2004,B8,$A$5:$A$2004,">="&DATE(YEAR(A8),MONTH(A8)-1,1),$A$5:$A$2004,"<"&DATE(YEAR(A8),MONTH(A8),1))) | L8: =IF(A8="","",MAX(0,NETWORKDAYS.INTL(DATE(YEAR(A8),MONTH(A8),1),EOMONTH(A8,0),11)-SUMPRODUCT((LICH_LAM_VIEC!$A$5:$A$1000>=DATE(YEAR(A8),MONTH(A8),1))*(LICH_LAM_VIEC!$A$5:$A$1000<=EOMONTH(A8,0))*(LICH_LAM_VIEC!$B$5:$B$1000="Nghỉ")*(WEEKDAY(LICH_LAM_VIEC!$A$5:$A$1000)<>1))+SUMPRODUCT((LICH_LAM_VIEC!$A$5:$A$1000>=DATE(YEAR(A8),MONTH(A8),1))*(LICH_LAM_VIEC!$A$5:$A$1000<=EOMONTH(A8,0))*(LICH_LAM_VIEC!$B$5:$B$1000="Làm bù")*(WEEKDAY(LICH_LAM_VIEC!$A$5:$A$1000)=1)))) | M8: =IF(OR(N(L8)=0,C8=""),"",ROUNDUP(C8/L8,0))

Sheet HIEN_THI
A1: 電視顯示 / BẢNG HIỂN THỊ TV | G1: CHỌN NGÀY (để trống = ngày mới nhất): | K1: ĐANG HIỂN THỊ: | M1: =IF(J1<>"",J1,MAX(NHAP_LIEU!$A$5:$A$10004))
A2: 日期 | B2: 產線 | C2: 产品代码 | D2: 工作時間 | E2: 總工時 | F2: 每小时目标产量PCS | G2: 每日目标产量PCS | H2: 每日实际产量PCS | I2: 当日达成率% | J2: 差異PCS | K2: 剩餘PCS | L2: 已輸入小時數 | M2: 累計目標PCS | N2: 進度達成率% | O2: 前一工作日 | P2: 前一日欠數PCS | Q2: 当月总目标产量PCS | R2: 当月累计产能PCS | S2: 当月总达成率 | T2: 剩餘PCS | U2: 本線當月累計PCS | V2: 第1小時 | W2: 第2小時 | X2: 第3小時 | Y2: 第4小時 | Z2: 第5小時 | AA2: 第6小時 | AB2: 第7小時 | AC2: 第8小時 | AD2: 第9小時 | AE2: 第10小時 | AF2: 第11小時 | AG2: 第12小時 | AH2: 狀態 | AI2: 備註 | AJ2: 索引 | AK2: 前一日索引 | AL2: 上月欠數PCS | AM2: 剩餘工作天數 | AN2: 每日需產量PCS | AO2: 工人數 | AP2: 人均每小時產量 | AQ2: 不良數PCS | AR2: 不良率% | AS2: 未達原因 | AT2: 停機分鐘
A3: NGÀY | B3: CHUYỀN | C3: MÃ SẢN PHẨM | D3: MÃ CA | E3: GIỜ CA | F3: MỤC TIÊU MỖI GIỜ | G3: MỤC TIÊU TRONG NGÀY | H3: THỰC TẾ TRONG NGÀY | I3: TỶ LỆ ĐẠT TRONG NGÀY | J3: CHÊNH LỆCH | K3: CÒN THIẾU | L3: SỐ GIỜ ĐÃ NHẬP | M3: MỤC TIÊU ĐẾN GIỜ ĐÃ NHẬP | N3: TIẾN ĐỘ THEO GIỜ | O3: NGÀY LÀM TRƯỚC | P3: THIẾU HÔM TRƯỚC | Q3: MỤC TIÊU THÁNG (SẢN PHẨM) | R3: LŨY KẾ THÁNG (SẢN PHẨM, đến ngày này) | S3: TỶ LỆ ĐẠT THÁNG | T3: CÒN THIẾU THÁNG | U3: LŨY KẾ THÁNG CỦA CHUYỀN | V3: GIỜ 1 | W3: GIỜ 2 | X3: GIỜ 3 | Y3: GIỜ 4 | Z3: GIỜ 5 | AA3: GIỜ 6 | AB3: GIỜ 7 | AC3: GIỜ 8 | AD3: GIỜ 9 | AE3: GIỜ 10 | AF3: GIỜ 11 | AG3: GIỜ 12 | AH3: TRẠNG THÁI | AI3: GHI CHÚ | AJ3: DÒNG NHẬP LIỆU (máy dùng) | AK3: DÒNG NGÀY TRƯỚC (máy dùng) | AL3: THIẾU THÁNG TRƯỚC (SẢN PHẨM) | AM3: NGÀY LÀM VIỆC CÒN LẠI (tính cả ngày này) | AN3: CẦN LÀM MỖI NGÀY ĐỂ KỊP THÁNG (SẢN PHẨM) | AO3: SỐ CÔNG NHÂN | AP3: SP / NGƯỜI / GIỜ | AQ3: SỐ LỖI | AR3: TỶ LỆ LỖI | AS3: LÝ DO KHÔNG ĐẠT | AT3: PHÚT DỪNG MÁY
A4: 1 | B4: 2 | C4: 3 | D4: 4 | E4: 5 | F4: 6 | G4: 7 | H4: 8 | I4: 9 | J4: 10 | K4: 11 | L4: 12 | M4: 13 | N4: 14 | O4: 15 | P4: 16 | Q4: 17 | R4: 18 | S4: 19 | T4: 20 | U4: 21 | V4: 22 | W4: 23 | X4: 24 | Y4: 25 | Z4: 26 | AA4: 27 | AB4: 28 | AC4: 29 | AD4: 30 | AE4: 31 | AF4: 32 | AG4: 33 | AH4: 34 | AI4: 35 | AJ4: 36 | AK4: 37 | AL4: 38 | AM4: 39 | AN4: 40 | AO4: 41 | AP4: 42 | AQ4: 43 | AR4: 44 | AS4: 45 | AT4: 46
A5: =IF(B5="","",$M$1) | B5: =IF(DANH_SACH_CHUYEN!B5="","",DANH_SACH_CHUYEN!B5) | C5: =IF($AJ5="","",IF(INDEX(NHAP_LIEU!$C$5:$C$10004,$AJ5)="","",INDEX(NHAP_LIEU!$C$5:$C$10004,$AJ5))) | D5: =IF($AJ5="","",IF(INDEX(NHAP_LIEU!$D$5:$D$10004,$AJ5)="","",INDEX(NHAP_LIEU!$D$5:$D$10004,$AJ5))) | E5: =IF(D5="","",IFERROR(INDEX(CAU_HINH_CA!$C$5:$C$50,MATCH(D5,CAU_HINH_CA!$A$5:$A$50,0)),"")) | F5: =IF($AJ5="","",IF(INDEX(NHAP_LIEU!$E$5:$E$10004,$AJ5)="","",INDEX(NHAP_LIEU!$E$5:$E$10004,$AJ5))) | G5: =IF(OR(E5="",F5=""),"",ROUND(E5*F5,0)) | H5: =IF(COUNT(V5:AG5)=0,"",SUM(V5:AG5)) | I5: =IF(OR(H5="",N(G5)=0),"",H5/G5) | J5: =IF(OR(H5="",G5=""),"",H5-G5) | K5: =IF(OR(H5="",G5=""),"",MAX(0,G5-H5)) | L5: =IF(AJ5="","",COUNT(V5:AG5)) | M5: =IF(OR(L5="",F5="",G5=""),"",MIN(G5,L5*F5)) | N5: =IF(OR(H5="",N(M5)=0),"",H5/M5) | O5: =IF(OR(B5="",A5=""),"",IF(SUMPRODUCT(MAX((NHAP_LIEU!$B$5:$B$10004=B5)*(NHAP_LIEU!$A$5:$A$10004<A5)*NHAP_LIEU!$A$5:$A$10004))=0,"",SUMPRODUCT(MAX((NHAP_LIEU!$B$5:$B$10004=B5)*(NHAP_LIEU!$A$5:$A$10004<A5)*NHAP_LIEU!$A$5:$A$10004)))) | P5: =IF(AK5="","",IF(COUNT(INDEX(NHAP_LIEU!$H$5:$S$10004,AK5,0))=0,0,MAX(0,IFERROR(ROUND(INDEX(CAU_HINH_CA!$C$5:$C$50,MATCH(INDEX(NHAP_LIEU!$D$5:$D$10004,AK5),CAU_HINH_CA!$A$5:$A$50,0))*INDEX(NHAP_LIEU!$E$5:$E$10004,AK5),0),0)-SUM(INDEX(NHAP_LIEU!$H$5:$S$10004,AK5,0))))) | Q5: =IF(C5="","",SUMIFS(MUC_TIEU_THANG!$C$5:$C$2004,MUC_TIEU_THANG!$B$5:$B$2004,C5,MUC_TIEU_THANG!$A$5:$A$2004,">="&DATE(YEAR(A5),MONTH(A5),1),MUC_TIEU_THANG!$A$5:$A$2004,"<"&DATE(YEAR(A5),MONTH(A5)+1,1))) | R5: =IF(C5="","",SUMPRODUCT((NHAP_LIEU!$C$5:$C$10004=C5)*(NHAP_LIEU!$A$5:$A$10004>=DATE(YEAR(A5),MONTH(A5),1))*(NHAP_LIEU!$A$5:$A$10004<=A5)*NHAP_LIEU!$H$5:$S$10004)) | S5: =IF(OR(R5="",N(Q5)=0),"",R5/Q5) | T5: =IF(OR(R5="",N(Q5)=0),"",MAX(0,Q5-R5)) | U5: =IF(B5="","",SUMPRODUCT((NHAP_LIEU!$B$5:$B$10004=B5)*(NHAP_LIEU!$A$5:$A$10004>=DATE(YEAR(A5),MONTH(A5),1))*(NHAP_LIEU!$A$5:$A$10004<=A5)*NHAP_LIEU!$H$5:$S$10004)) | V5: =IF($AJ5="","",IF(INDEX(NHAP_LIEU!$H$5:$H$10004,$AJ5)="","",INDEX(NHAP_LIEU!$H$5:$H$10004,$AJ5))) | W5: =IF($AJ5="","",IF(INDEX(NHAP_LIEU!$I$5:$I$10004,$AJ5)="","",INDEX(NHAP_LIEU!$I$5:$I$10004,$AJ5))) | X5: =IF($AJ5="","",IF(INDEX(NHAP_LIEU!$J$5:$J$10004,$AJ5)="","",INDEX(NHAP_LIEU!$J$5:$J$10004,$AJ5))) | Y5: =IF($AJ5="","",IF(INDEX(NHAP_LIEU!$K$5:$K$10004,$AJ5)="","",INDEX(NHAP_LIEU!$K$5:$K$10004,$AJ5))) | Z5: =IF($AJ5="","",IF(INDEX(NHAP_LIEU!$L$5:$L$10004,$AJ5)="","",INDEX(NHAP_LIEU!$L$5:$L$10004,$AJ5))) | AA5: =IF($AJ5="","",IF(INDEX(NHAP_LIEU!$M$5:$M$10004,$AJ5)="","",INDEX(NHAP_LIEU!$M$5:$M$10004,$AJ5))) | AB5: =IF($AJ5="","",IF(INDEX(NHAP_LIEU!$N$5:$N$10004,$AJ5)="","",INDEX(NHAP_LIEU!$N$5:$N$10004,$AJ5))) | AC5: =IF($AJ5="","",IF(INDEX(NHAP_LIEU!$O$5:$O$10004,$AJ5)="","",INDEX(NHAP_LIEU!$O$5:$O$10004,$AJ5))) | AD5: =IF($AJ5="","",IF(INDEX(NHAP_LIEU!$P$5:$P$10004,$AJ5)="","",INDEX(NHAP_LIEU!$P$5:$P$10004,$AJ5))) | AE5: =IF($AJ5="","",IF(INDEX(NHAP_LIEU!$Q$5:$Q$10004,$AJ5)="","",INDEX(NHAP_LIEU!$Q$5:$Q$10004,$AJ5))) | AF5: =IF($AJ5="","",IF(INDEX(NHAP_LIEU!$R$5:$R$10004,$AJ5)="","",INDEX(NHAP_LIEU!$R$5:$R$10004,$AJ5))) | AG5: =IF($AJ5="","",IF(INDEX(NHAP_LIEU!$S$5:$S$10004,$AJ5)="","",INDEX(NHAP_LIEU!$S$5:$S$10004,$AJ5))) | AH5: =IF($AJ5="","",IF(INDEX(NHAP_LIEU!$AC$5:$AC$10004,$AJ5)="","",INDEX(NHAP_LIEU!$AC$5:$AC$10004,$AJ5))) | AI5: =IF($AJ5="","",IF(INDEX(NHAP_LIEU!$AD$5:$AD$10004,$AJ5)="","",INDEX(NHAP_LIEU!$AD$5:$AD$10004,$AJ5))) | AJ5: =IF(OR(B5="",A5=""),"",IFERROR(MATCH(1,INDEX((NHAP_LIEU!$A$5:$A$10004=A5)*(NHAP_LIEU!$B$5:$B$10004=B5),0),0),"")) | AK5: =IF(O5="","",IFERROR(MATCH(1,INDEX((NHAP_LIEU!$A$5:$A$10004=O5)*(NHAP_LIEU!$B$5:$B$10004=B5),0),0),"")) | AL5: =IF(C5="","",SUMIFS(MUC_TIEU_THANG!$K$5:$K$2004,MUC_TIEU_THANG!$B$5:$B$2004,C5,MUC_TIEU_THANG!$A$5:$A$2004,">="&DATE(YEAR(A5),MONTH(A5),1),MUC_TIEU_THANG!$A$5:$A$2004,"<"&DATE(YEAR(A5),MONTH(A5)+1,1))) | AM5: =IF(A5="","",MAX(0,NETWORKDAYS.INTL(A5,EOMONTH(A5,0),11)-SUMPRODUCT((LICH_LAM_VIEC!$A$5:$A$1000>=A5)*(LICH_LAM_VIEC!$A$5:$A$1000<=EOMONTH(A5,0))*(LICH_LAM_VIEC!$B$5:$B$1000="Nghỉ")*(WEEKDAY(LICH_LAM_VIEC!$A$5:$A$1000)<>1))+SUMPRODUCT((LICH_LAM_VIEC!$A$5:$A$1000>=A5)*(LICH_LAM_VIEC!$A$5:$A$1000<=EOMONTH(A5,0))*(LICH_LAM_VIEC!$B$5:$B$1000="Làm bù")*(WEEKDAY(LICH_LAM_VIEC!$A$5:$A$1000)=1)))) | AN5: =IF(OR(C5="",N(Q5)=0,N(AM5)=0),"",ROUNDUP(MAX(0,Q5-SUMPRODUCT((NHAP_LIEU!$C$5:$C$10004=C5)*(NHAP_LIEU!$A$5:$A$10004>=DATE(YEAR(A5),MONTH(A5),1))*(NHAP_LIEU!$A$5:$A$10004<A5)*NHAP_LIEU!$H$5:$S$10004))/AM5,0)) | AO5: =IF($AJ5="","",IF(INDEX(NHAP_LIEU!$AG$5:$AG$10004,$AJ5)="","",INDEX(NHAP_LIEU!$AG$5:$AG$10004,$AJ5))) | AP5: =IF(OR(H5="",N(AO5)=0,N(L5)=0),"",H5/(AO5*L5)) | AQ5: =IF(OR(B5="",A5="",COUNTIFS(HANG_LOI!$A$5:$A$10004,A5,HANG_LOI!$C$5:$C$10004,B5)=0),"",SUMIFS(HANG_LOI!$F$5:$F$10004,HANG_LOI!$A$5:$A$10004,A5,HANG_LOI!$C$5:$C$10004,B5)) | AR5: =IF(OR(AQ5="",N(H5)=0),"",AQ5/H5) | AS5: =IF($AJ5="","",IF(INDEX(NHAP_LIEU!$AI$5:$AI$10004,$AJ5)="","",INDEX(NHAP_LIEU!$AI$5:$AI$10004,$AJ5))) | AT5: =IF($AJ5="","",IF(INDEX(NHAP_LIEU!$AJ$5:$AJ$10004,$AJ5)="","",INDEX(NHAP_LIEU!$AJ$5:$AJ$10004,$AJ5)))
A6: =IF(B6="","",$M$1) | B6: =IF(DANH_SACH_CHUYEN!B6="","",DANH_SACH_CHUYEN!B6) | C6: =IF($AJ6="","",IF(INDEX(NHAP_LIEU!$C$5:$C$10004,$AJ6)="","",INDEX(NHAP_LIEU!$C$5:$C$10004,$AJ6))) | D6: =IF($AJ6="","",IF(INDEX(NHAP_LIEU!$D$5:$D$10004,$AJ6)="","",INDEX(NHAP_LIEU!$D$5:$D$10004,$AJ6))) | E6: =IF(D6="","",IFERROR(INDEX(CAU_HINH_CA!$C$5:$C$50,MATCH(D6,CAU_HINH_CA!$A$5:$A$50,0)),"")) | F6: =IF($AJ6="","",IF(INDEX(NHAP_LIEU!$E$5:$E$10004,$AJ6)="","",INDEX(NHAP_LIEU!$E$5:$E$10004,$AJ6))) | G6: =IF(OR(E6="",F6=""),"",ROUND(E6*F6,0)) | H6: =IF(COUNT(V6:AG6)=0,"",SUM(V6:AG6)) | I6: =IF(OR(H6="",N(G6)=0),"",H6/G6) | J6: =IF(OR(H6="",G6=""),"",H6-G6) | K6: =IF(OR(H6="",G6=""),"",MAX(0,G6-H6)) | L6: =IF(AJ6="","",COUNT(V6:AG6)) | M6: =IF(OR(L6="",F6="",G6=""),"",MIN(G6,L6*F6)) | N6: =IF(OR(H6="",N(M6)=0),"",H6/M6) | O6: =IF(OR(B6="",A6=""),"",IF(SUMPRODUCT(MAX((NHAP_LIEU!$B$5:$B$10004=B6)*(NHAP_LIEU!$A$5:$A$10004<A6)*NHAP_LIEU!$A$5:$A$10004))=0,"",SUMPRODUCT(MAX((NHAP_LIEU!$B$5:$B$10004=B6)*(NHAP_LIEU!$A$5:$A$10004<A6)*NHAP_LIEU!$A$5:$A$10004)))) | P6: =IF(AK6="","",IF(COUNT(INDEX(NHAP_LIEU!$H$5:$S$10004,AK6,0))=0,0,MAX(0,IFERROR(ROUND(INDEX(CAU_HINH_CA!$C$5:$C$50,MATCH(INDEX(NHAP_LIEU!$D$5:$D$10004,AK6),CAU_HINH_CA!$A$5:$A$50,0))*INDEX(NHAP_LIEU!$E$5:$E$10004,AK6),0),0)-SUM(INDEX(NHAP_LIEU!$H$5:$S$10004,AK6,0))))) | Q6: =IF(C6="","",SUMIFS(MUC_TIEU_THANG!$C$5:$C$2004,MUC_TIEU_THANG!$B$5:$B$2004,C6,MUC_TIEU_THANG!$A$5:$A$2004,">="&DATE(YEAR(A6),MONTH(A6),1),MUC_TIEU_THANG!$A$5:$A$2004,"<"&DATE(YEAR(A6),MONTH(A6)+1,1))) | R6: =IF(C6="","",SUMPRODUCT((NHAP_LIEU!$C$5:$C$10004=C6)*(NHAP_LIEU!$A$5:$A$10004>=DATE(YEAR(A6),MONTH(A6),1))*(NHAP_LIEU!$A$5:$A$10004<=A6)*NHAP_LIEU!$H$5:$S$10004)) | S6: =IF(OR(R6="",N(Q6)=0),"",R6/Q6) | T6: =IF(OR(R6="",N(Q6)=0),"",MAX(0,Q6-R6)) | U6: =IF(B6="","",SUMPRODUCT((NHAP_LIEU!$B$5:$B$10004=B6)*(NHAP_LIEU!$A$5:$A$10004>=DATE(YEAR(A6),MONTH(A6),1))*(NHAP_LIEU!$A$5:$A$10004<=A6)*NHAP_LIEU!$H$5:$S$10004)) | V6: =IF($AJ6="","",IF(INDEX(NHAP_LIEU!$H$5:$H$10004,$AJ6)="","",INDEX(NHAP_LIEU!$H$5:$H$10004,$AJ6))) | W6: =IF($AJ6="","",IF(INDEX(NHAP_LIEU!$I$5:$I$10004,$AJ6)="","",INDEX(NHAP_LIEU!$I$5:$I$10004,$AJ6))) | X6: =IF($AJ6="","",IF(INDEX(NHAP_LIEU!$J$5:$J$10004,$AJ6)="","",INDEX(NHAP_LIEU!$J$5:$J$10004,$AJ6))) | Y6: =IF($AJ6="","",IF(INDEX(NHAP_LIEU!$K$5:$K$10004,$AJ6)="","",INDEX(NHAP_LIEU!$K$5:$K$10004,$AJ6))) | Z6: =IF($AJ6="","",IF(INDEX(NHAP_LIEU!$L$5:$L$10004,$AJ6)="","",INDEX(NHAP_LIEU!$L$5:$L$10004,$AJ6))) | AA6: =IF($AJ6="","",IF(INDEX(NHAP_LIEU!$M$5:$M$10004,$AJ6)="","",INDEX(NHAP_LIEU!$M$5:$M$10004,$AJ6))) | AB6: =IF($AJ6="","",IF(INDEX(NHAP_LIEU!$N$5:$N$10004,$AJ6)="","",INDEX(NHAP_LIEU!$N$5:$N$10004,$AJ6))) | AC6: =IF($AJ6="","",IF(INDEX(NHAP_LIEU!$O$5:$O$10004,$AJ6)="","",INDEX(NHAP_LIEU!$O$5:$O$10004,$AJ6))) | AD6: =IF($AJ6="","",IF(INDEX(NHAP_LIEU!$P$5:$P$10004,$AJ6)="","",INDEX(NHAP_LIEU!$P$5:$P$10004,$AJ6))) | AE6: =IF($AJ6="","",IF(INDEX(NHAP_LIEU!$Q$5:$Q$10004,$AJ6)="","",INDEX(NHAP_LIEU!$Q$5:$Q$10004,$AJ6))) | AF6: =IF($AJ6="","",IF(INDEX(NHAP_LIEU!$R$5:$R$10004,$AJ6)="","",INDEX(NHAP_LIEU!$R$5:$R$10004,$AJ6))) | AG6: =IF($AJ6="","",IF(INDEX(NHAP_LIEU!$S$5:$S$10004,$AJ6)="","",INDEX(NHAP_LIEU!$S$5:$S$10004,$AJ6))) | AH6: =IF($AJ6="","",IF(INDEX(NHAP_LIEU!$AC$5:$AC$10004,$AJ6)="","",INDEX(NHAP_LIEU!$AC$5:$AC$10004,$AJ6))) | AI6: =IF($AJ6="","",IF(INDEX(NHAP_LIEU!$AD$5:$AD$10004,$AJ6)="","",INDEX(NHAP_LIEU!$AD$5:$AD$10004,$AJ6))) | AJ6: =IF(OR(B6="",A6=""),"",IFERROR(MATCH(1,INDEX((NHAP_LIEU!$A$5:$A$10004=A6)*(NHAP_LIEU!$B$5:$B$10004=B6),0),0),"")) | AK6: =IF(O6="","",IFERROR(MATCH(1,INDEX((NHAP_LIEU!$A$5:$A$10004=O6)*(NHAP_LIEU!$B$5:$B$10004=B6),0),0),"")) | AL6: =IF(C6="","",SUMIFS(MUC_TIEU_THANG!$K$5:$K$2004,MUC_TIEU_THANG!$B$5:$B$2004,C6,MUC_TIEU_THANG!$A$5:$A$2004,">="&DATE(YEAR(A6),MONTH(A6),1),MUC_TIEU_THANG!$A$5:$A$2004,"<"&DATE(YEAR(A6),MONTH(A6)+1,1))) | AM6: =IF(A6="","",MAX(0,NETWORKDAYS.INTL(A6,EOMONTH(A6,0),11)-SUMPRODUCT((LICH_LAM_VIEC!$A$5:$A$1000>=A6)*(LICH_LAM_VIEC!$A$5:$A$1000<=EOMONTH(A6,0))*(LICH_LAM_VIEC!$B$5:$B$1000="Nghỉ")*(WEEKDAY(LICH_LAM_VIEC!$A$5:$A$1000)<>1))+SUMPRODUCT((LICH_LAM_VIEC!$A$5:$A$1000>=A6)*(LICH_LAM_VIEC!$A$5:$A$1000<=EOMONTH(A6,0))*(LICH_LAM_VIEC!$B$5:$B$1000="Làm bù")*(WEEKDAY(LICH_LAM_VIEC!$A$5:$A$1000)=1)))) | AN6: =IF(OR(C6="",N(Q6)=0,N(AM6)=0),"",ROUNDUP(MAX(0,Q6-SUMPRODUCT((NHAP_LIEU!$C$5:$C$10004=C6)*(NHAP_LIEU!$A$5:$A$10004>=DATE(YEAR(A6),MONTH(A6),1))*(NHAP_LIEU!$A$5:$A$10004<A6)*NHAP_LIEU!$H$5:$S$10004))/AM6,0)) | AO6: =IF($AJ6="","",IF(INDEX(NHAP_LIEU!$AG$5:$AG$10004,$AJ6)="","",INDEX(NHAP_LIEU!$AG$5:$AG$10004,$AJ6))) | AP6: =IF(OR(H6="",N(AO6)=0,N(L6)=0),"",H6/(AO6*L6)) | AQ6: =IF(OR(B6="",A6="",COUNTIFS(HANG_LOI!$A$5:$A$10004,A6,HANG_LOI!$C$5:$C$10004,B6)=0),"",SUMIFS(HANG_LOI!$F$5:$F$10004,HANG_LOI!$A$5:$A$10004,A6,HANG_LOI!$C$5:$C$10004,B6)) | AR6: =IF(OR(AQ6="",N(H6)=0),"",AQ6/H6) | AS6: =IF($AJ6="","",IF(INDEX(NHAP_LIEU!$AI$5:$AI$10004,$AJ6)="","",INDEX(NHAP_LIEU!$AI$5:$AI$10004,$AJ6))) | AT6: =IF($AJ6="","",IF(INDEX(NHAP_LIEU!$AJ$5:$AJ$10004,$AJ6)="","",INDEX(NHAP_LIEU!$AJ$5:$AJ$10004,$AJ6)))
A7: =IF(B7="","",$M$1) | B7: =IF(DANH_SACH_CHUYEN!B7="","",DANH_SACH_CHUYEN!B7) | C7: =IF($AJ7="","",IF(INDEX(NHAP_LIEU!$C$5:$C$10004,$AJ7)="","",INDEX(NHAP_LIEU!$C$5:$C$10004,$AJ7))) | D7: =IF($AJ7="","",IF(INDEX(NHAP_LIEU!$D$5:$D$10004,$AJ7)="","",INDEX(NHAP_LIEU!$D$5:$D$10004,$AJ7))) | E7: =IF(D7="","",IFERROR(INDEX(CAU_HINH_CA!$C$5:$C$50,MATCH(D7,CAU_HINH_CA!$A$5:$A$50,0)),"")) | F7: =IF($AJ7="","",IF(INDEX(NHAP_LIEU!$E$5:$E$10004,$AJ7)="","",INDEX(NHAP_LIEU!$E$5:$E$10004,$AJ7))) | G7: =IF(OR(E7="",F7=""),"",ROUND(E7*F7,0)) | H7: =IF(COUNT(V7:AG7)=0,"",SUM(V7:AG7)) | I7: =IF(OR(H7="",N(G7)=0),"",H7/G7) | J7: =IF(OR(H7="",G7=""),"",H7-G7) | K7: =IF(OR(H7="",G7=""),"",MAX(0,G7-H7)) | L7: =IF(AJ7="","",COUNT(V7:AG7)) | M7: =IF(OR(L7="",F7="",G7=""),"",MIN(G7,L7*F7)) | N7: =IF(OR(H7="",N(M7)=0),"",H7/M7) | O7: =IF(OR(B7="",A7=""),"",IF(SUMPRODUCT(MAX((NHAP_LIEU!$B$5:$B$10004=B7)*(NHAP_LIEU!$A$5:$A$10004<A7)*NHAP_LIEU!$A$5:$A$10004))=0,"",SUMPRODUCT(MAX((NHAP_LIEU!$B$5:$B$10004=B7)*(NHAP_LIEU!$A$5:$A$10004<A7)*NHAP_LIEU!$A$5:$A$10004)))) | P7: =IF(AK7="","",IF(COUNT(INDEX(NHAP_LIEU!$H$5:$S$10004,AK7,0))=0,0,MAX(0,IFERROR(ROUND(INDEX(CAU_HINH_CA!$C$5:$C$50,MATCH(INDEX(NHAP_LIEU!$D$5:$D$10004,AK7),CAU_HINH_CA!$A$5:$A$50,0))*INDEX(NHAP_LIEU!$E$5:$E$10004,AK7),0),0)-SUM(INDEX(NHAP_LIEU!$H$5:$S$10004,AK7,0))))) | Q7: =IF(C7="","",SUMIFS(MUC_TIEU_THANG!$C$5:$C$2004,MUC_TIEU_THANG!$B$5:$B$2004,C7,MUC_TIEU_THANG!$A$5:$A$2004,">="&DATE(YEAR(A7),MONTH(A7),1),MUC_TIEU_THANG!$A$5:$A$2004,"<"&DATE(YEAR(A7),MONTH(A7)+1,1))) | R7: =IF(C7="","",SUMPRODUCT((NHAP_LIEU!$C$5:$C$10004=C7)*(NHAP_LIEU!$A$5:$A$10004>=DATE(YEAR(A7),MONTH(A7),1))*(NHAP_LIEU!$A$5:$A$10004<=A7)*NHAP_LIEU!$H$5:$S$10004)) | S7: =IF(OR(R7="",N(Q7)=0),"",R7/Q7) | T7: =IF(OR(R7="",N(Q7)=0),"",MAX(0,Q7-R7)) | U7: =IF(B7="","",SUMPRODUCT((NHAP_LIEU!$B$5:$B$10004=B7)*(NHAP_LIEU!$A$5:$A$10004>=DATE(YEAR(A7),MONTH(A7),1))*(NHAP_LIEU!$A$5:$A$10004<=A7)*NHAP_LIEU!$H$5:$S$10004)) | V7: =IF($AJ7="","",IF(INDEX(NHAP_LIEU!$H$5:$H$10004,$AJ7)="","",INDEX(NHAP_LIEU!$H$5:$H$10004,$AJ7))) | W7: =IF($AJ7="","",IF(INDEX(NHAP_LIEU!$I$5:$I$10004,$AJ7)="","",INDEX(NHAP_LIEU!$I$5:$I$10004,$AJ7))) | X7: =IF($AJ7="","",IF(INDEX(NHAP_LIEU!$J$5:$J$10004,$AJ7)="","",INDEX(NHAP_LIEU!$J$5:$J$10004,$AJ7))) | Y7: =IF($AJ7="","",IF(INDEX(NHAP_LIEU!$K$5:$K$10004,$AJ7)="","",INDEX(NHAP_LIEU!$K$5:$K$10004,$AJ7))) | Z7: =IF($AJ7="","",IF(INDEX(NHAP_LIEU!$L$5:$L$10004,$AJ7)="","",INDEX(NHAP_LIEU!$L$5:$L$10004,$AJ7))) | AA7: =IF($AJ7="","",IF(INDEX(NHAP_LIEU!$M$5:$M$10004,$AJ7)="","",INDEX(NHAP_LIEU!$M$5:$M$10004,$AJ7))) | AB7: =IF($AJ7="","",IF(INDEX(NHAP_LIEU!$N$5:$N$10004,$AJ7)="","",INDEX(NHAP_LIEU!$N$5:$N$10004,$AJ7))) | AC7: =IF($AJ7="","",IF(INDEX(NHAP_LIEU!$O$5:$O$10004,$AJ7)="","",INDEX(NHAP_LIEU!$O$5:$O$10004,$AJ7))) | AD7: =IF($AJ7="","",IF(INDEX(NHAP_LIEU!$P$5:$P$10004,$AJ7)="","",INDEX(NHAP_LIEU!$P$5:$P$10004,$AJ7))) | AE7: =IF($AJ7="","",IF(INDEX(NHAP_LIEU!$Q$5:$Q$10004,$AJ7)="","",INDEX(NHAP_LIEU!$Q$5:$Q$10004,$AJ7))) | AF7: =IF($AJ7="","",IF(INDEX(NHAP_LIEU!$R$5:$R$10004,$AJ7)="","",INDEX(NHAP_LIEU!$R$5:$R$10004,$AJ7))) | AG7: =IF($AJ7="","",IF(INDEX(NHAP_LIEU!$S$5:$S$10004,$AJ7)="","",INDEX(NHAP_LIEU!$S$5:$S$10004,$AJ7))) | AH7: =IF($AJ7="","",IF(INDEX(NHAP_LIEU!$AC$5:$AC$10004,$AJ7)="","",INDEX(NHAP_LIEU!$AC$5:$AC$10004,$AJ7))) | AI7: =IF($AJ7="","",IF(INDEX(NHAP_LIEU!$AD$5:$AD$10004,$AJ7)="","",INDEX(NHAP_LIEU!$AD$5:$AD$10004,$AJ7))) | AJ7: =IF(OR(B7="",A7=""),"",IFERROR(MATCH(1,INDEX((NHAP_LIEU!$A$5:$A$10004=A7)*(NHAP_LIEU!$B$5:$B$10004=B7),0),0),"")) | AK7: =IF(O7="","",IFERROR(MATCH(1,INDEX((NHAP_LIEU!$A$5:$A$10004=O7)*(NHAP_LIEU!$B$5:$B$10004=B7),0),0),"")) | AL7: =IF(C7="","",SUMIFS(MUC_TIEU_THANG!$K$5:$K$2004,MUC_TIEU_THANG!$B$5:$B$2004,C7,MUC_TIEU_THANG!$A$5:$A$2004,">="&DATE(YEAR(A7),MONTH(A7),1),MUC_TIEU_THANG!$A$5:$A$2004,"<"&DATE(YEAR(A7),MONTH(A7)+1,1))) | AM7: =IF(A7="","",MAX(0,NETWORKDAYS.INTL(A7,EOMONTH(A7,0),11)-SUMPRODUCT((LICH_LAM_VIEC!$A$5:$A$1000>=A7)*(LICH_LAM_VIEC!$A$5:$A$1000<=EOMONTH(A7,0))*(LICH_LAM_VIEC!$B$5:$B$1000="Nghỉ")*(WEEKDAY(LICH_LAM_VIEC!$A$5:$A$1000)<>1))+SUMPRODUCT((LICH_LAM_VIEC!$A$5:$A$1000>=A7)*(LICH_LAM_VIEC!$A$5:$A$1000<=EOMONTH(A7,0))*(LICH_LAM_VIEC!$B$5:$B$1000="Làm bù")*(WEEKDAY(LICH_LAM_VIEC!$A$5:$A$1000)=1)))) | AN7: =IF(OR(C7="",N(Q7)=0,N(AM7)=0),"",ROUNDUP(MAX(0,Q7-SUMPRODUCT((NHAP_LIEU!$C$5:$C$10004=C7)*(NHAP_LIEU!$A$5:$A$10004>=DATE(YEAR(A7),MONTH(A7),1))*(NHAP_LIEU!$A$5:$A$10004<A7)*NHAP_LIEU!$H$5:$S$10004))/AM7,0)) | AO7: =IF($AJ7="","",IF(INDEX(NHAP_LIEU!$AG$5:$AG$10004,$AJ7)="","",INDEX(NHAP_LIEU!$AG$5:$AG$10004,$AJ7))) | AP7: =IF(OR(H7="",N(AO7)=0,N(L7)=0),"",H7/(AO7*L7)) | AQ7: =IF(OR(B7="",A7="",COUNTIFS(HANG_LOI!$A$5:$A$10004,A7,HANG_LOI!$C$5:$C$10004,B7)=0),"",SUMIFS(HANG_LOI!$F$5:$F$10004,HANG_LOI!$A$5:$A$10004,A7,HANG_LOI!$C$5:$C$10004,B7)) | AR7: =IF(OR(AQ7="",N(H7)=0),"",AQ7/H7) | AS7: =IF($AJ7="","",IF(INDEX(NHAP_LIEU!$AI$5:$AI$10004,$AJ7)="","",INDEX(NHAP_LIEU!$AI$5:$AI$10004,$AJ7))) | AT7: =IF($AJ7="","",IF(INDEX(NHAP_LIEU!$AJ$5:$AJ$10004,$AJ7)="","",INDEX(NHAP_LIEU!$AJ$5:$AJ$10004,$AJ7)))
A8: =IF(B8="","",$M$1) | B8: =IF(DANH_SACH_CHUYEN!B8="","",DANH_SACH_CHUYEN!B8) | C8: =IF($AJ8="","",IF(INDEX(NHAP_LIEU!$C$5:$C$10004,$AJ8)="","",INDEX(NHAP_LIEU!$C$5:$C$10004,$AJ8))) | D8: =IF($AJ8="","",IF(INDEX(NHAP_LIEU!$D$5:$D$10004,$AJ8)="","",INDEX(NHAP_LIEU!$D$5:$D$10004,$AJ8))) | E8: =IF(D8="","",IFERROR(INDEX(CAU_HINH_CA!$C$5:$C$50,MATCH(D8,CAU_HINH_CA!$A$5:$A$50,0)),"")) | F8: =IF($AJ8="","",IF(INDEX(NHAP_LIEU!$E$5:$E$10004,$AJ8)="","",INDEX(NHAP_LIEU!$E$5:$E$10004,$AJ8))) | G8: =IF(OR(E8="",F8=""),"",ROUND(E8*F8,0)) | H8: =IF(COUNT(V8:AG8)=0,"",SUM(V8:AG8)) | I8: =IF(OR(H8="",N(G8)=0),"",H8/G8) | J8: =IF(OR(H8="",G8=""),"",H8-G8) | K8: =IF(OR(H8="",G8=""),"",MAX(0,G8-H8)) | L8: =IF(AJ8="","",COUNT(V8:AG8)) | M8: =IF(OR(L8="",F8="",G8=""),"",MIN(G8,L8*F8)) | N8: =IF(OR(H8="",N(M8)=0),"",H8/M8) | O8: =IF(OR(B8="",A8=""),"",IF(SUMPRODUCT(MAX((NHAP_LIEU!$B$5:$B$10004=B8)*(NHAP_LIEU!$A$5:$A$10004<A8)*NHAP_LIEU!$A$5:$A$10004))=0,"",SUMPRODUCT(MAX((NHAP_LIEU!$B$5:$B$10004=B8)*(NHAP_LIEU!$A$5:$A$10004<A8)*NHAP_LIEU!$A$5:$A$10004)))) | P8: =IF(AK8="","",IF(COUNT(INDEX(NHAP_LIEU!$H$5:$S$10004,AK8,0))=0,0,MAX(0,IFERROR(ROUND(INDEX(CAU_HINH_CA!$C$5:$C$50,MATCH(INDEX(NHAP_LIEU!$D$5:$D$10004,AK8),CAU_HINH_CA!$A$5:$A$50,0))*INDEX(NHAP_LIEU!$E$5:$E$10004,AK8),0),0)-SUM(INDEX(NHAP_LIEU!$H$5:$S$10004,AK8,0))))) | Q8: =IF(C8="","",SUMIFS(MUC_TIEU_THANG!$C$5:$C$2004,MUC_TIEU_THANG!$B$5:$B$2004,C8,MUC_TIEU_THANG!$A$5:$A$2004,">="&DATE(YEAR(A8),MONTH(A8),1),MUC_TIEU_THANG!$A$5:$A$2004,"<"&DATE(YEAR(A8),MONTH(A8)+1,1))) | R8: =IF(C8="","",SUMPRODUCT((NHAP_LIEU!$C$5:$C$10004=C8)*(NHAP_LIEU!$A$5:$A$10004>=DATE(YEAR(A8),MONTH(A8),1))*(NHAP_LIEU!$A$5:$A$10004<=A8)*NHAP_LIEU!$H$5:$S$10004)) | S8: =IF(OR(R8="",N(Q8)=0),"",R8/Q8) | T8: =IF(OR(R8="",N(Q8)=0),"",MAX(0,Q8-R8)) | U8: =IF(B8="","",SUMPRODUCT((NHAP_LIEU!$B$5:$B$10004=B8)*(NHAP_LIEU!$A$5:$A$10004>=DATE(YEAR(A8),MONTH(A8),1))*(NHAP_LIEU!$A$5:$A$10004<=A8)*NHAP_LIEU!$H$5:$S$10004)) | V8: =IF($AJ8="","",IF(INDEX(NHAP_LIEU!$H$5:$H$10004,$AJ8)="","",INDEX(NHAP_LIEU!$H$5:$H$10004,$AJ8))) | W8: =IF($AJ8="","",IF(INDEX(NHAP_LIEU!$I$5:$I$10004,$AJ8)="","",INDEX(NHAP_LIEU!$I$5:$I$10004,$AJ8))) | X8: =IF($AJ8="","",IF(INDEX(NHAP_LIEU!$J$5:$J$10004,$AJ8)="","",INDEX(NHAP_LIEU!$J$5:$J$10004,$AJ8))) | Y8: =IF($AJ8="","",IF(INDEX(NHAP_LIEU!$K$5:$K$10004,$AJ8)="","",INDEX(NHAP_LIEU!$K$5:$K$10004,$AJ8))) | Z8: =IF($AJ8="","",IF(INDEX(NHAP_LIEU!$L$5:$L$10004,$AJ8)="","",INDEX(NHAP_LIEU!$L$5:$L$10004,$AJ8))) | AA8: =IF($AJ8="","",IF(INDEX(NHAP_LIEU!$M$5:$M$10004,$AJ8)="","",INDEX(NHAP_LIEU!$M$5:$M$10004,$AJ8))) | AB8: =IF($AJ8="","",IF(INDEX(NHAP_LIEU!$N$5:$N$10004,$AJ8)="","",INDEX(NHAP_LIEU!$N$5:$N$10004,$AJ8))) | AC8: =IF($AJ8="","",IF(INDEX(NHAP_LIEU!$O$5:$O$10004,$AJ8)="","",INDEX(NHAP_LIEU!$O$5:$O$10004,$AJ8))) | AD8: =IF($AJ8="","",IF(INDEX(NHAP_LIEU!$P$5:$P$10004,$AJ8)="","",INDEX(NHAP_LIEU!$P$5:$P$10004,$AJ8))) | AE8: =IF($AJ8="","",IF(INDEX(NHAP_LIEU!$Q$5:$Q$10004,$AJ8)="","",INDEX(NHAP_LIEU!$Q$5:$Q$10004,$AJ8))) | AF8: =IF($AJ8="","",IF(INDEX(NHAP_LIEU!$R$5:$R$10004,$AJ8)="","",INDEX(NHAP_LIEU!$R$5:$R$10004,$AJ8))) | AG8: =IF($AJ8="","",IF(INDEX(NHAP_LIEU!$S$5:$S$10004,$AJ8)="","",INDEX(NHAP_LIEU!$S$5:$S$10004,$AJ8))) | AH8: =IF($AJ8="","",IF(INDEX(NHAP_LIEU!$AC$5:$AC$10004,$AJ8)="","",INDEX(NHAP_LIEU!$AC$5:$AC$10004,$AJ8))) | AI8: =IF($AJ8="","",IF(INDEX(NHAP_LIEU!$AD$5:$AD$10004,$AJ8)="","",INDEX(NHAP_LIEU!$AD$5:$AD$10004,$AJ8))) | AJ8: =IF(OR(B8="",A8=""),"",IFERROR(MATCH(1,INDEX((NHAP_LIEU!$A$5:$A$10004=A8)*(NHAP_LIEU!$B$5:$B$10004=B8),0),0),"")) | AK8: =IF(O8="","",IFERROR(MATCH(1,INDEX((NHAP_LIEU!$A$5:$A$10004=O8)*(NHAP_LIEU!$B$5:$B$10004=B8),0),0),"")) | AL8: =IF(C8="","",SUMIFS(MUC_TIEU_THANG!$K$5:$K$2004,MUC_TIEU_THANG!$B$5:$B$2004,C8,MUC_TIEU_THANG!$A$5:$A$2004,">="&DATE(YEAR(A8),MONTH(A8),1),MUC_TIEU_THANG!$A$5:$A$2004,"<"&DATE(YEAR(A8),MONTH(A8)+1,1))) | AM8: =IF(A8="","",MAX(0,NETWORKDAYS.INTL(A8,EOMONTH(A8,0),11)-SUMPRODUCT((LICH_LAM_VIEC!$A$5:$A$1000>=A8)*(LICH_LAM_VIEC!$A$5:$A$1000<=EOMONTH(A8,0))*(LICH_LAM_VIEC!$B$5:$B$1000="Nghỉ")*(WEEKDAY(LICH_LAM_VIEC!$A$5:$A$1000)<>1))+SUMPRODUCT((LICH_LAM_VIEC!$A$5:$A$1000>=A8)*(LICH_LAM_VIEC!$A$5:$A$1000<=EOMONTH(A8,0))*(LICH_LAM_VIEC!$B$5:$B$1000="Làm bù")*(WEEKDAY(LICH_LAM_VIEC!$A$5:$A$1000)=1)))) | AN8: =IF(OR(C8="",N(Q8)=0,N(AM8)=0),"",ROUNDUP(MAX(0,Q8-SUMPRODUCT((NHAP_LIEU!$C$5:$C$10004=C8)*(NHAP_LIEU!$A$5:$A$10004>=DATE(YEAR(A8),MONTH(A8),1))*(NHAP_LIEU!$A$5:$A$10004<A8)*NHAP_LIEU!$H$5:$S$10004))/AM8,0)) | AO8: =IF($AJ8="","",IF(INDEX(NHAP_LIEU!$AG$5:$AG$10004,$AJ8)="","",INDEX(NHAP_LIEU!$AG$5:$AG$10004,$AJ8))) | AP8: =IF(OR(H8="",N(AO8)=0,N(L8)=0),"",H8/(AO8*L8)) | AQ8: =IF(OR(B8="",A8="",COUNTIFS(HANG_LOI!$A$5:$A$10004,A8,HANG_LOI!$C$5:$C$10004,B8)=0),"",SUMIFS(HANG_LOI!$F$5:$F$10004,HANG_LOI!$A$5:$A$10004,A8,HANG_LOI!$C$5:$C$10004,B8)) | AR8: =IF(OR(AQ8="",N(H8)=0),"",AQ8/H8) | AS8: =IF($AJ8="","",IF(INDEX(NHAP_LIEU!$AI$5:$AI$10004,$AJ8)="","",INDEX(NHAP_LIEU!$AI$5:$AI$10004,$AJ8))) | AT8: =IF($AJ8="","",IF(INDEX(NHAP_LIEU!$AJ$5:$AJ$10004,$AJ8)="","",INDEX(NHAP_LIEU!$AJ$5:$AJ$10004,$AJ8)))
A9: =IF(B9="","",$M$1) | B9: =IF(DANH_SACH_CHUYEN!B9="","",DANH_SACH_CHUYEN!B9) | C9: =IF($AJ9="","",IF(INDEX(NHAP_LIEU!$C$5:$C$10004,$AJ9)="","",INDEX(NHAP_LIEU!$C$5:$C$10004,$AJ9))) | D9: =IF($AJ9="","",IF(INDEX(NHAP_LIEU!$D$5:$D$10004,$AJ9)="","",INDEX(NHAP_LIEU!$D$5:$D$10004,$AJ9))) | E9: =IF(D9="","",IFERROR(INDEX(CAU_HINH_CA!$C$5:$C$50,MATCH(D9,CAU_HINH_CA!$A$5:$A$50,0)),"")) | F9: =IF($AJ9="","",IF(INDEX(NHAP_LIEU!$E$5:$E$10004,$AJ9)="","",INDEX(NHAP_LIEU!$E$5:$E$10004,$AJ9))) | G9: =IF(OR(E9="",F9=""),"",ROUND(E9*F9,0)) | H9: =IF(COUNT(V9:AG9)=0,"",SUM(V9:AG9)) | I9: =IF(OR(H9="",N(G9)=0),"",H9/G9) | J9: =IF(OR(H9="",G9=""),"",H9-G9) | K9: =IF(OR(H9="",G9=""),"",MAX(0,G9-H9)) | L9: =IF(AJ9="","",COUNT(V9:AG9)) | M9: =IF(OR(L9="",F9="",G9=""),"",MIN(G9,L9*F9)) | N9: =IF(OR(H9="",N(M9)=0),"",H9/M9) | O9: =IF(OR(B9="",A9=""),"",IF(SUMPRODUCT(MAX((NHAP_LIEU!$B$5:$B$10004=B9)*(NHAP_LIEU!$A$5:$A$10004<A9)*NHAP_LIEU!$A$5:$A$10004))=0,"",SUMPRODUCT(MAX((NHAP_LIEU!$B$5:$B$10004=B9)*(NHAP_LIEU!$A$5:$A$10004<A9)*NHAP_LIEU!$A$5:$A$10004)))) | P9: =IF(AK9="","",IF(COUNT(INDEX(NHAP_LIEU!$H$5:$S$10004,AK9,0))=0,0,MAX(0,IFERROR(ROUND(INDEX(CAU_HINH_CA!$C$5:$C$50,MATCH(INDEX(NHAP_LIEU!$D$5:$D$10004,AK9),CAU_HINH_CA!$A$5:$A$50,0))*INDEX(NHAP_LIEU!$E$5:$E$10004,AK9),0),0)-SUM(INDEX(NHAP_LIEU!$H$5:$S$10004,AK9,0))))) | Q9: =IF(C9="","",SUMIFS(MUC_TIEU_THANG!$C$5:$C$2004,MUC_TIEU_THANG!$B$5:$B$2004,C9,MUC_TIEU_THANG!$A$5:$A$2004,">="&DATE(YEAR(A9),MONTH(A9),1),MUC_TIEU_THANG!$A$5:$A$2004,"<"&DATE(YEAR(A9),MONTH(A9)+1,1))) | R9: =IF(C9="","",SUMPRODUCT((NHAP_LIEU!$C$5:$C$10004=C9)*(NHAP_LIEU!$A$5:$A$10004>=DATE(YEAR(A9),MONTH(A9),1))*(NHAP_LIEU!$A$5:$A$10004<=A9)*NHAP_LIEU!$H$5:$S$10004)) | S9: =IF(OR(R9="",N(Q9)=0),"",R9/Q9) | T9: =IF(OR(R9="",N(Q9)=0),"",MAX(0,Q9-R9)) | U9: =IF(B9="","",SUMPRODUCT((NHAP_LIEU!$B$5:$B$10004=B9)*(NHAP_LIEU!$A$5:$A$10004>=DATE(YEAR(A9),MONTH(A9),1))*(NHAP_LIEU!$A$5:$A$10004<=A9)*NHAP_LIEU!$H$5:$S$10004)) | V9: =IF($AJ9="","",IF(INDEX(NHAP_LIEU!$H$5:$H$10004,$AJ9)="","",INDEX(NHAP_LIEU!$H$5:$H$10004,$AJ9))) | W9: =IF($AJ9="","",IF(INDEX(NHAP_LIEU!$I$5:$I$10004,$AJ9)="","",INDEX(NHAP_LIEU!$I$5:$I$10004,$AJ9))) | X9: =IF($AJ9="","",IF(INDEX(NHAP_LIEU!$J$5:$J$10004,$AJ9)="","",INDEX(NHAP_LIEU!$J$5:$J$10004,$AJ9))) | Y9: =IF($AJ9="","",IF(INDEX(NHAP_LIEU!$K$5:$K$10004,$AJ9)="","",INDEX(NHAP_LIEU!$K$5:$K$10004,$AJ9))) | Z9: =IF($AJ9="","",IF(INDEX(NHAP_LIEU!$L$5:$L$10004,$AJ9)="","",INDEX(NHAP_LIEU!$L$5:$L$10004,$AJ9))) | AA9: =IF($AJ9="","",IF(INDEX(NHAP_LIEU!$M$5:$M$10004,$AJ9)="","",INDEX(NHAP_LIEU!$M$5:$M$10004,$AJ9))) | AB9: =IF($AJ9="","",IF(INDEX(NHAP_LIEU!$N$5:$N$10004,$AJ9)="","",INDEX(NHAP_LIEU!$N$5:$N$10004,$AJ9))) | AC9: =IF($AJ9="","",IF(INDEX(NHAP_LIEU!$O$5:$O$10004,$AJ9)="","",INDEX(NHAP_LIEU!$O$5:$O$10004,$AJ9))) | AD9: =IF($AJ9="","",IF(INDEX(NHAP_LIEU!$P$5:$P$10004,$AJ9)="","",INDEX(NHAP_LIEU!$P$5:$P$10004,$AJ9))) | AE9: =IF($AJ9="","",IF(INDEX(NHAP_LIEU!$Q$5:$Q$10004,$AJ9)="","",INDEX(NHAP_LIEU!$Q$5:$Q$10004,$AJ9))) | AF9: =IF($AJ9="","",IF(INDEX(NHAP_LIEU!$R$5:$R$10004,$AJ9)="","",INDEX(NHAP_LIEU!$R$5:$R$10004,$AJ9))) | AG9: =IF($AJ9="","",IF(INDEX(NHAP_LIEU!$S$5:$S$10004,$AJ9)="","",INDEX(NHAP_LIEU!$S$5:$S$10004,$AJ9))) | AH9: =IF($AJ9="","",IF(INDEX(NHAP_LIEU!$AC$5:$AC$10004,$AJ9)="","",INDEX(NHAP_LIEU!$AC$5:$AC$10004,$AJ9))) | AI9: =IF($AJ9="","",IF(INDEX(NHAP_LIEU!$AD$5:$AD$10004,$AJ9)="","",INDEX(NHAP_LIEU!$AD$5:$AD$10004,$AJ9))) | AJ9: =IF(OR(B9="",A9=""),"",IFERROR(MATCH(1,INDEX((NHAP_LIEU!$A$5:$A$10004=A9)*(NHAP_LIEU!$B$5:$B$10004=B9),0),0),"")) | AK9: =IF(O9="","",IFERROR(MATCH(1,INDEX((NHAP_LIEU!$A$5:$A$10004=O9)*(NHAP_LIEU!$B$5:$B$10004=B9),0),0),"")) | AL9: =IF(C9="","",SUMIFS(MUC_TIEU_THANG!$K$5:$K$2004,MUC_TIEU_THANG!$B$5:$B$2004,C9,MUC_TIEU_THANG!$A$5:$A$2004,">="&DATE(YEAR(A9),MONTH(A9),1),MUC_TIEU_THANG!$A$5:$A$2004,"<"&DATE(YEAR(A9),MONTH(A9)+1,1))) | AM9: =IF(A9="","",MAX(0,NETWORKDAYS.INTL(A9,EOMONTH(A9,0),11)-SUMPRODUCT((LICH_LAM_VIEC!$A$5:$A$1000>=A9)*(LICH_LAM_VIEC!$A$5:$A$1000<=EOMONTH(A9,0))*(LICH_LAM_VIEC!$B$5:$B$1000="Nghỉ")*(WEEKDAY(LICH_LAM_VIEC!$A$5:$A$1000)<>1))+SUMPRODUCT((LICH_LAM_VIEC!$A$5:$A$1000>=A9)*(LICH_LAM_VIEC!$A$5:$A$1000<=EOMONTH(A9,0))*(LICH_LAM_VIEC!$B$5:$B$1000="Làm bù")*(WEEKDAY(LICH_LAM_VIEC!$A$5:$A$1000)=1)))) | AN9: =IF(OR(C9="",N(Q9)=0,N(AM9)=0),"",ROUNDUP(MAX(0,Q9-SUMPRODUCT((NHAP_LIEU!$C$5:$C$10004=C9)*(NHAP_LIEU!$A$5:$A$10004>=DATE(YEAR(A9),MONTH(A9),1))*(NHAP_LIEU!$A$5:$A$10004<A9)*NHAP_LIEU!$H$5:$S$10004))/AM9,0)) | AO9: =IF($AJ9="","",IF(INDEX(NHAP_LIEU!$AG$5:$AG$10004,$AJ9)="","",INDEX(NHAP_LIEU!$AG$5:$AG$10004,$AJ9))) | AP9: =IF(OR(H9="",N(AO9)=0,N(L9)=0),"",H9/(AO9*L9)) | AQ9: =IF(OR(B9="",A9="",COUNTIFS(HANG_LOI!$A$5:$A$10004,A9,HANG_LOI!$C$5:$C$10004,B9)=0),"",SUMIFS(HANG_LOI!$F$5:$F$10004,HANG_LOI!$A$5:$A$10004,A9,HANG_LOI!$C$5:$C$10004,B9)) | AR9: =IF(OR(AQ9="",N(H9)=0),"",AQ9/H9) | AS9: =IF($AJ9="","",IF(INDEX(NHAP_LIEU!$AI$5:$AI$10004,$AJ9)="","",INDEX(NHAP_LIEU!$AI$5:$AI$10004,$AJ9))) | AT9: =IF($AJ9="","",IF(INDEX(NHAP_LIEU!$AJ$5:$AJ$10004,$AJ9)="","",INDEX(NHAP_LIEU!$AJ$5:$AJ$10004,$AJ9)))
A10: =IF(B10="","",$M$1) | B10: =IF(DANH_SACH_CHUYEN!B10="","",DANH_SACH_CHUYEN!B10) | C10: =IF($AJ10="","",IF(INDEX(NHAP_LIEU!$C$5:$C$10004,$AJ10)="","",INDEX(NHAP_LIEU!$C$5:$C$10004,$AJ10))) | D10: =IF($AJ10="","",IF(INDEX(NHAP_LIEU!$D$5:$D$10004,$AJ10)="","",INDEX(NHAP_LIEU!$D$5:$D$10004,$AJ10))) | E10: =IF(D10="","",IFERROR(INDEX(CAU_HINH_CA!$C$5:$C$50,MATCH(D10,CAU_HINH_CA!$A$5:$A$50,0)),"")) | F10: =IF($AJ10="","",IF(INDEX(NHAP_LIEU!$E$5:$E$10004,$AJ10)="","",INDEX(NHAP_LIEU!$E$5:$E$10004,$AJ10))) | G10: =IF(OR(E10="",F10=""),"",ROUND(E10*F10,0)) | H10: =IF(COUNT(V10:AG10)=0,"",SUM(V10:AG10)) | I10: =IF(OR(H10="",N(G10)=0),"",H10/G10) | J10: =IF(OR(H10="",G10=""),"",H10-G10) | K10: =IF(OR(H10="",G10=""),"",MAX(0,G10-H10)) | L10: =IF(AJ10="","",COUNT(V10:AG10)) | M10: =IF(OR(L10="",F10="",G10=""),"",MIN(G10,L10*F10)) | N10: =IF(OR(H10="",N(M10)=0),"",H10/M10) | O10: =IF(OR(B10="",A10=""),"",IF(SUMPRODUCT(MAX((NHAP_LIEU!$B$5:$B$10004=B10)*(NHAP_LIEU!$A$5:$A$10004<A10)*NHAP_LIEU!$A$5:$A$10004))=0,"",SUMPRODUCT(MAX((NHAP_LIEU!$B$5:$B$10004=B10)*(NHAP_LIEU!$A$5:$A$10004<A10)*NHAP_LIEU!$A$5:$A$10004)))) | P10: =IF(AK10="","",IF(COUNT(INDEX(NHAP_LIEU!$H$5:$S$10004,AK10,0))=0,0,MAX(0,IFERROR(ROUND(INDEX(CAU_HINH_CA!$C$5:$C$50,MATCH(INDEX(NHAP_LIEU!$D$5:$D$10004,AK10),CAU_HINH_CA!$A$5:$A$50,0))*INDEX(NHAP_LIEU!$E$5:$E$10004,AK10),0),0)-SUM(INDEX(NHAP_LIEU!$H$5:$S$10004,AK10,0))))) | Q10: =IF(C10="","",SUMIFS(MUC_TIEU_THANG!$C$5:$C$2004,MUC_TIEU_THANG!$B$5:$B$2004,C10,MUC_TIEU_THANG!$A$5:$A$2004,">="&DATE(YEAR(A10),MONTH(A10),1),MUC_TIEU_THANG!$A$5:$A$2004,"<"&DATE(YEAR(A10),MONTH(A10)+1,1))) | R10: =IF(C10="","",SUMPRODUCT((NHAP_LIEU!$C$5:$C$10004=C10)*(NHAP_LIEU!$A$5:$A$10004>=DATE(YEAR(A10),MONTH(A10),1))*(NHAP_LIEU!$A$5:$A$10004<=A10)*NHAP_LIEU!$H$5:$S$10004)) | S10: =IF(OR(R10="",N(Q10)=0),"",R10/Q10) | T10: =IF(OR(R10="",N(Q10)=0),"",MAX(0,Q10-R10)) | U10: =IF(B10="","",SUMPRODUCT((NHAP_LIEU!$B$5:$B$10004=B10)*(NHAP_LIEU!$A$5:$A$10004>=DATE(YEAR(A10),MONTH(A10),1))*(NHAP_LIEU!$A$5:$A$10004<=A10)*NHAP_LIEU!$H$5:$S$10004)) | V10: =IF($AJ10="","",IF(INDEX(NHAP_LIEU!$H$5:$H$10004,$AJ10)="","",INDEX(NHAP_LIEU!$H$5:$H$10004,$AJ10))) | W10: =IF($AJ10="","",IF(INDEX(NHAP_LIEU!$I$5:$I$10004,$AJ10)="","",INDEX(NHAP_LIEU!$I$5:$I$10004,$AJ10))) | X10: =IF($AJ10="","",IF(INDEX(NHAP_LIEU!$J$5:$J$10004,$AJ10)="","",INDEX(NHAP_LIEU!$J$5:$J$10004,$AJ10))) | Y10: =IF($AJ10="","",IF(INDEX(NHAP_LIEU!$K$5:$K$10004,$AJ10)="","",INDEX(NHAP_LIEU!$K$5:$K$10004,$AJ10))) | Z10: =IF($AJ10="","",IF(INDEX(NHAP_LIEU!$L$5:$L$10004,$AJ10)="","",INDEX(NHAP_LIEU!$L$5:$L$10004,$AJ10))) | AA10: =IF($AJ10="","",IF(INDEX(NHAP_LIEU!$M$5:$M$10004,$AJ10)="","",INDEX(NHAP_LIEU!$M$5:$M$10004,$AJ10))) | AB10: =IF($AJ10="","",IF(INDEX(NHAP_LIEU!$N$5:$N$10004,$AJ10)="","",INDEX(NHAP_LIEU!$N$5:$N$10004,$AJ10))) | AC10: =IF($AJ10="","",IF(INDEX(NHAP_LIEU!$O$5:$O$10004,$AJ10)="","",INDEX(NHAP_LIEU!$O$5:$O$10004,$AJ10))) | AD10: =IF($AJ10="","",IF(INDEX(NHAP_LIEU!$P$5:$P$10004,$AJ10)="","",INDEX(NHAP_LIEU!$P$5:$P$10004,$AJ10))) | AE10: =IF($AJ10="","",IF(INDEX(NHAP_LIEU!$Q$5:$Q$10004,$AJ10)="","",INDEX(NHAP_LIEU!$Q$5:$Q$10004,$AJ10))) | AF10: =IF($AJ10="","",IF(INDEX(NHAP_LIEU!$R$5:$R$10004,$AJ10)="","",INDEX(NHAP_LIEU!$R$5:$R$10004,$AJ10))) | AG10: =IF($AJ10="","",IF(INDEX(NHAP_LIEU!$S$5:$S$10004,$AJ10)="","",INDEX(NHAP_LIEU!$S$5:$S$10004,$AJ10))) | AH10: =IF($AJ10="","",IF(INDEX(NHAP_LIEU!$AC$5:$AC$10004,$AJ10)="","",INDEX(NHAP_LIEU!$AC$5:$AC$10004,$AJ10))) | AI10: =IF($AJ10="","",IF(INDEX(NHAP_LIEU!$AD$5:$AD$10004,$AJ10)="","",INDEX(NHAP_LIEU!$AD$5:$AD$10004,$AJ10))) | AJ10: =IF(OR(B10="",A10=""),"",IFERROR(MATCH(1,INDEX((NHAP_LIEU!$A$5:$A$10004=A10)*(NHAP_LIEU!$B$5:$B$10004=B10),0),0),"")) | AK10: =IF(O10="","",IFERROR(MATCH(1,INDEX((NHAP_LIEU!$A$5:$A$10004=O10)*(NHAP_LIEU!$B$5:$B$10004=B10),0),0),"")) | AL10: =IF(C10="","",SUMIFS(MUC_TIEU_THANG!$K$5:$K$2004,MUC_TIEU_THANG!$B$5:$B$2004,C10,MUC_TIEU_THANG!$A$5:$A$2004,">="&DATE(YEAR(A10),MONTH(A10),1),MUC_TIEU_THANG!$A$5:$A$2004,"<"&DATE(YEAR(A10),MONTH(A10)+1,1))) | AM10: =IF(A10="","",MAX(0,NETWORKDAYS.INTL(A10,EOMONTH(A10,0),11)-SUMPRODUCT((LICH_LAM_VIEC!$A$5:$A$1000>=A10)*(LICH_LAM_VIEC!$A$5:$A$1000<=EOMONTH(A10,0))*(LICH_LAM_VIEC!$B$5:$B$1000="Nghỉ")*(WEEKDAY(LICH_LAM_VIEC!$A$5:$A$1000)<>1))+SUMPRODUCT((LICH_LAM_VIEC!$A$5:$A$1000>=A10)*(LICH_LAM_VIEC!$A$5:$A$1000<=EOMONTH(A10,0))*(LICH_LAM_VIEC!$B$5:$B$1000="Làm bù")*(WEEKDAY(LICH_LAM_VIEC!$A$5:$A$1000)=1)))) | AN10: =IF(OR(C10="",N(Q10)=0,N(AM10)=0),"",ROUNDUP(MAX(0,Q10-SUMPRODUCT((NHAP_LIEU!$C$5:$C$10004=C10)*(NHAP_LIEU!$A$5:$A$10004>=DATE(YEAR(A10),MONTH(A10),1))*(NHAP_LIEU!$A$5:$A$10004<A10)*NHAP_LIEU!$H$5:$S$10004))/AM10,0)) | AO10: =IF($AJ10="","",IF(INDEX(NHAP_LIEU!$AG$5:$AG$10004,$AJ10)="","",INDEX(NHAP_LIEU!$AG$5:$AG$10004,$AJ10))) | AP10: =IF(OR(H10="",N(AO10)=0,N(L10)=0),"",H10/(AO10*L10)) | AQ10: =IF(OR(B10="",A10="",COUNTIFS(HANG_LOI!$A$5:$A$10004,A10,HANG_LOI!$C$5:$C$10004,B10)=0),"",SUMIFS(HANG_LOI!$F$5:$F$10004,HANG_LOI!$A$5:$A$10004,A10,HANG_LOI!$C$5:$C$10004,B10)) | AR10: =IF(OR(AQ10="",N(H10)=0),"",AQ10/H10) | AS10: =IF($AJ10="","",IF(INDEX(NHAP_LIEU!$AI$5:$AI$10004,$AJ10)="","",INDEX(NHAP_LIEU!$AI$5:$AI$10004,$AJ10))) | AT10: =IF($AJ10="","",IF(INDEX(NHAP_LIEU!$AJ$5:$AJ$10004,$AJ10)="","",INDEX(NHAP_LIEU!$AJ$5:$AJ$10004,$AJ10)))
A12: =$M$1 | B12: TỔNG CỘNG | G12: =IF(COUNT(G5:G10)=0,"",SUM(G5:G10)) | H12: =IF(COUNT(H5:H10)=0,"",SUM(H5:H10)) | I12: =IF(OR(H12="",N(G12)=0),"",H12/G12) | J12: =IF(COUNT(J5:J10)=0,"",SUM(J5:J10)) | K12: =IF(COUNT(K5:K10)=0,"",SUM(K5:K10)) | M12: =IF(COUNT(M5:M10)=0,"",SUM(M5:M10)) | N12: =IF(OR(H12="",N(M12)=0),"",H12/M12) | P12: =IF(COUNT(P5:P10)=0,"",SUM(P5:P10)) | U12: =IF(COUNT(U5:U10)=0,"",SUM(U5:U10)) | AO12: =IF(COUNT(AO5:AO10)=0,"",SUM(AO5:AO10)) | AP12: =IF(SUMPRODUCT(AO5:AO10,L5:L10)=0,"",H12/SUMPRODUCT(AO5:AO10,L5:L10)) | AQ12: =IF(COUNT(AQ5:AQ10)=0,"",SUM(AQ5:AQ10)) | AR12: =IF(OR(AQ12="",N(H12)=0),"",AQ12/H12) | AT12: =IF(COUNT(AT5:AT10)=0,"",SUM(AT5:AT10))

Sheet BAO_CAO_THANG
A1: 月度報告 / BÁO CÁO THÁNG THEO CHUYỀN
A2: CHỌN THÁNG (trống = tháng mới nhất): | H2: ĐANG XEM: | J2: =IF(F2<>"",DATE(YEAR(F2),MONTH(F2),1),DATE(YEAR(MAX(NHAP_LIEU!$A$5:$A$10004)),MONTH(MAX(NHAP_LIEU!$A$5:$A$10004)),1))
A4: 1. SẢN LƯỢNG THỰC TẾ THEO NGÀY
A5: CHUYỀN | B5: =IF(MONTH($J$2+1-1)=MONTH($J$2),1,"") | C5: =IF(MONTH($J$2+2-1)=MONTH($J$2),2,"") | D5: =IF(MONTH($J$2+3-1)=MONTH($J$2),3,"") | E5: =IF(MONTH($J$2+4-1)=MONTH($J$2),4,"") | F5: =IF(MONTH($J$2+5-1)=MONTH($J$2),5,"") | G5: =IF(MONTH($J$2+6-1)=MONTH($J$2),6,"") | H5: =IF(MONTH($J$2+7-1)=MONTH($J$2),7,"") | I5: =IF(MONTH($J$2+8-1)=MONTH($J$2),8,"") | J5: =IF(MONTH($J$2+9-1)=MONTH($J$2),9,"") | K5: =IF(MONTH($J$2+10-1)=MONTH($J$2),10,"") | L5: =IF(MONTH($J$2+11-1)=MONTH($J$2),11,"") | M5: =IF(MONTH($J$2+12-1)=MONTH($J$2),12,"") | N5: =IF(MONTH($J$2+13-1)=MONTH($J$2),13,"") | O5: =IF(MONTH($J$2+14-1)=MONTH($J$2),14,"") | P5: =IF(MONTH($J$2+15-1)=MONTH($J$2),15,"") | Q5: =IF(MONTH($J$2+16-1)=MONTH($J$2),16,"") | R5: =IF(MONTH($J$2+17-1)=MONTH($J$2),17,"") | S5: =IF(MONTH($J$2+18-1)=MONTH($J$2),18,"") | T5: =IF(MONTH($J$2+19-1)=MONTH($J$2),19,"") | U5: =IF(MONTH($J$2+20-1)=MONTH($J$2),20,"") | V5: =IF(MONTH($J$2+21-1)=MONTH($J$2),21,"") | W5: =IF(MONTH($J$2+22-1)=MONTH($J$2),22,"") | X5: =IF(MONTH($J$2+23-1)=MONTH($J$2),23,"") | Y5: =IF(MONTH($J$2+24-1)=MONTH($J$2),24,"") | Z5: =IF(MONTH($J$2+25-1)=MONTH($J$2),25,"") | AA5: =IF(MONTH($J$2+26-1)=MONTH($J$2),26,"") | AB5: =IF(MONTH($J$2+27-1)=MONTH($J$2),27,"") | AC5: =IF(MONTH($J$2+28-1)=MONTH($J$2),28,"") | AD5: =IF(MONTH($J$2+29-1)=MONTH($J$2),29,"") | AE5: =IF(MONTH($J$2+30-1)=MONTH($J$2),30,"") | AF5: =IF(MONTH($J$2+31-1)=MONTH($J$2),31,"") | AG5: TỔNG THÁNG | AH5: MỤC TIÊU (ngày đã làm) | AI5: % ĐẠT
